Workbook
Name OLE_LINK1: 'Annex 3 Preserved charges'!#REF!

Sheet Overview
A2: Company and Licence name, charging year, effective from, status
B3: Company and Licence name | C3: Year | D3: Effective From | E3: Status
A4: Company and Licence name, charging year, effective from, status | B4: London Power Networks | C4: 2022/23 | D4: 1 April 2022 | E4: Final
A6: List of data tables in this workbook
A7: Worksheet | B7: Information
A8: Annex 1 LV, HV and Unmetered Supplies charges | B8: Annex 1 contains the charges to LV and HV Designated Properties and Unmetered Supplies.
A9: Annex 2 EHV charges | B9: ="Annex 2 contains the charges to Designated EHV Properties and charges applied to LDNOs with Designated EHV Properties/end-users embedded in networks within the " &B4 &" Licence area." -> Annex 2 contains the charges to Designated EHV Properties and charges applied to LDNOs with Designated EHV Properties/end-users embedded in networks within the London Power Networks Licence area.
A10: Annex 3 Preserved charges | B10: Annex 3 contains details of any preserved and additional charges that are valid at this time.
A11: Annex 4 LDNO charges | B11: ="Annex 4 contains charges that are levied on the owner of an embedded network within the "&B4&" Licence area. "&"Electricity suppliers and consumers who have properties connected to an embedded network should contact the embedded network owner to determine their distribution charges."&" The charges listed in this table are not payable by domestic consumers, business consumers or electricity suppliers." -> Annex 4 contains charges that are levied on the owner of an embedded network within the London Power Networks Licence area. Electricity suppliers and consumers who have properties connected to an embedded network should contact the embedded network owner to determine their distribution charges. The charges listed in this table are not payable by domestic consumers, business consumers or electricity suppliers.
A12: Annex 5 LLFs | B12: Annex 5 has been intentionally left blank as this charging statement is published a complete year before the LLFs have been audited. The line loss factors that are approved by the BSC Panel for the applicable year and consequently published on the Elexon website will take precedence and be used in Settlement. This annex will be re-published with these values once they are available.
A13: Annex 6 Charges for New or Amended Designated EHV Properties | B13: ="Annex 6 contains the charges for new or amended Designated EHV Properties and charges applied to LDNOs with new or amended Designated EHV Properties/end-users embedded in networks within the " &B4 &" Licence area." -> Annex 6 contains the charges for new or amended Designated EHV Properties and charges applied to LDNOs with new or amended Designated EHV Properties/end-users embedded in networks within the London Power Networks Licence area.
A14: Annex 7 Fixed adders for Supplier of Last Resort and Eligible Bad Debt pass-through costs | B14: Annex 7 contains the fixed adders to recover Supplier of Last Resort and Eligible Bad Debt pass-through costs. The Excess Supplier of Last Resort fixed adder relates to an increase to previously published charges only.
A15: Nodal prices | B15: Contains the underlying nodal costs used to calculate the current EDCM charges.
A16: Residual Charging Bandings | B16: Contains the four Residual charging band allocation for Customers
A17: Charge calculator | B17: Charge calculator is a tool to help you estimate your distribution charges using current consumption data and forecast consumption data.
A19: Notes to users of this spreadsheet
A21: Please use this spreadsheet with reference to the LC14 use of system charging statement.
A23: Notes to DNOs populating this spreadsheet
A25: DNOs must endeavour to maintain consistency in the structure of this spreadsheet. Any changes to the structure must be noted in the 'Notes to users of this spreadsheet'
A26: The drop down list on the charge calculator can be expanded by unprotecting the charge calculator sheet and selecting 'data', 'data validation...' and then expanding the 'source' data range. The sheet can then be protected.

Sheet Annex 1 LV, HV and UMS charges
A1: Back to Overview
A2: =Overview!B4& " - Effective from "&Overview!D4&" - "&Overview!E4&" LV and HV charges" -> London Power Networks - Effective from 1 April 2022 - Final LV and HV charges
A4: Time Bands for LV and HV Designated Properties | G4: Time Bands for Unmetered Properties
A5: Time periods | B5: Red Time Band | C5: Amber Time Band | E5: Green Time Band | I5: Black Time Band | J5: Yellow Time Band | K5: Green Time Band
A6: Monday to Friday (Including Bank Holidays) All Year | B6: 11:00 - 14:00 16:00 - 19:00 | C6: 07:00 - 11:00 14:00 - 16:00 19:00 - 23:00 | E6: 00:00 - 07:00 23:00 - 24:00 | G6: Monday to Friday (Including Bank Holidays) June to August Inclusive | I6: 11:00 - 14:00 | J6: 07:00 - 11:00 14:00 - 23:00 | K6: 00:00 - 07:00 23:00 - 24:00
A7: Saturday and Sunday All Year | E7: 00:00 - 24:00 | G7: Monday to Friday (Including Bank Holidays) November to February Inclusive | I7: 16:00 - 19:00 | J7: 07:00 - 16:00 19:00 - 23:00 | K7: 00:00 - 07:00 23:00 - 24:00
A8: Notes | B8: All the above times are in UK Clock time | G8: Monday to Friday (Including Bank Holidays) March, April, May and September, October | J8: 07:00 - 23:00 | K8: 00:00 - 07:00 23:00 - 24:00
G9: Saturday and Sunday All year | K9: 00:00 - 24:00
G10: Notes | I10: All the above times are in UK Clock time
A12: Tariff name | B12: Open LLFCs | C12: PCs | D12: Red/black unit charge p/kWh | E12: Amber/yellow unit charge p/kWh | F12: Green unit charge p/kWh | G12: Fixed charge p/MPAN/day | H12: Capacity charge p/kVA/day | I12: Exceeded capacity charge p/kVA/day | J12: Reactive power charge p/kVArh | K12: Closed LLFCs
A13: Domestic Aggregated with Residual | B13: 1 | C13: 0, 1, 2 | D13: 9.469 | E13: 1.785 | F13: 0.057 | G13: 10.86 | K13: 902, 903, 906, 907, 910
A14: Domestic Aggregated (Related MPAN) | B14: 2 | C14: 2 | D14: 9.469 | E14: 1.785 | F14: 0.057 | K14: 911, 914, 915
A15: Non-Domestic Aggregated No Residual | B15: 199 | C15: 0, 3, 4, 5-8 | D15: 5.793 | E15: 1.092 | F15: 0.035 | G15: 3.2
A16: Non-Domestic Aggregated Band 1 | B16: 201 | C16: 0, 3, 4, 5-8 | D16: 5.793 | E16: 1.092 | F16: 0.035 | G16: 2.43 | K16: 200, 400, 404, 952, 953, 956, 957, 960, 961, 970, 971
A17: Non-Domestic Aggregated Band 2 | B17: 202 | C17: 0, 3, 4, 5-8 | D17: 5.668 | E17: 0.967 | F17: 0 | G17: 0
A18: Non-Domestic Aggregated Band 3 | B18: 203 | C18: 0, 3, 4, 5-8 | D18: 5.519 | E18: 0.818 | F18: 0 | G18: 0
A19: Non-Domestic Aggregated Band 4 | B19: 204 | C19: 0, 3, 4, 5-8 | D19: 5.445 | E19: 0.744 | F19: 0 | G19: 0
A20: Non-Domestic Aggregated (related MPAN) | B20: 200 | C20: 4 | D20: 5.793 | E20: 1.092 | F20: 0.035 | K20: 964965
A21: LV Site Specific No Residual | B21: 70 | C21: 0 | D21: 4.769 | E21: 0.916 | F21: 0.031 | G21: 7.93 | H21: 4.29 | I21: 6.66 | J21: 0.409 | K21: 19
A22: LV Site Specific Band 1 | B22: 71 | C22: 0 | D22: 4.392 | E22: 0.539 | F22: 0.007 | G22: 2.07 | H22: 4.29 | I22: 6.66 | J22: 0.409 | K22: 9
A23: LV Site Specific Band 2 | B23: 72 | C23: 0 | D23: 4.382 | E23: 0.529 | F23: 0.007 | G23: 2.07 | H23: 4.29 | I23: 6.66 | J23: 0.409
A24: LV Site Specific Band 3 | B24: 73 | C24: 0 | D24: 4.372 | E24: 0.52 | F24: 0.007 | G24: 2.07 | H24: 4.29 | I24: 6.66 | J24: 0.409
A25: LV Site Specific Band 4 | B25: 74 | C25: 0 | D25: 4.365 | E25: 0.512 | F25: 0.007 | G25: 2.07 | H25: 4.29 | I25: 6.66 | J25: 0.409
A26: LV Sub Site Specific No Residual | B26: 80 | C26: 0 | D26: 3.237 | E26: 0.654 | F26: 0.024 | G26: 5.86 | H26: 7.53 | I26: 8.57 | J26: 0.241 | K26: 79
A27: LV Sub Site Specific Band 1 | B27: 81 | C27: 0 | D27: 2.86 | E27: 0.277 | F27: 0 | G27: 0 | H27: 7.53 | I27: 8.57 | J27: 0.241 | K27: 756
A28: LV Sub Site Specific Band 2 | B28: 82 | C28: 0 | D28: 2.85 | E28: 0.267 | F28: 0 | G28: 0 | H28: 7.53 | I28: 8.57 | J28: 0.241
A29: LV Sub Site Specific Band 3 | B29: 83 | C29: 0 | D29: 2.841 | E29: 0.257 | F29: 0 | G29: 0 | H29: 7.53 | I29: 8.57 | J29: 0.241
A30: LV Sub Site Specific Band 4 | B30: 84 | C30: 0 | D30: 2.833 | E30: 0.25 | F30: 0 | G30: 0 | H30: 7.53 | I30: 8.57 | J30: 0.241
A31: HV Site Specific No Residual | B31: 90 | C31: 0 | D31: 2.375 | E31: 0.462 | F31: 0.017 | G31: 78.57 | H31: 7.67 | I31: 8.62 | J31: 0.204 | K31: 89
A32: HV Site Specific Band 1 | B32: 91 | C32: 0 | D32: 2.023 | E32: 0.111 | F32: 0 | G32: 0 | H32: 7.67 | I32: 8.62 | J32: 0.204 | K32: 359
A33: HV Site Specific Band 2 | B33: 92 | C33: 0 | D33: 1.977 | E33: 0.065 | F33: 0 | G33: 0 | H33: 7.67 | I33: 8.62 | J33: 0.204
A34: HV Site Specific Band 3 | B34: 93 | C34: 0 | D34: 1.966 | E34: 0.053 | F34: 0 | G34: 0 | H34: 7.67 | I34: 8.62 | J34: 0.204
A35: HV Site Specific Band 4 | B35: 94 | C35: 0 | D35: 1.954 | E35: 0.042 | F35: 0 | G35: 0 | H35: 7.67 | I35: 8.62 | J35: 0.204
A36: Unmetered Supplies | B36: 350, 420, 421, 422, 423 | C36: 0, 1 or 8 | D36: 30.621 | E36: 2.281 | F36: 0.289 | K36: 424, 425, 426, 427, 428, 429, 430, 431, 432, 433, 434, 435
A37: LV Generation Aggregated | B37: 932 | C37: 0 | D37: -5.239 | E37: -0.987 | F37: -0.032 | G37: 0 | K37: 753, 763, 762
A38: LV Sub Generation Aggregated | C38: 0 | D38: -4.614 | E38: -0.879 | F38: -0.029 | G38: 0
A39: LV Generation Site Specific | B39: 980 | C39: 0 | D39: -5.239 | E39: -0.987 | F39: -0.032 | G39: 0 | J39: 0.361 | K39: 982
A40: LV Generation Site Specific no RP charge | B40: 981 | C40: 0 | D40: -5.239 | E40: -0.987 | F40: -0.032 | G40: 0 | K40: 983
A41: LV Sub Generation Site Specific | B41: 984 | C41: 0 | D41: -4.614 | E41: -0.879 | F41: -0.029 | G41: 0 | J41: 0.322 | K41: 986
A42: LV Sub Generation Site Specific no RP charge | B42: 985 | C42: 0 | D42: -4.614 | E42: -0.879 | F42: -0.029 | G42: 0 | K42: 987
...

Sheet Annex 2 EHV charges
A1: Back to Overview | F1: Note: The list of MPANs / MSIDs provided may be incomplete; the DNO reserves the right to apply the listed charges to any other MPANs / MSIDs associated with the site.
A2: =Overview!B4& " - Effective from "&Overview!D4&" - "&Overview!E4&" EDCM charges" -> London Power Networks - Effective from 1 April 2022 - Final EDCM charges
A4: Time Periods for Designated EHV Properties
A5: Time periods | D5: Super Red Time Band
A6: Monday to Friday (Including Bank Holidays) June to August Inclusive | D6: 11:00 - 14:00
A7: Monday to Friday (Including Bank Holidays) November to February Inclusive | D7: 16:00 - 19:00
A8: Notes | D8: All the above times are in UK Clock time
A10: Import Unique Identifier | B10: LLFC | C10: Import MPANs/MSIDs | D10: Export Unique Identifier | E10: LLFC | F10: Export MPANs/MSIDs | G10: Name | H10: Import Super Red unit charge (p/kWh) | I10: Import fixed charge (p/day) | J10: Import capacity charge (p/kVA/day) | K10: Import exceeded capacity charge (p/kVA/day) | L10: Export Super Red unit charge (p/kWh) | M10: Export fixed charge (p/day) | N10: Export capacity charge (p/kVA/day) | O10: Export exceeded capacity charge (p/kVA/day)
A11: 22BSHP | B11: 810 | C11: 1200062355497 1200062355502 | G11: 22BSHP | H11: 0.245 | I11: 6147.17 | J11: 1.13 | K11: 1.13
A12: BISHPC | B12: 811 | C12: 1200061143976 1200061143985 | G12: BISHPC | H12: 0.189 | I12: 17915.96 | J12: 1.53 | K12: 1.53
A13: BLMBGN | B13: 820 | C13: 1200061385700 1200061385710 | G13: BLMBGN | H13: 0.197 | I13: 5951.01 | J13: 1.8 | K13: 1.8
A14: BLMBGS | B14: 821 | C14: 1200061385729 1200061385738 | G14: BLMBGS | H14: 0.157 | I14: 1066.62 | J14: 1.31 | K14: 1.31
A15: BRDGTE | B15: 805 | C15: 1200061148014 1200061148023 | G15: BRDGTE | H15: 0.186 | I15: 5951.01 | J15: 2.58 | K15: 2.58
A16: BRKFLD | B16: 829 | C16: 1200061148060 1200061148079 | G16: BRKFLD | H16: 0.182 | I16: 6147.17 | J16: 1.81 | K16: 1.81
A17: BRMLEY | C17: MSID: 1630 | G17: BRMLEY | H17: 0 | I17: 43861.69 | J17: 3.12 | K17: 3.12
A18: CRLIMM | B18: 812 | C18: 1200062090483 1200062090492 | G18: CRLIMM | H18: 0 | I18: 51301.59 | J18: 0.98 | K18: 0.98
A19: DART11 | C19: MSID: 1032 | G19: DART11 | H19: 0.217 | I19: 5754.85 | J19: 5.11 | K19: 5.11
A20: DART33 | C20: MSID: 1032 | G20: DART33 | H20: 0.427 | I20: 17523.64 | J20: 5.27 | K20: 5.27
A21: EPNLEI | C21: MSID: 1628 | G21: EPNLEI | H21: 0 | I21: 43861.69 | J21: 3.51 | K21: 3.51
A22: FENAVE | B22: 813 | C22: 1200062132159 1200062132168 | G22: FENAVE | H22: 0.185 | I22: 6147.17 | J22: 1.62 | K22: 1.62
A23: FENCHS | B23: 800 | C23: 1200061144029 1200061144038 | G23: FENCHS | H23: 0.167 | I23: 6266.15 | J23: 2.57 | K23: 2.57
A24: GBLSWI | B24: 843 | C24: 1200050913681 1200050913690 1200050913706 1200050913715 | G24: GBLSWI | H24: 0 | I24: 51413.33 | J24: 2.05 | K24: 2.05
A25: KNGLPN | C25: MSID: 1027 | G25: KNGLPN | H25: 0 | I25: 5754.85 | J25: 0.9 | K25: 0.9
A26: LEDNHS | B26: 808 | C26: 1200061144065 1200061144074 | G26: LEDNHS | H26: 0.188 | I26: 6194.76 | J26: 1.4 | K26: 1.4
A27: LIMEST | B27: 814 | C27: 1200062132006 1200062132015 | G27: LIMEST | H27: 0.18 | I27: 6147.17 | J27: 1.69 | K27: 1.69
A28: LNWAL1 | B28: 816 | C28: 1200061148194 1200061148200 | G28: LNWAL1 | H28: 0.364 | I28: 1437.08 | J28: 2.82 | K28: 2.82
A29: LNWALL | B29: 816 | C29: 1200061953070 1200061953089 | G29: LNWALL | H29: 0.364 | I29: 6321.47 | J29: 1.54 | K29: 1.54
A30: LU_ACT | C30: MSID: 1631 | G30: LU_ACT | H30: 0 | I30: 5959.98 | J30: 2.22 | K30: 2.22
A31: LU_CAN | B31: 818 | C31: 1200060323207 1200060323216 | G31: LU_CAN | H31: 0 | I31: 50481.63 | J31: 1.09 | K31: 1.09
A32: LU_CHA | B32: 801 | C32: 1200061231921 1200061231930 1200061231940 1200061231959 | G32: LU_CHA | H32: 0 | I32: 51099.15 | J32: 1.28 | K32: 1.28
A33: LU_HOX | B33: 804 | C33: 1200060323191 | G33: LU_HOX | H33: 0 | I33: 50387.62 | J33: 0.47 | K33: 0.47
A34: LU_LOT | B34: 838 | C34: 1200050376902 1200050376911 | G34: LU_LOT | H34: 0 | I34: 76308.74 | J34: 2.13 | K34: 2.13
A35: LU_MAN | B35: 837 | C35: 1200010200926 | G35: LU_MAN | H35: 0.026 | I35: 66672.24 | J35: 1.44 | K35: 1.44
A36: LU_STE | B36: 839 | C36: 1200010157225 1200010157234 | G36: LU_STE | H36: 0 | I36: 50003.99 | J36: 2.93 | K36: 2.93
A37: MRKLNE | B37: 806 | C37: 1200061378624 1200061378633 | G37: MRKLNE | H37: 0.173 | I37: 1262.78 | J37: 1.83 | K37: 1.83
A38: NGC_BA | B38: 817 | C38: 1200010151863 1200010151872 | G38: NGC_BA | H38: 0.258 | I38: 870.46 | J38: 0.8 | K38: 0.8
A39: NR_BOW | B39: 807 | C39: 1200060280440 1200060280468 | G39: NR_BOW | H39: 0 | I39: 22833.28 | J39: 3.99 | K39: 3.99
A40: NR_BRO | B40: 847 | C40: 1200010251559 | G40: NR_BRO | H40: 0 | I40: 46038.69 | J40: 1.68 | K40: 1.68
A41: NR_CIT | B41: 846 | C41: 1200010251521 | G41: NR_CIT | H41: 2.651 | I41: 938.84 | J41: 2.08 | K41: 2.08
A42: NR_MAD | B42: 840 | C42: 1200010251540 | G42: NR_MAD | H42: 0 | I42: 1007.21 | J42: 0.78 | K42: 0.78
...

Sheet Annex 2a Import
A1: Note: The list of MPANs / MSIDs provided may be incomplete; the DNO reserves the right to apply the listed charges to any other MPANs / MSIDs associated with the site. Note: This table is automatically populated based on the content of the tab entitled 'Annex 2 EHV Charges'. The timebands are as shown in Annex 2.
A2: =Overview!B4& " - Effective from "&Overview!D4&" - "&Overview!E4&" EDCM import charges" -> London Power Networks - Effective from 1 April 2022 - Final EDCM import charges
A4: Import Unique Identifier | B4: LLFC | C4: Import MPANs/MSIDs | D4: Name | E4: ='Annex 2 EHV charges'!H10 -> Import Super Red unit charge (p/kWh) | F4: ='Annex 2 EHV charges'!I10 -> Import fixed charge (p/day) | G4: ='Annex 2 EHV charges'!J10 -> Import capacity charge (p/kVA/day) | H4: ='Annex 2 EHV charges'!K10 -> Import exceeded capacity charge (p/kVA/day)
A5: {=IFERROR(INDEX('Annex 2 EHV charges'!$A$11:$A$59, MATCH(0, IF(ISBLANK('Annex 2 EHV charges'!$A$11:$A$59),1, COUNTIF(A$4:$A4, 'Annex 2 EHV charges'!$A$11:$A$59)), 0)),"")} -> 22BSHP | B5: =IF($A5="","",VLOOKUP($A5,'Annex 2 EHV charges'!$A:$O,2,0)) -> 810 | C5: =IF($A5="","",VLOOKUP($A5,'Annex 2 EHV charges'!$A:$O,3,0)) -> 1200062355497 1200062355502 | D5: =IF($A5="","",VLOOKUP($A5,'Annex 2 EHV charges'!$A:$O,7,0)) -> 22BSHP | E5: =IFERROR(IF(VLOOKUP($A5,'Annex 2 EHV charges'!$A:$O,8,FALSE)=0,"",VLOOKUP($A5,'Annex 2 EHV charges'!$A:$O,8,FALSE)),"") -> 0.245 | F5: =IFERROR(IF(VLOOKUP($A5,'Annex 2 EHV charges'!$A:$O,9,FALSE)=0,"",VLOOKUP($A5,'Annex 2 EHV charges'!$A:$O,9,FALSE)),"") -> 6147.17 | G5: =IFERROR(IF(VLOOKUP($A5,'Annex 2 EHV charges'!$A:$O,10,FALSE)=0,"",VLOOKUP($A5,'Annex 2 EHV charges'!$A:$O,10,FALSE)),"") -> 1.13 | H5: =IFERROR(IF(VLOOKUP($A5,'Annex 2 EHV charges'!$A:$O,11,FALSE)=0,"",VLOOKUP($A5,'Annex 2 EHV charges'!$A:$O,11,FALSE)),"") -> 1.13
A6: {=IFERROR(INDEX('Annex 2 EHV charges'!$A$11:$A$59, MATCH(0, IF(ISBLANK('Annex 2 EHV charges'!$A$11:$A$59),1, COUNTIF(A$4:$A5, 'Annex 2 EHV charges'!$A$11:$A$59)), 0)),"")} -> BISHPC | B6: =IF($A6="","",VLOOKUP($A6,'Annex 2 EHV charges'!$A:$O,2,0)) -> 811 | C6: =IF($A6="","",VLOOKUP($A6,'Annex 2 EHV charges'!$A:$O,3,0)) -> 1200061143976 1200061143985 | D6: =IF($A6="","",VLOOKUP($A6,'Annex 2 EHV charges'!$A:$O,7,0)) -> BISHPC | E6: =IFERROR(IF(VLOOKUP($A6,'Annex 2 EHV charges'!$A:$O,8,FALSE)=0,"",VLOOKUP($A6,'Annex 2 EHV charges'!$A:$O,8,FALSE)),"") -> 0.189 | F6: =IFERROR(IF(VLOOKUP($A6,'Annex 2 EHV charges'!$A:$O,9,FALSE)=0,"",VLOOKUP($A6,'Annex 2 EHV charges'!$A:$O,9,FALSE)),"") -> 17915.96 | G6: =IFERROR(IF(VLOOKUP($A6,'Annex 2 EHV charges'!$A:$O,10,FALSE)=0,"",VLOOKUP($A6,'Annex 2 EHV charges'!$A:$O,10,FALSE)),"") -> 1.53 | H6: =IFERROR(IF(VLOOKUP($A6,'Annex 2 EHV charges'!$A:$O,11,FALSE)=0,"",VLOOKUP($A6,'Annex 2 EHV charges'!$A:$O,11,FALSE)),"") -> 1.53
A7: {=IFERROR(INDEX('Annex 2 EHV charges'!$A$11:$A$59, MATCH(0, IF(ISBLANK('Annex 2 EHV charges'!$A$11:$A$59),1, COUNTIF(A$4:$A6, 'Annex 2 EHV charges'!$A$11:$A$59)), 0)),"")} -> BLMBGN | B7: =IF($A7="","",VLOOKUP($A7,'Annex 2 EHV charges'!$A:$O,2,0)) -> 820 | C7: =IF($A7="","",VLOOKUP($A7,'Annex 2 EHV charges'!$A:$O,3,0)) -> 1200061385700 1200061385710 | D7: =IF($A7="","",VLOOKUP($A7,'Annex 2 EHV charges'!$A:$O,7,0)) -> BLMBGN | E7: =IFERROR(IF(VLOOKUP($A7,'Annex 2 EHV charges'!$A:$O,8,FALSE)=0,"",VLOOKUP($A7,'Annex 2 EHV charges'!$A:$O,8,FALSE)),"") -> 0.197 | F7: =IFERROR(IF(VLOOKUP($A7,'Annex 2 EHV charges'!$A:$O,9,FALSE)=0,"",VLOOKUP($A7,'Annex 2 EHV charges'!$A:$O,9,FALSE)),"") -> 5951.01 | G7: =IFERROR(IF(VLOOKUP($A7,'Annex 2 EHV charges'!$A:$O,10,FALSE)=0,"",VLOOKUP($A7,'Annex 2 EHV charges'!$A:$O,10,FALSE)),"") -> 1.8 | H7: =IFERROR(IF(VLOOKUP($A7,'Annex 2 EHV charges'!$A:$O,11,FALSE)=0,"",VLOOKUP($A7,'Annex 2 EHV charges'!$A:$O,11,FALSE)),"") -> 1.8
A8: {=IFERROR(INDEX('Annex 2 EHV charges'!$A$11:$A$59, MATCH(0, IF(ISBLANK('Annex 2 EHV charges'!$A$11:$A$59),1, COUNTIF(A$4:$A7, 'Annex 2 EHV charges'!$A$11:$A$59)), 0)),"")} -> BLMBGS | B8: =IF($A8="","",VLOOKUP($A8,'Annex 2 EHV charges'!$A:$O,2,0)) -> 821 | C8: =IF($A8="","",VLOOKUP($A8,'Annex 2 EHV charges'!$A:$O,3,0)) -> 1200061385729 1200061385738 | D8: =IF($A8="","",VLOOKUP($A8,'Annex 2 EHV charges'!$A:$O,7,0)) -> BLMBGS | E8: =IFERROR(IF(VLOOKUP($A8,'Annex 2 EHV charges'!$A:$O,8,FALSE)=0,"",VLOOKUP($A8,'Annex 2 EHV charges'!$A:$O,8,FALSE)),"") -> 0.157 | F8: =IFERROR(IF(VLOOKUP($A8,'Annex 2 EHV charges'!$A:$O,9,FALSE)=0,"",VLOOKUP($A8,'Annex 2 EHV charges'!$A:$O,9,FALSE)),"") -> 1066.62 | G8: =IFERROR(IF(VLOOKUP($A8,'Annex 2 EHV charges'!$A:$O,10,FALSE)=0,"",VLOOKUP($A8,'Annex 2 EHV charges'!$A:$O,10,FALSE)),"") -> 1.31 | H8: =IFERROR(IF(VLOOKUP($A8,'Annex 2 EHV charges'!$A:$O,11,FALSE)=0,"",VLOOKUP($A8,'Annex 2 EHV charges'!$A:$O,11,FALSE)),"") -> 1.31
A9: {=IFERROR(INDEX('Annex 2 EHV charges'!$A$11:$A$59, MATCH(0, IF(ISBLANK('Annex 2 EHV charges'!$A$11:$A$59),1, COUNTIF(A$4:$A8, 'Annex 2 EHV charges'!$A$11:$A$59)), 0)),"")} -> BRDGTE | B9: =IF($A9="","",VLOOKUP($A9,'Annex 2 EHV charges'!$A:$O,2,0)) -> 805 | C9: =IF($A9="","",VLOOKUP($A9,'Annex 2 EHV charges'!$A:$O,3,0)) -> 1200061148014 1200061148023 | D9: =IF($A9="","",VLOOKUP($A9,'Annex 2 EHV charges'!$A:$O,7,0)) -> BRDGTE | E9: =IFERROR(IF(VLOOKUP($A9,'Annex 2 EHV charges'!$A:$O,8,FALSE)=0,"",VLOOKUP($A9,'Annex 2 EHV charges'!$A:$O,8,FALSE)),"") -> 0.186 | F9: =IFERROR(IF(VLOOKUP($A9,'Annex 2 EHV charges'!$A:$O,9,FALSE)=0,"",VLOOKUP($A9,'Annex 2 EHV charges'!$A:$O,9,FALSE)),"") -> 5951.01 | G9: =IFERROR(IF(VLOOKUP($A9,'Annex 2 EHV charges'!$A:$O,10,FALSE)=0,"",VLOOKUP($A9,'Annex 2 EHV charges'!$A:$O,10,FALSE)),"") -> 2.58 | H9: =IFERROR(IF(VLOOKUP($A9,'Annex 2 EHV charges'!$A:$O,11,FALSE)=0,"",VLOOKUP($A9,'Annex 2 EHV charges'!$A:$O,11,FALSE)),"") -> 2.58
A10: {=IFERROR(INDEX('Annex 2 EHV charges'!$A$11:$A$59, MATCH(0, IF(ISBLANK('Annex 2 EHV charges'!$A$11:$A$59),1, COUNTIF(A$4:$A9, 'Annex 2 EHV charges'!$A$11:$A$59)), 0)),"")} -> BRKFLD | B10: =IF($A10="","",VLOOKUP($A10,'Annex 2 EHV charges'!$A:$O,2,0)) -> 829 | C10: =IF($A10="","",VLOOKUP($A10,'Annex 2 EHV charges'!$A:$O,3,0)) -> 1200061148060 1200061148079 | D10: =IF($A10="","",VLOOKUP($A10,'Annex 2 EHV charges'!$A:$O,7,0)) -> BRKFLD | E10: =IFERROR(IF(VLOOKUP($A10,'Annex 2 EHV charges'!$A:$O,8,FALSE)=0,"",VLOOKUP($A10,'Annex 2 EHV charges'!$A:$O,8,FALSE)),"") -> 0.182 | F10: =IFERROR(IF(VLOOKUP($A10,'Annex 2 EHV charges'!$A:$O,9,FALSE)=0,"",VLOOKUP($A10,'Annex 2 EHV charges'!$A:$O,9,FALSE)),"") -> 6147.17 | G10: =IFERROR(IF(VLOOKUP($A10,'Annex 2 EHV charges'!$A:$O,10,FALSE)=0,"",VLOOKUP($A10,'Annex 2 EHV charges'!$A:$O,10,FALSE)),"") -> 1.81 | H10: =IFERROR(IF(VLOOKUP($A10,'Annex 2 EHV charges'!$A:$O,11,FALSE)=0,"",VLOOKUP($A10,'Annex 2 EHV charges'!$A:$O,11,FALSE)),"") -> 1.81
A11: {=IFERROR(INDEX('Annex 2 EHV charges'!$A$11:$A$59, MATCH(0, IF(ISBLANK('Annex 2 EHV charges'!$A$11:$A$59),1, COUNTIF(A$4:$A10, 'Annex 2 EHV charges'!$A$11:$A$59)), 0)),"")} -> BRMLEY | B11: =IF($A11="","",VLOOKUP($A11,'Annex 2 EHV charges'!$A:$O,2,0)) -> 0 | C11: =IF($A11="","",VLOOKUP($A11,'Annex 2 EHV charges'!$A:$O,3,0)) -> MSID: 1630 | D11: =IF($A11="","",VLOOKUP($A11,'Annex 2 EHV charges'!$A:$O,7,0)) -> BRMLEY | E11: =IFERROR(IF(VLOOKUP($A11,'Annex 2 EHV charges'!$A:$O,8,FALSE)=0,"",VLOOKUP($A11,'Annex 2 EHV charges'!$A:$O,8,FALSE)),"") | F11: =IFERROR(IF(VLOOKUP($A11,'Annex 2 EHV charges'!$A:$O,9,FALSE)=0,"",VLOOKUP($A11,'Annex 2 EHV charges'!$A:$O,9,FALSE)),"") -> 43861.69 | G11: =IFERROR(IF(VLOOKUP($A11,'Annex 2 EHV charges'!$A:$O,10,FALSE)=0,"",VLOOKUP($A11,'Annex 2 EHV charges'!$A:$O,10,FALSE)),"") -> 3.12 | H11: =IFERROR(IF(VLOOKUP($A11,'Annex 2 EHV charges'!$A:$O,11,FALSE)=0,"",VLOOKUP($A11,'Annex 2 EHV charges'!$A:$O,11,FALSE)),"") -> 3.12
A12: {=IFERROR(INDEX('Annex 2 EHV charges'!$A$11:$A$59, MATCH(0, IF(ISBLANK('Annex 2 EHV charges'!$A$11:$A$59),1, COUNTIF(A$4:$A11, 'Annex 2 EHV charges'!$A$11:$A$59)), 0)),"")} -> CRLIMM | B12: =IF($A12="","",VLOOKUP($A12,'Annex 2 EHV charges'!$A:$O,2,0)) -> 812 | C12: =IF($A12="","",VLOOKUP($A12,'Annex 2 EHV charges'!$A:$O,3,0)) -> 1200062090483 1200062090492 | D12: =IF($A12="","",VLOOKUP($A12,'Annex 2 EHV charges'!$A:$O,7,0)) -> CRLIMM | E12: =IFERROR(IF(VLOOKUP($A12,'Annex 2 EHV charges'!$A:$O,8,FALSE)=0,"",VLOOKUP($A12,'Annex 2 EHV charges'!$A:$O,8,FALSE)),"") | F12: =IFERROR(IF(VLOOKUP($A12,'Annex 2 EHV charges'!$A:$O,9,FALSE)=0,"",VLOOKUP($A12,'Annex 2 EHV charges'!$A:$O,9,FALSE)),"") -> 51301.59 | G12: =IFERROR(IF(VLOOKUP($A12,'Annex 2 EHV charges'!$A:$O,10,FALSE)=0,"",VLOOKUP($A12,'Annex 2 EHV charges'!$A:$O,10,FALSE)),"") -> 0.98 | H12: =IFERROR(IF(VLOOKUP($A12,'Annex 2 EHV charges'!$A:$O,11,FALSE)=0,"",VLOOKUP($A12,'Annex 2 EHV charges'!$A:$O,11,FALSE)),"") -> 0.98
A13: {=IFERROR(INDEX('Annex 2 EHV charges'!$A$11:$A$59, MATCH(0, IF(ISBLANK('Annex 2 EHV charges'!$A$11:$A$59),1, COUNTIF(A$4:$A12, 'Annex 2 EHV charges'!$A$11:$A$59)), 0)),"")} -> DART11 | B13: =IF($A13="","",VLOOKUP($A13,'Annex 2 EHV charges'!$A:$O,2,0)) -> 0 | C13: =IF($A13="","",VLOOKUP($A13,'Annex 2 EHV charges'!$A:$O,3,0)) -> MSID: 1032 | D13: =IF($A13="","",VLOOKUP($A13,'Annex 2 EHV charges'!$A:$O,7,0)) -> DART11 | E13: =IFERROR(IF(VLOOKUP($A13,'Annex 2 EHV charges'!$A:$O,8,FALSE)=0,"",VLOOKUP($A13,'Annex 2 EHV charges'!$A:$O,8,FALSE)),"") -> 0.217 | F13: =IFERROR(IF(VLOOKUP($A13,'Annex 2 EHV charges'!$A:$O,9,FALSE)=0,"",VLOOKUP($A13,'Annex 2 EHV charges'!$A:$O,9,FALSE)),"") -> 5754.85 | G13: =IFERROR(IF(VLOOKUP($A13,'Annex 2 EHV charges'!$A:$O,10,FALSE)=0,"",VLOOKUP($A13,'Annex 2 EHV charges'!$A:$O,10,FALSE)),"") -> 5.11 | H13: =IFERROR(IF(VLOOKUP($A13,'Annex 2 EHV charges'!$A:$O,11,FALSE)=0,"",VLOOKUP($A13,'Annex 2 EHV charges'!$A:$O,11,FALSE)),"") -> 5.11
A14: {=IFERROR(INDEX('Annex 2 EHV charges'!$A$11:$A$59, MATCH(0, IF(ISBLANK('Annex 2 EHV charges'!$A$11:$A$59),1, COUNTIF(A$4:$A13, 'Annex 2 EHV charges'!$A$11:$A$59)), 0)),"")} -> DART33 | B14: =IF($A14="","",VLOOKUP($A14,'Annex 2 EHV charges'!$A:$O,2,0)) -> 0 | C14: =IF($A14="","",VLOOKUP($A14,'Annex 2 EHV charges'!$A:$O,3,0)) -> MSID: 1032 | D14: =IF($A14="","",VLOOKUP($A14,'Annex 2 EHV charges'!$A:$O,7,0)) -> DART33 | E14: =IFERROR(IF(VLOOKUP($A14,'Annex 2 EHV charges'!$A:$O,8,FALSE)=0,"",VLOOKUP($A14,'Annex 2 EHV charges'!$A:$O,8,FALSE)),"") -> 0.427 | F14: =IFERROR(IF(VLOOKUP($A14,'Annex 2 EHV charges'!$A:$O,9,FALSE)=0,"",VLOOKUP($A14,'Annex 2 EHV charges'!$A:$O,9,FALSE)),"") -> 17523.64 | G14: =IFERROR(IF(VLOOKUP($A14,'Annex 2 EHV charges'!$A:$O,10,FALSE)=0,"",VLOOKUP($A14,'Annex 2 EHV charges'!$A:$O,10,FALSE)),"") -> 5.27 | H14: =IFERROR(IF(VLOOKUP($A14,'Annex 2 EHV charges'!$A:$O,11,FALSE)=0,"",VLOOKUP($A14,'Annex 2 EHV charges'!$A:$O,11,FALSE)),"") -> 5.27
A15: {=IFERROR(INDEX('Annex 2 EHV charges'!$A$11:$A$59, MATCH(0, IF(ISBLANK('Annex 2 EHV charges'!$A$11:$A$59),1, COUNTIF(A$4:$A14, 'Annex 2 EHV charges'!$A$11:$A$59)), 0)),"")} -> EPNLEI | B15: =IF($A15="","",VLOOKUP($A15,'Annex 2 EHV charges'!$A:$O,2,0)) -> 0 | C15: =IF($A15="","",VLOOKUP($A15,'Annex 2 EHV charges'!$A:$O,3,0)) -> MSID: 1628 | D15: =IF($A15="","",VLOOKUP($A15,'Annex 2 EHV charges'!$A:$O,7,0)) -> EPNLEI | E15: =IFERROR(IF(VLOOKUP($A15,'Annex 2 EHV charges'!$A:$O,8,FALSE)=0,"",VLOOKUP($A15,'Annex 2 EHV charges'!$A:$O,8,FALSE)),"") | F15: =IFERROR(IF(VLOOKUP($A15,'Annex 2 EHV charges'!$A:$O,9,FALSE)=0,"",VLOOKUP($A15,'Annex 2 EHV charges'!$A:$O,9,FALSE)),"") -> 43861.69 | G15: =IFERROR(IF(VLOOKUP($A15,'Annex 2 EHV charges'!$A:$O,10,FALSE)=0,"",VLOOKUP($A15,'Annex 2 EHV charges'!$A:$O,10,FALSE)),"") -> 3.51 | H15: =IFERROR(IF(VLOOKUP($A15,'Annex 2 EHV charges'!$A:$O,11,FALSE)=0,"",VLOOKUP($A15,'Annex 2 EHV charges'!$A:$O,11,FALSE)),"") -> 3.51
A16: {=IFERROR(INDEX('Annex 2 EHV charges'!$A$11:$A$59, MATCH(0, IF(ISBLANK('Annex 2 EHV charges'!$A$11:$A$59),1, COUNTIF(A$4:$A15, 'Annex 2 EHV charges'!$A$11:$A$59)), 0)),"")} -> FENAVE | B16: =IF($A16="","",VLOOKUP($A16,'Annex 2 EHV charges'!$A:$O,2,0)) -> 813 | C16: =IF($A16="","",VLOOKUP($A16,'Annex 2 EHV charges'!$A:$O,3,0)) -> 1200062132159 1200062132168 | D16: =IF($A16="","",VLOOKUP($A16,'Annex 2 EHV charges'!$A:$O,7,0)) -> FENAVE | E16: =IFERROR(IF(VLOOKUP($A16,'Annex 2 EHV charges'!$A:$O,8,FALSE)=0,"",VLOOKUP($A16,'Annex 2 EHV charges'!$A:$O,8,FALSE)),"") -> 0.185 | F16: =IFERROR(IF(VLOOKUP($A16,'Annex 2 EHV charges'!$A:$O,9,FALSE)=0,"",VLOOKUP($A16,'Annex 2 EHV charges'!$A:$O,9,FALSE)),"") -> 6147.17 | G16: =IFERROR(IF(VLOOKUP($A16,'Annex 2 EHV charges'!$A:$O,10,FALSE)=0,"",VLOOKUP($A16,'Annex 2 EHV charges'!$A:$O,10,FALSE)),"") -> 1.62 | H16: =IFERROR(IF(VLOOKUP($A16,'Annex 2 EHV charges'!$A:$O,11,FALSE)=0,"",VLOOKUP($A16,'Annex 2 EHV charges'!$A:$O,11,FALSE)),"") -> 1.62
... A51: {=IFERROR(INDEX('Annex 2 EHV charges'!$A$11:$A$59, MATCH(0, IF(ISBLANK('Annex 2 EHV charges'!$A$11:$A$59),1, COUNTIF(A$4:$A50, 'Annex 2 EHV charges'!$A$11:$A$59)), 0)),"")} -> TLRSLN | B51: =IF($A51="","",VLOOKUP($A51,'Annex 2 EHV charges'!$A:$O,2,0)) -> 0 | C51: =IF($A51="","",VLOOKUP($A51,'Annex 2 EHV charges'!$A:$O,3,0)) -> MSID: 5538 | D51: =IF($A51="","",VLOOKUP($A51,'Annex 2 EHV charges'!$A:$O,7,0)) -> TLRSLN | E51: =IFERROR(IF(VLOOKUP($A51,'Annex 2 EHV charges'!$A:$O,8,FALSE)=0,"",VLOOKUP($A51,'Annex 2 EHV charges'!$A:$O,8,FALSE)),"") | F51: =IFERROR(IF(VLOOKUP($A51,'Annex 2 EHV charges'!$A:$O,9,FALSE)=0,"",VLOOKUP($A51,'Annex 2 EHV charges'!$A:$O,9,FALSE)),"") -> 903.03 | G51: =IFERROR(IF(VLOOKUP($A51,'Annex 2 EHV charges'!$A:$O,10,FALSE)=0,"",VLOOKUP($A51,'Annex 2 EHV charges'!$A:$O,10,FALSE)),"") -> 0.88 | H51: =IFERROR(IF(VLOOKUP($A51,'Annex 2 EHV charges'!$A:$O,11,FALSE)=0,"",VLOOKUP($A51,'Annex 2 EHV charges'!$A:$O,11,FALSE)),"") -> 0.88

Sheet Annex 2b Export
A1: Note: The list of MPANs / MSIDs provided may be incomplete; the DNO reserves the right to apply the listed charges to any other MPANs / MSIDs associated with the site. Note: This table is automatically populated based on the content of the tab entitled 'Annex 2 EHV Charges'. The timebands are as shown in Annex 2.
A2: =Overview!B4& " - Effective from "&Overview!D4&" - "&Overview!E4&" EDCM export charges" -> London Power Networks - Effective from 1 April 2022 - Final EDCM export charges
A4: Export Unique Identifier | B4: LLFC | C4: Export MPANs/MSIDs | D4: Name | E4: ='Annex 2 EHV charges'!L10 -> Export Super Red unit charge (p/kWh) | F4: ='Annex 2 EHV charges'!M10 -> Export fixed charge (p/day) | G4: ='Annex 2 EHV charges'!N10 -> Export capacity charge (p/kVA/day) | H4: ='Annex 2 EHV charges'!O10 -> Export exceeded capacity charge (p/kVA/day)
A5: {=IFERROR(INDEX('Annex 2 EHV charges'!$D$11:$D$59, MATCH(0, IF(ISBLANK('Annex 2 EHV charges'!$D$11:$D$59),1, COUNTIF(A$4:$A4, 'Annex 2 EHV charges'!$D$11:$D$59)), 0)),"")} -> NR_WES | B5: =IF($A5="","",VLOOKUP($A5,'Annex 2 EHV charges'!$D:$O,2,0)) -> 716 | C5: =IF($A5="","",VLOOKUP($A5,'Annex 2 EHV charges'!$D:$O,3,0)) -> 1200052486875 | D5: =IF($A5="","",VLOOKUP($A5,'Annex 2 EHV charges'!$D:$O,4,0)) -> NR_WES | E5: =IFERROR(IF(VLOOKUP($A5,'Annex 2 EHV charges'!$D:$O,9,FALSE)=0,"",VLOOKUP($A5,'Annex 2 EHV charges'!$D:$O,9,FALSE)),"") | F5: =IFERROR(IF(VLOOKUP($A5,'Annex 2 EHV charges'!$D:$O,10,FALSE)=0,"",VLOOKUP($A5,'Annex 2 EHV charges'!$D:$O,10,FALSE)),"") -> 387.31 | G5: =IFERROR(IF(VLOOKUP($A5,'Annex 2 EHV charges'!$D:$O,11,FALSE)=0,"",VLOOKUP($A5,'Annex 2 EHV charges'!$D:$O,11,FALSE)),"") -> 0.05 | H5: =IFERROR(IF(VLOOKUP($A5,'Annex 2 EHV charges'!$D:$O,12,FALSE)=0,"",VLOOKUP($A5,'Annex 2 EHV charges'!$D:$O,12,FALSE)),"") -> 0.05
A6: {=IFERROR(INDEX('Annex 2 EHV charges'!$D$11:$D$59, MATCH(0, IF(ISBLANK('Annex 2 EHV charges'!$D$11:$D$59),1, COUNTIF(A$4:$A5, 'Annex 2 EHV charges'!$D$11:$D$59)), 0)),"")} -> THAMEB | B6: =IF($A6="","",VLOOKUP($A6,'Annex 2 EHV charges'!$D:$O,2,0)) -> 701 | C6: =IF($A6="","",VLOOKUP($A6,'Annex 2 EHV charges'!$D:$O,3,0)) -> 1200050312030 1200050312040 1200061219394 | D6: =IF($A6="","",VLOOKUP($A6,'Annex 2 EHV charges'!$D:$O,4,0)) -> THAMEB | E6: =IFERROR(IF(VLOOKUP($A6,'Annex 2 EHV charges'!$D:$O,9,FALSE)=0,"",VLOOKUP($A6,'Annex 2 EHV charges'!$D:$O,9,FALSE)),"") | F6: =IFERROR(IF(VLOOKUP($A6,'Annex 2 EHV charges'!$D:$O,10,FALSE)=0,"",VLOOKUP($A6,'Annex 2 EHV charges'!$D:$O,10,FALSE)),"") | G6: =IFERROR(IF(VLOOKUP($A6,'Annex 2 EHV charges'!$D:$O,11,FALSE)=0,"",VLOOKUP($A6,'Annex 2 EHV charges'!$D:$O,11,FALSE)),"") | H6: =IFERROR(IF(VLOOKUP($A6,'Annex 2 EHV charges'!$D:$O,12,FALSE)=0,"",VLOOKUP($A6,'Annex 2 EHV charges'!$D:$O,12,FALSE)),"")
A7: {=IFERROR(INDEX('Annex 2 EHV charges'!$D$11:$D$59, MATCH(0, IF(ISBLANK('Annex 2 EHV charges'!$D$11:$D$59),1, COUNTIF(A$4:$A6, 'Annex 2 EHV charges'!$D$11:$D$59)), 0)),"")} -> THAMEC | B7: =IF($A7="","",VLOOKUP($A7,'Annex 2 EHV charges'!$D:$O,2,0)) -> 702 | C7: =IF($A7="","",VLOOKUP($A7,'Annex 2 EHV charges'!$D:$O,3,0)) -> 1200061171342 1200061171351 | D7: =IF($A7="","",VLOOKUP($A7,'Annex 2 EHV charges'!$D:$O,4,0)) -> THAMEC | E7: =IFERROR(IF(VLOOKUP($A7,'Annex 2 EHV charges'!$D:$O,9,FALSE)=0,"",VLOOKUP($A7,'Annex 2 EHV charges'!$D:$O,9,FALSE)),"") | F7: =IFERROR(IF(VLOOKUP($A7,'Annex 2 EHV charges'!$D:$O,10,FALSE)=0,"",VLOOKUP($A7,'Annex 2 EHV charges'!$D:$O,10,FALSE)),"") -> 675.05 | G7: =IFERROR(IF(VLOOKUP($A7,'Annex 2 EHV charges'!$D:$O,11,FALSE)=0,"",VLOOKUP($A7,'Annex 2 EHV charges'!$D:$O,11,FALSE)),"") -> 0.05 | H7: =IFERROR(IF(VLOOKUP($A7,'Annex 2 EHV charges'!$D:$O,12,FALSE)=0,"",VLOOKUP($A7,'Annex 2 EHV charges'!$D:$O,12,FALSE)),"") -> 0.05
A8: {=IFERROR(INDEX('Annex 2 EHV charges'!$D$11:$D$59, MATCH(0, IF(ISBLANK('Annex 2 EHV charges'!$D$11:$D$59),1, COUNTIF(A$4:$A7, 'Annex 2 EHV charges'!$D$11:$D$59)), 0)),"")} -> BELVED | B8: =IF($A8="","",VLOOKUP($A8,'Annex 2 EHV charges'!$D:$O,2,0)) -> 711 | C8: =IF($A8="","",VLOOKUP($A8,'Annex 2 EHV charges'!$D:$O,3,0)) -> 1200060787118 | D8: =IF($A8="","",VLOOKUP($A8,'Annex 2 EHV charges'!$D:$O,4,0)) -> BELVED | E8: =IFERROR(IF(VLOOKUP($A8,'Annex 2 EHV charges'!$D:$O,9,FALSE)=0,"",VLOOKUP($A8,'Annex 2 EHV charges'!$D:$O,9,FALSE)),"") | F8: =IFERROR(IF(VLOOKUP($A8,'Annex 2 EHV charges'!$D:$O,10,FALSE)=0,"",VLOOKUP($A8,'Annex 2 EHV charges'!$D:$O,10,FALSE)),"") -> 628.44 | G8: =IFERROR(IF(VLOOKUP($A8,'Annex 2 EHV charges'!$D:$O,11,FALSE)=0,"",VLOOKUP($A8,'Annex 2 EHV charges'!$D:$O,11,FALSE)),"") -> 0.05 | H8: =IFERROR(IF(VLOOKUP($A8,'Annex 2 EHV charges'!$D:$O,12,FALSE)=0,"",VLOOKUP($A8,'Annex 2 EHV charges'!$D:$O,12,FALSE)),"") -> 0.05
A9: {=IFERROR(INDEX('Annex 2 EHV charges'!$D$11:$D$59, MATCH(0, IF(ISBLANK('Annex 2 EHV charges'!$D$11:$D$59),1, COUNTIF(A$4:$A8, 'Annex 2 EHV charges'!$D$11:$D$59)), 0)),"")} -> SELCHP | B9: =IF($A9="","",VLOOKUP($A9,'Annex 2 EHV charges'!$D:$O,2,0)) -> 730 | C9: =IF($A9="","",VLOOKUP($A9,'Annex 2 EHV charges'!$D:$O,3,0)) -> 1200010258304 | D9: =IF($A9="","",VLOOKUP($A9,'Annex 2 EHV charges'!$D:$O,4,0)) -> SELCHP | E9: =IFERROR(IF(VLOOKUP($A9,'Annex 2 EHV charges'!$D:$O,9,FALSE)=0,"",VLOOKUP($A9,'Annex 2 EHV charges'!$D:$O,9,FALSE)),"") | F9: =IFERROR(IF(VLOOKUP($A9,'Annex 2 EHV charges'!$D:$O,10,FALSE)=0,"",VLOOKUP($A9,'Annex 2 EHV charges'!$D:$O,10,FALSE)),"") -> 3106.09 | G9: =IFERROR(IF(VLOOKUP($A9,'Annex 2 EHV charges'!$D:$O,11,FALSE)=0,"",VLOOKUP($A9,'Annex 2 EHV charges'!$D:$O,11,FALSE)),"") -> 0.05 | H9: =IFERROR(IF(VLOOKUP($A9,'Annex 2 EHV charges'!$D:$O,12,FALSE)=0,"",VLOOKUP($A9,'Annex 2 EHV charges'!$D:$O,12,FALSE)),"") -> 0.05
A10: {=IFERROR(INDEX('Annex 2 EHV charges'!$D$11:$D$59, MATCH(0, IF(ISBLANK('Annex 2 EHV charges'!$D$11:$D$59),1, COUNTIF(A$4:$A9, 'Annex 2 EHV charges'!$D$11:$D$59)), 0)),"")} -> TLRSLN | B10: =IF($A10="","",VLOOKUP($A10,'Annex 2 EHV charges'!$D:$O,2,0)) -> 0 | C10: =IF($A10="","",VLOOKUP($A10,'Annex 2 EHV charges'!$D:$O,3,0)) -> MSID: 5538 | D10: =IF($A10="","",VLOOKUP($A10,'Annex 2 EHV charges'!$D:$O,4,0)) -> TLRSLN | E10: =IFERROR(IF(VLOOKUP($A10,'Annex 2 EHV charges'!$D:$O,9,FALSE)=0,"",VLOOKUP($A10,'Annex 2 EHV charges'!$D:$O,9,FALSE)),"") -> -0.059 | F10: =IFERROR(IF(VLOOKUP($A10,'Annex 2 EHV charges'!$D:$O,10,FALSE)=0,"",VLOOKUP($A10,'Annex 2 EHV charges'!$D:$O,10,FALSE)),"") -> 3039.7 | G10: =IFERROR(IF(VLOOKUP($A10,'Annex 2 EHV charges'!$D:$O,11,FALSE)=0,"",VLOOKUP($A10,'Annex 2 EHV charges'!$D:$O,11,FALSE)),"") -> 0.05 | H10: =IFERROR(IF(VLOOKUP($A10,'Annex 2 EHV charges'!$D:$O,12,FALSE)=0,"",VLOOKUP($A10,'Annex 2 EHV charges'!$D:$O,12,FALSE)),"") -> 0.05

Sheet Annex 3 Preserved charges
A1: Back to Overview
A2: =Overview!B4& " - Effective from "&Overview!D4&" - "&Overview!E4&" LV and HV tariffs" -> London Power Networks - Effective from 1 April 2022 - Final LV and HV tariffs
A3: Supercustomer preserved charges/additional LLFCs
B4: Closed LLFCs | C4: PCs | D4: Red/black unit charge p/kWh | E4: Amber/yellow unit charge p/kWh | F4: Green unit charge p/kWh | G4: Fixed charge p/MPAN/day
A6: Notes: | B6: London Power Networks has no Preserved NHH Tariffs/Additional LLFC classes
A11: Site Specific preserved charges/additional LLFCs
B12: Closed LLFCs | C12: PCs | D12: Red/black unit charge p/kWh | E12: Amber/yellow unit charge p/kWh | F12: Green unit charge p/kWh | G12: Fixed charge p/MPAN/day | H12: Capacity charge p/kVA/day | I12: Exceeded capacity charge p/kVA/day | J12: Reactive power charge p/kVArh
A14: Notes: | B14: London Power Networks has no Preserved HH Tariffs/Additional LLFC classes

Sheet Annex 4 LDNO charges
A1: Back to Overview
A2: =Overview!B4& " - Effective from "&Overview!D4&" - "&Overview!E4&" LDNO tariffs" -> London Power Networks - Effective from 1 April 2022 - Final LDNO tariffs
A4: Time Bands for LV and HV Designated Properties | F4: Time Bands for Unmetered Properties
A5: Time periods | B5: Red Time Band | C5: Amber Time Band | D5: Green Time Band | H5: Black Time Band | I5: Yellow Time Band | J5: Green Time Band
A6: Monday to Friday (Including Bank Holidays) All Year | B6: 11:00 - 14:00 16:00 - 19:00 | C6: 07:00 - 11:00 14:00 - 16:00 19:00 - 23:00 | D6: 00:00 - 07:00 23:00 - 24:00 | F6: Monday to Friday (Including Bank Holidays) June to August Inclusive | H6: 11:00 - 14:00 | I6: 07:00 - 11:00 14:00 - 23:00 | J6: 00:00 - 07:00 23:00 - 24:00
A7: Saturday and Sunday All Year | D7: 00:00 - 24:00 | F7: Monday to Friday (Including Bank Holidays) November to February Inclusive | H7: 16:00 - 19:00 | I7: 07:00 - 16:00 19:00 - 23:00 | J7: 00:00 - 07:00 23:00 - 24:00
A8: Notes | B8: All the above times are in UK Clock time | F8: Monday to Friday (Including Bank Holidays) March, April, May and September, October | I8: 07:00 - 23:00 | J8: 00:00 - 07:00 23:00 - 24:00
F9: Saturday and Sunday All year | J9: 00:00 - 24:00
F10: Notes | H10: All the above times are in UK Clock time
A12: Tariff name | B12: Unique billing identifier | C12: PCs | D12: Red/black unit charge p/kWh | E12: Amber/yellow unit charge p/kWh | F12: Green unit charge p/kWh | G12: Fixed charge p/MPAN/day | H12: Capacity charge p/kVA/day | I12: Exceeded capacity charge p/kVA/day | J12: Reactive power charge p/kVArh
A13: LDNO LV: Domestic Aggregated with Residual | B13: A00 | C13: 0, 1, 2 | D13: 6.903 | E13: 1.301 | F13: 0.042 | G13: 10.56
A14: LDNO LV: Domestic Aggregated (Related MPAN) | B14: B00 | C14: 2 | D14: 6.903 | E14: 1.301 | F14: 0.042
A15: LDNO LV: Non-Domestic Aggregated No Residual | B15: C00 | C15: 0, 3, 4, 5-8 | D15: 4.223 | E15: 0.796 | F15: 0.026 | G15: 2.35
A16: LDNO LV: Non-Domestic Aggregated Band 1 | B16: C01 | C16: 0, 3, 4, 5-8 | D16: 4.223 | E16: 0.796 | F16: 0.026 | G16: 1.78
A17: LDNO LV: Non-Domestic Aggregated Band 2 | B17: C02 | C17: 0, 3, 4, 5-8 | D17: 4.132 | E17: 0.705 | F17: 0 | G17: 0.01
A18: LDNO LV: Non-Domestic Aggregated Band 3 | B18: C03 | C18: 0, 3, 4, 5-8 | D18: 4.024 | E18: 0.596 | F18: 0 | G18: 0.01
A19: LDNO LV: Non-Domestic Aggregated Band 4 | B19: C04 | C19: 0, 3, 4, 5-8 | D19: 3.969 | E19: 0.542 | F19: 0 | G19: 0.01
A20: LDNO LV: Non-Domestic Aggregated (related MPAN) | B20: D00 | C20: 4 | D20: 4.223 | E20: 0.796 | F20: 0.026
A21: LDNO LV: LV Site Specific No Residual | B21: E00 | C21: 0 | D21: 3.476 | E21: 0.668 | F21: 0.022 | G21: 5.79 | H21: 3.13 | I21: 4.86 | J21: 0.298
A22: LDNO LV: LV Site Specific Band 1 | B22: E01 | C22: 0 | D22: 3.202 | E22: 0.393 | F22: 0.005 | G22: 1.52 | H22: 3.13 | I22: 4.86 | J22: 0.298
A23: LDNO LV: LV Site Specific Band 2 | B23: E02 | C23: 0 | D23: 3.194 | E23: 0.386 | F23: 0.005 | G23: 1.52 | H23: 3.13 | I23: 4.86 | J23: 0.298
A24: LDNO LV: LV Site Specific Band 3 | B24: E03 | C24: 0 | D24: 3.187 | E24: 0.379 | F24: 0.005 | G24: 1.52 | H24: 3.13 | I24: 4.86 | J24: 0.298
A25: LDNO LV: LV Site Specific Band 4 | B25: E04 | C25: 0 | D25: 3.182 | E25: 0.373 | F25: 0.005 | G25: 1.52 | H25: 3.13 | I25: 4.86 | J25: 0.298
A26: LDNO LV: Unmetered Supplies | B26: U00 | C26: 0, 1 or 8 | D26: 22.323 | E26: 1.663 | F26: 0.21
A27: LDNO LV: LV Generation Aggregated | B27: F00 | C27: 0 | D27: -5.239 | E27: -0.987 | F27: -0.032 | G27: 0
A28: LDNO LV: LV Generation Site Specific | B28: G00 | C28: 0 | D28: -5.239 | E28: -0.987 | F28: -0.032 | G28: 0 | J28: 0.361
A29: LDNO HV: Domestic Aggregated with Residual | B29: A10 | C29: 0, 1, 2 | D29: 5.336 | E29: 1.006 | F29: 0.032 | G29: 10.38
A30: LDNO HV: Domestic Aggregated (Related MPAN) | B30: B10 | C30: 2 | D30: 5.336 | E30: 1.006 | F30: 0.032
A31: LDNO HV: Non-Domestic Aggregated No Residual | B31: C10 | C31: 0, 3, 4, 5-8 | D31: 3.264 | E31: 0.615 | F31: 0.02 | G31: 1.83
A32: LDNO HV: Non-Domestic Aggregated Band 1 | B32: C11 | C32: 0, 3, 4, 5-8 | D32: 3.264 | E32: 0.615 | F32: 0.02 | G32: 1.39
A33: LDNO HV: Non-Domestic Aggregated Band 2 | B33: C12 | C33: 0, 3, 4, 5-8 | D33: 3.194 | E33: 0.545 | F33: 0 | G33: 0.02
A34: LDNO HV: Non-Domestic Aggregated Band 3 | B34: C13 | C34: 0, 3, 4, 5-8 | D34: 3.11 | E34: 0.461 | F34: 0 | G34: 0.02
A35: LDNO HV: Non-Domestic Aggregated Band 4 | B35: C14 | C35: 0, 3, 4, 5-8 | D35: 3.068 | E35: 0.419 | F35: 0 | G35: 0.02
A36: LDNO HV: Non-Domestic Aggregated (related MPAN) | B36: D10 | C36: 4 | D36: 3.264 | E36: 0.615 | F36: 0.02
A37: LDNO HV: LV Site Specific No Residual | B37: E10 | C37: 0 | D37: 2.687 | E37: 0.516 | F37: 0.017 | G37: 4.49 | H37: 2.42 | I37: 3.75 | J37: 0.23
A38: LDNO HV: LV Site Specific Band 1 | B38: E11 | C38: 0 | D38: 2.475 | E38: 0.304 | F38: 0.004 | G38: 1.19 | H38: 2.42 | I38: 3.75 | J38: 0.23
A39: LDNO HV: LV Site Specific Band 2 | B39: E12 | C39: 0 | D39: 2.469 | E39: 0.298 | F39: 0.004 | G39: 1.19 | H39: 2.42 | I39: 3.75 | J39: 0.23
A40: LDNO HV: LV Site Specific Band 3 | B40: E13 | C40: 0 | D40: 2.464 | E40: 0.293 | F40: 0.004 | G40: 1.19 | H40: 2.42 | I40: 3.75 | J40: 0.23
A41: LDNO HV: LV Site Specific Band 4 | B41: E14 | C41: 0 | D41: 2.459 | E41: 0.289 | F41: 0.004 | G41: 1.19 | H41: 2.42 | I41: 3.75 | J41: 0.23
A42: LDNO HV: LV Sub Site Specific No Residual | B42: J10 | C42: 0 | D42: 2.539 | E42: 0.513 | F42: 0.019 | G42: 4.6 | H42: 5.9 | I42: 6.72 | J42: 0.189
...

Sheet Annex 5 LLFs
A1: Back to Overview
A2: These line loss factors are illustrative based on the latest calculated values and are published in good faith. However, the line loss factors that are approved by the BSC Panel for the applicable year and consequently published on the Elexon website will take precedence and will be used in Settlement if they differ from these values.
A3: =Overview!B4& " - Illustrative LLFs for year beginning "&Overview!D4 -> London Power Networks - Illustrative LLFs for year beginning 1 April 2022
A4: Time periods | C4: Period 1 | D4: Period 2 | E4: Period 3 | F4: Period 4 | G4: Period 5
C5: Winter Peak | D5: Summer Peak | E5: Winter Shoulder | F5: Night | G5: Other
A6: Monday to Friday November to February | C6: 16:00 - 19:59 | E6: 07:00 - 15:59
A7: Monday to Friday June to August | D7: 07:00 - 19:59
A8: Monday to Friday March | E8: 07:00 - 19:59
A9: All Year | F9: 00:00 - 06:59 | G9: All Other Times
A10: Notes | C10: All the above times are in UK Clock time
A13: Generic demand and generation LLFs
A14: Metered voltage, respective periods and associated LLFCs
A15: Metered voltage | B15: Period 1 | C15: Period 2 | D15: Period 3 | E15: Period 4 | F15: Period 5 | G15: Associated LLFC
A16: Low-voltage network | B16: 1.11 | C16: 1.089 | D16: 1.101 | E16: 1.071 | F16: 1.089 | G16: 1, 2, 9, 19, 69, 70, 71, 72, 73, 74, 199, 200, 201, 202, 203, 204, 350, 400, 420, 421, 422, 423, 424, 425, 426, 427, 428, 429, 430, 431, 432, 433, 434, 435, 750, 762, 765, 902, 906, 911, 952, 956, 964, 980, 981, 982, 983, 932
A17: Low-voltage substation | B17: 1.061 | C17: 1.053 | D17: 1.057 | E17: 1.043 | F17: 1.051 | G17: 79, 80, 81, 82, 83, 84, 756, 781, 782, 984, 985, 986, 987
A18: High-voltage network | B18: 1.038 | C18: 1.033 | D18: 1.036 | E18: 1.026 | F18: 1.032 | G18: 89, 90, 91, 92, 93, 94, 359, 751, 767, 988, 989, 990, 991
A19: High-voltage substation | B19: 1.03 | C19: 1.028 | D19: 1.029 | E19: 1.025 | F19: 1.027 | G19: 771, 791, 792
A20: 33kV generic | B20: 1.022 | C20: 1.02 | D20: 1.021 | E20: 1.018 | F20: 1.02 | G20: 796, 797
A21: 132kV generic | B21: 1.002 | C21: 1.002 | D21: 1.002 | E21: 1.002 | F21: 1.002 | G21: 798, 799
A23: EHV site specific LLFs
A24: Demand
A25: Site | B25: Period 1 | C25: Period 2 | D25: Period 3 | E25: Period 4 | F25: Period 5 | G25: Associated LLFC
A26: FENCHS - Import | B26: 1.009 | C26: 1.007 | D26: 1.009 | E26: 1.006 | F26: 1.007 | G26: 800
A27: LU_CHA - Import | B27: 1.006 | C27: 1.006 | D27: 1.006 | E27: 1.006 | F27: 1.006 | G27: 801
A28: THAMEC - Import | B28: 1.001 | C28: 1.001 | D28: 1.001 | E28: 1.001 | F28: 1.001 | G28: 802
A29: VOLTDC - Import | B29: 1.006 | C29: 1.005 | D29: 1.006 | E29: 1.005 | F29: 1.006 | G29: 803
A30: LU_HOX - Import | B30: 1.022 | C30: 1.02 | D30: 1.021 | E30: 1.018 | F30: 1.02 | G30: 804
A31: BRDGTE - Import | B31: 1.012 | C31: 1.011 | D31: 1.012 | E31: 1.008 | F31: 1.008 | G31: 805
A32: MRKLNE - Import | B32: 1.007 | C32: 1.006 | D32: 1.007 | E32: 1.006 | F32: 1.006 | G32: 806
A33: NR_BOW - Import | B33: 1.012 | C33: 1.013 | D33: 1.013 | E33: 1.012 | F33: 1.013 | G33: 807
A34: Leadenhall St. - IMPORT | B34: 1.01 | C34: 1.007 | D34: 1.01 | E34: 1.006 | F34: 1.008 | G34: 808
A35: TELEHW - Import | B35: 1 | C35: 1 | D35: 1 | E35: 1 | F35: 1 | G35: 809
A36: 22BSHP - Import | B36: 1.014 | C36: 1.015 | D36: 1.015 | E36: 1.013 | F36: 1.013 | G36: 810
A37: BISHPC - Import | B37: 1.02 | C37: 1.019 | D37: 1.019 | E37: 1.019 | F37: 1.019 | G37: 811
... A65: NR_WHI - Import | B65: 1.04 | C65: 1.035 | D65: 1.044 | E65: 1.024 | F65: 1.033 | G65: 849
A67: EHV site specific LLFs
A68: Generation
A69: Site | B69: Period 1 | C69: Period 2 | D69: Period 3 | E69: Period 4 | F69: Period 5 | G69: Associated LLFC
A70: THAMEB - Export | B70: 0.999 | C70: 0.999 | D70: 0.999 | E70: 0.999 | F70: 0.999 | G70: 701
A71: THAMEC - Export | B71: 1 | C71: 0.999 | D71: 1 | E71: 0.999 | F71: 1 | G71: 702
...

Sheet Annex 6 New or Amended EHV
A1: Back to Overview | H1: Note: The list of MPANs/MSIDs provided may be incomplete; the DNO reserves the right to apply the listed charges to any other MPANs/MSIDs associated with the site. If sites appear in both Annex 2 and Annex 6, the charges in Annex 6 take precedence. Where an existing Designated EHV Property is modified and energised in the charging year, we may revise the EDCM charges for the modified Designated EHV Property.
A2: Annex 6 - Charges for New or Amended Designated EHV Properties
A4: =Overview!B4& " - Effective from "&Overview!D4&" - "&Overview!E4&" new designated EHV charges" -> London Power Networks - Effective from 1 April 2022 - Final new designated EHV charges
A5: Effective from date | B5: Import Unique Identifier | C5: LLFC | D5: Import MPANs/MSIDs | E5: Export Unique Identifier | F5: LLFC | G5: Export MPANs/MSIDs | H5: Name | I5: ='Annex 2 EHV charges'!H10 -> Import Super Red unit charge (p/kWh) | J5: ='Annex 2 EHV charges'!I10 -> Import fixed charge (p/day) | K5: ='Annex 2 EHV charges'!J10 -> Import capacity charge (p/kVA/day) | L5: ='Annex 2 EHV charges'!K10 -> Import exceeded capacity charge (p/kVA/day) | M5: ='Annex 2 EHV charges'!L10 -> Export Super Red unit charge (p/kWh) | N5: ='Annex 2 EHV charges'!M10 -> Export fixed charge (p/day) | O5: ='Annex 2 EHV charges'!N10 -> Export capacity charge (p/kVA/day) | P5: ='Annex 2 EHV charges'!O10 -> Export exceeded capacity charge (p/kVA/day)
A6: 01/04/2022 | B6: BELVED | C6: 815 | D6: 1200060787109 | E6: BELVED | F6: 711 | G6: 1200060787118 | H6: BELVED | I6: 0 | J6: 331.69 | K6: 0.46 | L6: 0.46 | M6: 0 | N6: 628.26 | O6: 0.05 | P6: 0.05
A7: 01/04/2022 | B7: SELCHP | C7: 827 | D7: 1200010175650 | E7: SELCHP | F7: 730 | G7: 1200010258304 | H7: SELCHP | I7: 0 | J7: 292.78 | K7: 0.64 | L7: 0.64 | M7: 0 | N7: 3105.2 | O7: 0.05 | P7: 0.05
A8: 01/04/2022 | B8: 21MOOR | C8: 854 | D8: 1200062747376 1200062747385 | H8: 21MOOR | I8: 0.364 | J8: 6073.31 | K8: 2.3 | L8: 2.3
A16: =Overview!B4& " - Effective from "&Overview!D4&" - "&Overview!E4&" new designated EHV line loss factors" -> London Power Networks - Effective from 1 April 2022 - Final new designated EHV line loss factors
A17: Effective from date | B17: Import Unique Identifier | C17: LLFC | D17: Import MPANs/MSIDs | E17: Export Unique Identifier | F17: LLFC | G17: Export MPANs/MSIDs | H17: Name | I17: Import LLF period 1 | J17: Import LLF period 2 | K17: Import LLF period 3 | L17: Import LLF period 4 | M17: Import LLF period 5 | N17: Export LLF period 1 | O17: Export LLF period 2 | P17: Export LLF period 3 | Q17: Export LLF period 4 | R17: Export LLF period 5
A18: 01/04/2022 | B18: BELVED | C18: 815 | D18: 1200060787109 | E18: BELVED | F18: 711 | G18: 1200060787118 | H18: BELVED | I18: 1.003 | J18: 1.003 | K18: 1.003 | L18: 1.003 | M18: 1.003 | N18: 0.999 | O18: 0.998 | P18: 0.999 | Q18: 0.998 | R18: 0.998
A19: 01/04/2022 | B19: SELCHP | C19: 827 | D19: 1200010175650 | E19: SELCHP | F19: 730 | G19: 1200010258304 | H19: SELCHP | I19: 1.025 | J19: 1.025 | K19: 1.025 | L19: 1.025 | M19: 1.025 | N19: 1 | O19: 1 | P19: 1 | Q19: 1 | R19: 1
A20: 01/04/2022 | B20: 21MOOR | C20: 854 | D20: 1200062747376 1200062747385 | H20: 21MOOR | I20: 1.022 | J20: 1.02 | K20: 1.021 | L20: 1.018 | M20: 1.02

Sheet Annex 7 Pass-Through Costs
A1: Back to Overview
A2: =Overview!B4& " - Effective from "&Overview!D4&" - "&Overview!E4&" Supplier of Last Resort and Eligible Bad Debt Pass-Through Costs" -> London Power Networks - Effective from 1 April 2022 - Final Supplier of Last Resort and Eligible Bad Debt Pass-Through Costs
A4: Tariff name | B4: Open LLFCs / LDNO unique billing identifier | C4: PCs | D4: Supplier of Last Resort Fixed charge adder* p/MPAN/day | E4: Excess Supplier of Last Resort Fixed charge adder** p/MPAN/day | F4: Eligible Bad Debt Fixed charge adder*** p/MPAN/day
A5: Domestic Aggregated with Residual | B5: =IFERROR(INDEX('Annex 1 LV, HV and UMS charges'!$B$12:$B$44,MATCH($A5,'Annex 1 LV, HV and UMS charges'!$A$12:$A$44,0)),IF(INDEX('Annex 4 LDNO charges'!$B$11:$B$202,MATCH($A5,'Annex 4 LDNO charges'!$A$11:$A$202,0))=0,"",INDEX('Annex 4 LDNO charges'!$B$11:$B$202,MATCH($A5,'Annex 4 LDNO charges'!$A$11:$A$202,0)))) -> 1 | C5: =IFERROR(INDEX('Annex 1 LV, HV and UMS charges'!$C$13:$C$44,MATCH($A5,'Annex 1 LV, HV and UMS charges'!$A$13:$A$44,0)),INDEX('Annex 4 LDNO charges'!$C$13:$C$202,MATCH($A5,'Annex 4 LDNO charges'!$A$13:$A$202,0))) -> 0, 1, 2 | D5: 0.05859276 | E5: 9.6543478 | F5: 0.052226762
A6: Non-Domestic Aggregated No Residual | B6: =IFERROR(INDEX('Annex 1 LV, HV and UMS charges'!$B$12:$B$44,MATCH($A6,'Annex 1 LV, HV and UMS charges'!$A$12:$A$44,0)),IF(INDEX('Annex 4 LDNO charges'!$B$11:$B$202,MATCH($A6,'Annex 4 LDNO charges'!$A$11:$A$202,0))=0,"",INDEX('Annex 4 LDNO charges'!$B$11:$B$202,MATCH($A6,'Annex 4 LDNO charges'!$A$11:$A$202,0)))) -> 199 | C6: =IFERROR(INDEX('Annex 1 LV, HV and UMS charges'!$C$13:$C$44,MATCH($A6,'Annex 1 LV, HV and UMS charges'!$A$13:$A$44,0)),INDEX('Annex 4 LDNO charges'!$C$13:$C$202,MATCH($A6,'Annex 4 LDNO charges'!$A$13:$A$202,0))) -> 0, 3, 4, 5-8 | F6: 0.052226762
A7: Non-Domestic Aggregated Band 1 | B7: =IFERROR(INDEX('Annex 1 LV, HV and UMS charges'!$B$12:$B$44,MATCH($A7,'Annex 1 LV, HV and UMS charges'!$A$12:$A$44,0)),IF(INDEX('Annex 4 LDNO charges'!$B$11:$B$202,MATCH($A7,'Annex 4 LDNO charges'!$A$11:$A$202,0))=0,"",INDEX('Annex 4 LDNO charges'!$B$11:$B$202,MATCH($A7,'Annex 4 LDNO charges'!$A$11:$A$202,0)))) -> 201 | C7: =IFERROR(INDEX('Annex 1 LV, HV and UMS charges'!$C$13:$C$44,MATCH($A7,'Annex 1 LV, HV and UMS charges'!$A$13:$A$44,0)),INDEX('Annex 4 LDNO charges'!$C$13:$C$202,MATCH($A7,'Annex 4 LDNO charges'!$A$13:$A$202,0))) -> 0, 3, 4, 5-8 | F7: 0.052226762
A8: Non-Domestic Aggregated Band 2 | B8: =IFERROR(INDEX('Annex 1 LV, HV and UMS charges'!$B$12:$B$44,MATCH($A8,'Annex 1 LV, HV and UMS charges'!$A$12:$A$44,0)),IF(INDEX('Annex 4 LDNO charges'!$B$11:$B$202,MATCH($A8,'Annex 4 LDNO charges'!$A$11:$A$202,0))=0,"",INDEX('Annex 4 LDNO charges'!$B$11:$B$202,MATCH($A8,'Annex 4 LDNO charges'!$A$11:$A$202,0)))) -> 202 | C8: =IFERROR(INDEX('Annex 1 LV, HV and UMS charges'!$C$13:$C$44,MATCH($A8,'Annex 1 LV, HV and UMS charges'!$A$13:$A$44,0)),INDEX('Annex 4 LDNO charges'!$C$13:$C$202,MATCH($A8,'Annex 4 LDNO charges'!$A$13:$A$202,0))) -> 0, 3, 4, 5-8 | F8: 0.052226762
A9: Non-Domestic Aggregated Band 3 | B9: =IFERROR(INDEX('Annex 1 LV, HV and UMS charges'!$B$12:$B$44,MATCH($A9,'Annex 1 LV, HV and UMS charges'!$A$12:$A$44,0)),IF(INDEX('Annex 4 LDNO charges'!$B$11:$B$202,MATCH($A9,'Annex 4 LDNO charges'!$A$11:$A$202,0))=0,"",INDEX('Annex 4 LDNO charges'!$B$11:$B$202,MATCH($A9,'Annex 4 LDNO charges'!$A$11:$A$202,0)))) -> 203 | C9: =IFERROR(INDEX('Annex 1 LV, HV and UMS charges'!$C$13:$C$44,MATCH($A9,'Annex 1 LV, HV and UMS charges'!$A$13:$A$44,0)),INDEX('Annex 4 LDNO charges'!$C$13:$C$202,MATCH($A9,'Annex 4 LDNO charges'!$A$13:$A$202,0))) -> 0, 3, 4, 5-8 | F9: 0.052226762
A10: Non-Domestic Aggregated Band 4 | B10: =IFERROR(INDEX('Annex 1 LV, HV and UMS charges'!$B$12:$B$44,MATCH($A10,'Annex 1 LV, HV and UMS charges'!$A$12:$A$44,0)),IF(INDEX('Annex 4 LDNO charges'!$B$11:$B$202,MATCH($A10,'Annex 4 LDNO charges'!$A$11:$A$202,0))=0,"",INDEX('Annex 4 LDNO charges'!$B$11:$B$202,MATCH($A10,'Annex 4 LDNO charges'!$A$11:$A$202,0)))) -> 204 | C10: =IFERROR(INDEX('Annex 1 LV, HV and UMS charges'!$C$13:$C$44,MATCH($A10,'Annex 1 LV, HV and UMS charges'!$A$13:$A$44,0)),INDEX('Annex 4 LDNO charges'!$C$13:$C$202,MATCH($A10,'Annex 4 LDNO charges'!$A$13:$A$202,0))) -> 0, 3, 4, 5-8 | F10: 0.052226762
A11: LV Site Specific No Residual | B11: =IFERROR(INDEX('Annex 1 LV, HV and UMS charges'!$B$12:$B$44,MATCH($A11,'Annex 1 LV, HV and UMS charges'!$A$12:$A$44,0)),IF(INDEX('Annex 4 LDNO charges'!$B$11:$B$202,MATCH($A11,'Annex 4 LDNO charges'!$A$11:$A$202,0))=0,"",INDEX('Annex 4 LDNO charges'!$B$11:$B$202,MATCH($A11,'Annex 4 LDNO charges'!$A$11:$A$202,0)))) -> 70 | C11: =IFERROR(INDEX('Annex 1 LV, HV and UMS charges'!$C$13:$C$44,MATCH($A11,'Annex 1 LV, HV and UMS charges'!$A$13:$A$44,0)),INDEX('Annex 4 LDNO charges'!$C$13:$C$202,MATCH($A11,'Annex 4 LDNO charges'!$A$13:$A$202,0))) -> 0 | F11: 0.052226762
A12: LV Site Specific Band 1 | B12: =IFERROR(INDEX('Annex 1 LV, HV and UMS charges'!$B$12:$B$44,MATCH($A12,'Annex 1 LV, HV and UMS charges'!$A$12:$A$44,0)),IF(INDEX('Annex 4 LDNO charges'!$B$11:$B$202,MATCH($A12,'Annex 4 LDNO charges'!$A$11:$A$202,0))=0,"",INDEX('Annex 4 LDNO charges'!$B$11:$B$202,MATCH($A12,'Annex 4 LDNO charges'!$A$11:$A$202,0)))) -> 71 | C12: =IFERROR(INDEX('Annex 1 LV, HV and UMS charges'!$C$13:$C$44,MATCH($A12,'Annex 1 LV, HV and UMS charges'!$A$13:$A$44,0)),INDEX('Annex 4 LDNO charges'!$C$13:$C$202,MATCH($A12,'Annex 4 LDNO charges'!$A$13:$A$202,0))) -> 0 | F12: 0.052226762
A13: LV Site Specific Band 2 | B13: =IFERROR(INDEX('Annex 1 LV, HV and UMS charges'!$B$12:$B$44,MATCH($A13,'Annex 1 LV, HV and UMS charges'!$A$12:$A$44,0)),IF(INDEX('Annex 4 LDNO charges'!$B$11:$B$202,MATCH($A13,'Annex 4 LDNO charges'!$A$11:$A$202,0))=0,"",INDEX('Annex 4 LDNO charges'!$B$11:$B$202,MATCH($A13,'Annex 4 LDNO charges'!$A$11:$A$202,0)))) -> 72 | C13: =IFERROR(INDEX('Annex 1 LV, HV and UMS charges'!$C$13:$C$44,MATCH($A13,'Annex 1 LV, HV and UMS charges'!$A$13:$A$44,0)),INDEX('Annex 4 LDNO charges'!$C$13:$C$202,MATCH($A13,'Annex 4 LDNO charges'!$A$13:$A$202,0))) -> 0 | F13: 0.052226762
A14: LV Site Specific Band 3 | B14: =IFERROR(INDEX('Annex 1 LV, HV and UMS charges'!$B$12:$B$44,MATCH($A14,'Annex 1 LV, HV and UMS charges'!$A$12:$A$44,0)),IF(INDEX('Annex 4 LDNO charges'!$B$11:$B$202,MATCH($A14,'Annex 4 LDNO charges'!$A$11:$A$202,0))=0,"",INDEX('Annex 4 LDNO charges'!$B$11:$B$202,MATCH($A14,'Annex 4 LDNO charges'!$A$11:$A$202,0)))) -> 73 | C14: =IFERROR(INDEX('Annex 1 LV, HV and UMS charges'!$C$13:$C$44,MATCH($A14,'Annex 1 LV, HV and UMS charges'!$A$13:$A$44,0)),INDEX('Annex 4 LDNO charges'!$C$13:$C$202,MATCH($A14,'Annex 4 LDNO charges'!$A$13:$A$202,0))) -> 0 | F14: 0.052226762
A15: LV Site Specific Band 4 | B15: =IFERROR(INDEX('Annex 1 LV, HV and UMS charges'!$B$12:$B$44,MATCH($A15,'Annex 1 LV, HV and UMS charges'!$A$12:$A$44,0)),IF(INDEX('Annex 4 LDNO charges'!$B$11:$B$202,MATCH($A15,'Annex 4 LDNO charges'!$A$11:$A$202,0))=0,"",INDEX('Annex 4 LDNO charges'!$B$11:$B$202,MATCH($A15,'Annex 4 LDNO charges'!$A$11:$A$202,0)))) -> 74 | C15: =IFERROR(INDEX('Annex 1 LV, HV and UMS charges'!$C$13:$C$44,MATCH($A15,'Annex 1 LV, HV and UMS charges'!$A$13:$A$44,0)),INDEX('Annex 4 LDNO charges'!$C$13:$C$202,MATCH($A15,'Annex 4 LDNO charges'!$A$13:$A$202,0))) -> 0 | F15: 0.052226762
A16: LV Sub Site Specific No Residual | B16: =IFERROR(INDEX('Annex 1 LV, HV and UMS charges'!$B$12:$B$44,MATCH($A16,'Annex 1 LV, HV and UMS charges'!$A$12:$A$44,0)),IF(INDEX('Annex 4 LDNO charges'!$B$11:$B$202,MATCH($A16,'Annex 4 LDNO charges'!$A$11:$A$202,0))=0,"",INDEX('Annex 4 LDNO charges'!$B$11:$B$202,MATCH($A16,'Annex 4 LDNO charges'!$A$11:$A$202,0)))) -> 80 | C16: =IFERROR(INDEX('Annex 1 LV, HV and UMS charges'!$C$13:$C$44,MATCH($A16,'Annex 1 LV, HV and UMS charges'!$A$13:$A$44,0)),INDEX('Annex 4 LDNO charges'!$C$13:$C$202,MATCH($A16,'Annex 4 LDNO charges'!$A$13:$A$202,0))) -> 0 | F16: 0.052226762
A17: LV Sub Site Specific Band 1 | B17: =IFERROR(INDEX('Annex 1 LV, HV and UMS charges'!$B$12:$B$44,MATCH($A17,'Annex 1 LV, HV and UMS charges'!$A$12:$A$44,0)),IF(INDEX('Annex 4 LDNO charges'!$B$11:$B$202,MATCH($A17,'Annex 4 LDNO charges'!$A$11:$A$202,0))=0,"",INDEX('Annex 4 LDNO charges'!$B$11:$B$202,MATCH($A17,'Annex 4 LDNO charges'!$A$11:$A$202,0)))) -> 81 | C17: =IFERROR(INDEX('Annex 1 LV, HV and UMS charges'!$C$13:$C$44,MATCH($A17,'Annex 1 LV, HV and UMS charges'!$A$13:$A$44,0)),INDEX('Annex 4 LDNO charges'!$C$13:$C$202,MATCH($A17,'Annex 4 LDNO charges'!$A$13:$A$202,0))) -> 0 | F17: 0.052226762
... A25: HV Site Specific Band 4 | B25: =IFERROR(INDEX('Annex 1 LV, HV and UMS charges'!$B$12:$B$44,MATCH($A25,'Annex 1 LV, HV and UMS charges'!$A$12:$A$44,0)),IF(INDEX('Annex 4 LDNO charges'!$B$11:$B$202,MATCH($A25,'Annex 4 LDNO charges'!$A$11:$A$202,0))=0,"",INDEX('Annex 4 LDNO charges'!$B$11:$B$202,MATCH($A25,'Annex 4 LDNO charges'!$A$11:$A$202,0)))) -> 94 | C25: =IFERROR(INDEX('Annex 1 LV, HV and UMS charges'!$C$13:$C$44,MATCH($A25,'Annex 1 LV, HV and UMS charges'!$A$13:$A$44,0)),INDEX('Annex 4 LDNO charges'!$C$13:$C$202,MATCH($A25,'Annex 4 LDNO charges'!$A$13:$A$202,0))) -> 0 | F25: 0.052226762
A26: LDNO LV: Domestic Aggregated with Residual | B26: =IFERROR(INDEX('Annex 1 LV, HV and UMS charges'!$B$12:$B$44,MATCH($A26,'Annex 1 LV, HV and UMS charges'!$A$12:$A$44,0)),IF(INDEX('Annex 4 LDNO charges'!$B$11:$B$202,MATCH($A26,'Annex 4 LDNO charges'!$A$11:$A$202,0))=0,"",INDEX('Annex 4 LDNO charges'!$B$11:$B$202,MATCH($A26,'Annex 4 LDNO charges'!$A$11:$A$202,0)))) -> A00 | C26: =IFERROR(INDEX('Annex 1 LV, HV and UMS charges'!$C$13:$C$44,MATCH($A26,'Annex 1 LV, HV and UMS charges'!$A$13:$A$44,0)),INDEX('Annex 4 LDNO charges'!$C$13:$C$202,MATCH($A26,'Annex 4 LDNO charges'!$A$13:$A$202,0))) -> 0, 1, 2 | D26: 0.05859276 | E26: 9.6543478 | F26: 0.052226762
A27: LDNO LV: Non-Domestic Aggregated No Residual | B27: =IFERROR(INDEX('Annex 1 LV, HV and UMS charges'!$B$12:$B$44,MATCH($A27,'Annex 1 LV, HV and UMS charges'!$A$12:$A$44,0)),IF(INDEX('Annex 4 LDNO charges'!$B$11:$B$202,MATCH($A27,'Annex 4 LDNO charges'!$A$11:$A$202,0))=0,"",INDEX('Annex 4 LDNO charges'!$B$11:$B$202,MATCH($A27,'Annex 4 LDNO charges'!$A$11:$A$202,0)))) -> C00 | C27: =IFERROR(INDEX('Annex 1 LV, HV and UMS charges'!$C$13:$C$44,MATCH($A27,'Annex 1 LV, HV and UMS charges'!$A$13:$A$44,0)),INDEX('Annex 4 LDNO charges'!$C$13:$C$202,MATCH($A27,'Annex 4 LDNO charges'!$A$13:$A$202,0))) -> 0, 3, 4, 5-8 | F27: 0.052226762
A28: LDNO LV: Non-Domestic Aggregated Band 1 | B28: =IFERROR(INDEX('Annex 1 LV, HV and UMS charges'!$B$12:$B$44,MATCH($A28,'Annex 1 LV, HV and UMS charges'!$A$12:$A$44,0)),IF(INDEX('Annex 4 LDNO charges'!$B$11:$B$202,MATCH($A28,'Annex 4 LDNO charges'!$A$11:$A$202,0))=0,"",INDEX('Annex 4 LDNO charges'!$B$11:$B$202,MATCH($A28,'Annex 4 LDNO charges'!$A$11:$A$202,0)))) -> C01 | C28: =IFERROR(INDEX('Annex 1 LV, HV and UMS charges'!$C$13:$C$44,MATCH($A28,'Annex 1 LV, HV and UMS charges'!$A$13:$A$44,0)),INDEX('Annex 4 LDNO charges'!$C$13:$C$202,MATCH($A28,'Annex 4 LDNO charges'!$A$13:$A$202,0))) -> 0, 3, 4, 5-8 | F28: 0.052226762
