Workbook
Name OLE_LINK1: 'Annex 3 Preserved charges'!#REF!

Sheet Overview
A2: Company and Licence name, charging year, effective from, status
B3: Company and Licence name | C3: Year | D3: Effective From | E3: Status
A4: Company and Licence name, charging year, effective from, status | B4: South Eastern Power Networks | C4: 2024/25 | D4: 1 April 2024 | E4: Final
A6: List of data tables in this workbook
A7: Worksheet | B7: Information
A8: Annex 1 LV, HV and Unmetered Supplies charges | B8: Annex 1 contains the charges to LV and HV Designated Properties and Unmetered Supplies.
A9: Annex 2 EHV charges | B9: ="Annex 2 contains the charges to Designated EHV Properties and charges applied to LDNOs with Designated EHV Properties/end-users embedded in networks within the " &B4 &" Licence area." -> Annex 2 contains the charges to Designated EHV Properties and charges applied to LDNOs with Designated EHV Properties/end-users embedded in networks within the South Eastern Power Networks Licence area.
A10: Annex 3 Preserved charges | B10: Annex 3 contains details of any preserved and additional charges that are valid at this time.
A11: Annex 4 LDNO charges | B11: ="Annex 4 contains charges that are levied on the owner of an embedded network within the "&B4&" Licence area. "&"Electricity suppliers and consumers who have properties connected to an embedded network should contact the embedded network owner to determine their distribution charges."&" The charges listed in this table are not payable by domestic consumers, business consumers or electricity suppliers." -> Annex 4 contains charges that are levied on the owner of an embedded network within the South Eastern Power Networks Licence area. Electricity suppliers and consumers who have properties connected to an embedded network should contact the embedded network owner to determine their distribution charges. The charges listed in this table are not payable by domestic consumers, business consumers or electricity suppliers.
A12: Annex 5 LLFs | B12: Annex 5 has been intentionally left blank as this charging statement is published a complete year before the LLFs have been audited. The line loss factors that are approved by the BSC Panel for the applicable year and consequently published on the Elexon website will take precedence and be used in Settlement. This annex will be re-published with these values once they are available.
A13: Annex 6 Charges for New or Amended Designated EHV Properties | B13: ="Annex 6 contains the charges for new or amended Designated EHV Properties and charges applied to LDNOs with new or amended Designated EHV Properties/end-users embedded in networks within the " &B4 &" Licence area." -> Annex 6 contains the charges for new or amended Designated EHV Properties and charges applied to LDNOs with new or amended Designated EHV Properties/end-users embedded in networks within the South Eastern Power Networks Licence area.
A14: Annex 7 Fixed adders for Supplier of Last Resort and Eligible Bad Debt pass-through costs | B14: Annex 7 contains the fixed adders to recover Supplier of Last Resort and Eligible Bad Debt pass-through costs. The Excess Supplier of Last Resort fixed adder relates to an increase to previously published charges only.
A15: Nodal prices | B15: Contains the underlying nodal group costs used to calculate the current EDCM charges.
A16: Residual Charging Bandings | B16: Contains the four Residual charging band allocation for Customers
A17: Charge calculator | B17: Charge calculator is a tool to help you estimate your distribution charges using current consumption data and forecast consumption data.
A19: Notes to users of this spreadsheet
A21: Please use this spreadsheet with reference to the LC14 use of system charging statement.
A23: Notes to DNOs populating this spreadsheet
A25: DNOs must endeavour to maintain consistency in the structure of this spreadsheet. Any changes to the structure must be noted in the 'Notes to users of this spreadsheet'
A26: The drop down list on the charge calculator can be expanded by unprotecting the charge calculator sheet and selecting 'data', 'data validation...' and then expanding the 'source' data range. The sheet can then be protected.

Sheet Annex 1 LV, HV and UMS charges
A1: Back to Overview | B1: 'DNOs paste value cells A15:J47 from CDCM 3701 into cells A14:J46
A2: =Overview!B4& " - Effective from "&Overview!D4&" - "&Overview!E4&" LV and HV charges" -> South Eastern Power Networks - Effective from 1 April 2024 - Final LV and HV charges
A4: Time Bands for LV and HV Designated Properties | G4: Time Bands for Unmetered Properties
A5: Time periods | B5: Red Time Band | C5: Amber Time Band | E5: Green Time Band | I5: Black Time Band | J5: Yellow Time Band | K5: Green Time Band
A6: Monday to Friday (Including Bank Holidays) All Year | B6: 16:00 - 19:00 | C6: 07:00 - 16:00 19:00 - 23:00 | E6: 00:00 - 07:00 23:00 - 24:00 | G6: Monday to Friday (Including Bank Holidays) November to February Inclusive | I6: 16:00 - 19:00 | J6: 07:00 - 16:00 19:00 - 23:00 | K6: 00:00 - 07:00 23:00 - 24:00
A7: Saturday and Sunday All Year | E7: 00:00 - 24:00 | G7: Monday to Friday (Including Bank Holidays) March to October Inclusive | J7: 07:00 - 23:00 | K7: 00:00 - 07:00 23:00 - 24:00
A8: Notes | B8: All the above times are in UK Clock time | G8: Saturday and Sunday All Year | K8: 00:00 - 24:00
G9: Notes | I9: All the above times are in UK Clock time
A11: Tariff name | B11: Open LLFCs | C11: PCs | D11: Red/black unit charge p/kWh | E11: Amber/yellow unit charge p/kWh | F11: Green unit charge p/kWh | G11: Fixed charge p/MPAN/day | H11: Capacity charge p/kVA/day | I11: Exceeded capacity charge p/kVA/day | J11: Reactive power charge p/kVArh | K11: Closed LLFCs
A12: Domestic Aggregated or CT with Residual | B12: 1 | C12: 0, 1, 2 | D12: 17.48 | E12: 0.656 | F12: 0.224 | G12: 20 | K12: 100, 300
A13: Domestic Aggregated (Related MPAN) | B13: 2 | C13: 2 | D13: 17.48 | E13: 0.656 | F13: 0.224 | K13: 251
A14: Non-Domestic Aggregated or CT No Residual | B14: 199 | C14: 0, 3, 4, 5-8 | D14: 11.894 | E14: 0.446 | F14: 0.152 | G14: 6.1
A15: Non-Domestic Aggregated or CT Band 1 | B15: 201 | C15: 0, 3, 4, 5-8 | D15: 11.894 | E15: 0.446 | F15: 0.152 | G15: 11.78 | K15: 200, 320
A16: Non-Domestic Aggregated or CT Band 2 | B16: 202 | C16: 0, 3, 4, 5-8 | D16: 11.894 | E16: 0.446 | F16: 0.152 | G16: 37.16
A17: Non-Domestic Aggregated or CT Band 3 | B17: 203 | C17: 0, 3, 4, 5-8 | D17: 11.894 | E17: 0.446 | F17: 0.152 | G17: 78.22
A18: Non-Domestic Aggregated or CT Band 4 | B18: 204 | C18: 0, 3, 4, 5-8 | D18: 11.894 | E18: 0.446 | F18: 0.152 | G18: 229.77
A19: Non-Domestic Aggregated (related MPAN) | B19: 200 | C19: 4 | D19: 11.894 | E19: 0.446 | F19: 0.152 | K19: 287
A20: LV Site Specific No Residual | B20: 70 | C20: 0 | D20: 9.862 | E20: 0.358 | F20: 0.12 | G20: 18.94 | H20: 4.34 | I20: 7.73 | J20: 0.32
A21: LV Site Specific Band 1 | B21: 71 | C21: 0 | D21: 9.862 | E21: 0.358 | F21: 0.12 | G21: 439.77 | H21: 4.34 | I21: 7.73 | J21: 0.32
A22: LV Site Specific Band 2 | B22: 72 | C22: 0 | D22: 9.862 | E22: 0.358 | F22: 0.12 | G22: 728.02 | H22: 4.34 | I22: 7.73 | J22: 0.32
A23: LV Site Specific Band 3 | B23: 73 | C23: 0 | D23: 9.862 | E23: 0.358 | F23: 0.12 | G23: 1176.88 | H23: 4.34 | I23: 7.73 | J23: 0.32
A24: LV Site Specific Band 4 | B24: 74 | C24: 0 | D24: 9.862 | E24: 0.358 | F24: 0.12 | G24: 2596.04 | H24: 4.34 | I24: 7.73 | J24: 0.32
A25: LV Sub Site Specific No Residual | B25: 80 | C25: 0 | D25: 6.35 | E25: 0.215 | F25: 0.069 | G25: 16.01 | H25: 6.32 | I25: 8.03 | J25: 0.201
A26: LV Sub Site Specific Band 1 | B26: 81 | C26: 0 | D26: 6.35 | E26: 0.215 | F26: 0.069 | G26: 436.84 | H26: 6.32 | I26: 8.03 | J26: 0.201
A27: LV Sub Site Specific Band 2 | B27: 82 | C27: 0 | D27: 6.35 | E27: 0.215 | F27: 0.069 | G27: 725.09 | H27: 6.32 | I27: 8.03 | J27: 0.201
A28: LV Sub Site Specific Band 3 | B28: 83 | C28: 0 | D28: 6.35 | E28: 0.215 | F28: 0.069 | G28: 1173.95 | H28: 6.32 | I28: 8.03 | J28: 0.201
A29: LV Sub Site Specific Band 4 | B29: 84 | C29: 0 | D29: 6.35 | E29: 0.215 | F29: 0.069 | G29: 2593.11 | H29: 6.32 | I29: 8.03 | J29: 0.201
A30: HV Site Specific No Residual | B30: 90 | C30: 0 | D30: 5.569 | E30: 0.181 | F30: 0.054 | G30: 180.95 | H30: 4.86 | I30: 7.2 | J30: 0.174
A31: HV Site Specific Band 1 | B31: 91 | C31: 0 | D31: 5.569 | E31: 0.181 | F31: 0.054 | G31: 1874.44 | H31: 4.86 | I31: 7.2 | J31: 0.174
... A34: HV Site Specific Band 4 | B34: 94 | C34: 0 | D34: 5.569 | E34: 0.181 | F34: 0.054 | G34: 21672.59 | H34: 4.86 | I34: 7.2 | J34: 0.174
A35: Unmetered Supplies | B35: 350, 351, 352, 353, 354 | C35: 0, 1 or 8 | D35: 46.082 | E35: 3.234 | F35: 2.919 | K35: 355, 356, 357, 358, 359, 360, 361, 362, 363, 364, 365, 366
A36: LV Generation Aggregated | B36: 932 | C36: 0 | D36: -10.397 | E36: -0.39 | F36: -0.133 | G36: 0
A37: LV Sub Generation Aggregated | C37: 0 | D37: -8.979 | E37: -0.33 | F37: -0.111 | G37: 0
A38: LV Generation Site Specific | B38: 980 | C38: 0 | D38: -10.397 | E38: -0.39 | F38: -0.133 | G38: 0 | J38: 0.311 | K38: 982
A39: LV Generation Site Specific no RP charge | B39: 981 | C39: 0 | D39: -10.397 | E39: -0.39 | F39: -0.133 | G39: 0 | K39: 983
A40: LV Sub Generation Site Specific | B40: 984 | C40: 0 | D40: -8.979 | E40: -0.33 | F40: -0.111 | G40: 0 | J40: 0.272 | K40: 986
A41: LV Sub Generation Site Specific no RP charge | B41: 985 | C41: 0 | D41: -8.979 | E41: -0.33 | F41: -0.111 | G41: 0 | K41: 987
A42: HV Generation Site Specific | B42: 988 | C42: 0 | D42: -6.173 | E42: -0.207 | F42: -0.065 | G42: 13.66 | J42: 0.22 | K42: 990
A43: HV Generation Site Specific no RP charge | B43: 989 | C43: 0 | D43: -6.173 | E43: -0.207 | F43: -0.065 | G43: 13.66 | K43: 991

Sheet Annex 2 EHV charges
A1: Back to Overview | C1: Copy EDCM table 5001 range starting B101 and paste into G11. Extend or reduce print area as required. | F1: Note: The DNO reserves the right to apply the listed charges to any other MPANs/MSIDs associated with the site. This includes reallocating charges to a traded MPAN at the same site where another MPAN has been disconnected or de-energised.
A2: =Overview!B4& " - Effective from "&Overview!D4&" - "&Overview!E4&" EDCM charges" -> South Eastern Power Networks - Effective from 1 April 2024 - Final EDCM charges
A4: Time Periods for Designated EHV Properties
A5: Time periods | D5: Super Red Time Band
A6: Monday to Friday (Including Bank Holidays) November to February Inclusive | D6: 16:00 - 19:00
A7: Notes | D7: All the above times are in UK Clock time
A9: Import Unique Identifier | B9: LLFC | C9: Import MPANs/MSIDs | D9: Export Unique Identifier | E9: LLFC | F9: Export MPANs/MSIDs | G9: Name | H9: Residual Charging Band | I9: Import Super Red unit charge (p/kWh) | J9: Import fixed charge (p/day) | K9: Import capacity charge (p/kVA/day) | L9: Import exceeded capacity charge (p/kVA/day) | M9: Export Super Red unit charge (p/kWh) | N9: Export fixed charge (p/day) | O9: Export capacity charge (p/kVA/day) | P9: Export exceeded capacity charge (p/kVA/day)
A10: B&RLTD | B10: 834 | C10: 1900035000482;1900035425153 | G10: B&RLTD | H10: 1 | I10: 1.862 | J10: 2865.31 | K10: 2.97 | L10: 2.97 | M10: 0 | N10: 0 | O10: 0 | P10: 0
A11: BEDDIN | B11: 889 | C11: 1900070745640;1900070745650;1900070745669;1900070745678 | G11: BEDDIN | H11: 2 | I11: 0.005 | J11: 16076.25 | K11: 1.45 | L11: 1.45 | M11: 0 | N11: 0 | O11: 0 | P11: 0
A12: BP_OIL | B12: 835 | C12: 1900017426438;1900017426447 | G12: BP_OIL | H12: 1 | I12: 0.312 | J12: 2865.31 | K12: 1.43 | L12: 1.43 | M12: 0 | N12: 0 | O12: 0 | P12: 0
A13: CHESDC | C13: ENET | G13: CHESDC | H13: 3 | I13: 0.004 | J13: 33041.98 | K13: 0.99 | L13: 0.99 | M13: 0 | N13: 0 | O13: 0 | P13: 0
A14: DIGREA | B14: 833 | C14: 1900091200323;1900091200332 | G14: DIGREA | H14: 4 | I14: 0 | J14: 69548.53 | K14: 1.86 | L14: 1.86 | M14: 0 | N14: 0 | O14: 0 | P14: 0
A15: EUROTU | B15: 874 | C15: 1900060219605 | G15: EUROTU | H15: 4 | I15: 0 | J15: 220981.93 | K15: 0.74 | L15: 0.74 | M15: 0 | N15: 0 | O15: 0 | P15: 0
A16: GAT_AF | B16: 869 | C16: 1900017427938;1900017427947;1900060576620 | G16: GAT_AF | H16: 3 | I16: 0.746 | J16: 39690.72 | K16: 1.78 | L16: 1.78 | M16: 0 | N16: 0 | O16: 0 | P16: 0
A17: GAT_BF | B17: 870 | C17: 1900060690231;1900060690240 | G17: GAT_BF | H17: 3 | I17: 0.776 | J17: 36594.39 | K17: 1.91 | L17: 1.91 | M17: 0 | N17: 0 | O17: 0 | P17: 0
A18: KNGSPN | C18: MSID: 1027 | G18: KNGSPN | H18: 4 | I18: 0.13 | J18: 66928.99 | K18: 2.16 | L18: 2.16 | M18: 0 | N18: 0 | O18: 0 | P18: 0
A19: NP_LAB | B19: 837 | C19: 1900047386380 | G19: NP_LAB | H19: 1 | I19: 1.888 | J19: 3238.38 | K19: 3.07 | L19: 3.07 | M19: 0 | N19: 0 | O19: 0 | P19: 0
A20: NR_3BR | B20: 866 | C20: 1900060219145 | G20: NR_3BR | H20: 4 | I20: 0.815 | J20: 68534.37 | K20: 2.73 | L20: 2.73 | M20: 0 | N20: 0 | O20: 0 | P20: 0
A21: NR_AFD | B21: 851 | C21: 1900060219377 | G21: NR_AFD | H21: 3 | I21: 1.802 | J21: 36594.39 | K21: 2.42 | L21: 2.42 | M21: 0 | N21: 0 | O21: 0 | P21: 0
A22: NR_ASH | B22: 879 | C22: 1900070068129 | G22: NR_ASH | H22: 3 | I22: 0.341 | J22: 36594.39 | K22: 2.78 | L22: 2.78 | M22: 0 | N22: 0 | O22: 0 | P22: 0
A23: NR_BRI | B23: 852 | C23: 1900060218675 | G23: NR_BRI | H23: 4 | I23: 0.405 | J23: 68534.37 | K23: 2.22 | L23: 2.22 | M23: 0 | N23: 0 | O23: 0 | P23: 0
A24: NR_BYF | B24: 853 | C24: 1900060218727 | G24: NR_BYF | H24: 4 | I24: 0.364 | J24: 68534.37 | K24: 1.95 | L24: 1.95 | M24: 0 | N24: 0 | O24: 0 | P24: 0
A25: NR_CAN | B25: 854 | C25: 1900060218790 | G25: NR_CAN | H25: 2 | I25: 0.015 | J25: 16959.97 | K25: 2.56 | L25: 2.56 | M25: 0 | N25: 0 | O25: 0 | P25: 0
A26: NR_CRO | B26: 855 | C26: 1900060218815 | G26: NR_CRO | H26: 4 | I26: 0.021 | J26: 67999.24 | K26: 2.11 | L26: 2.11 | M26: 0 | N26: 0 | O26: 0 | P26: 0
A27: NR_DOR | B27: 856 | C27: 1900060219303 | G27: NR_DOR | H27: 2 | I27: 4.623 | J27: 16959.97 | K27: 2.3 | L27: 2.3 | M27: 0 | N27: 0 | O27: 0 | P27: 0
A28: NR_EAS | B28: 857 | C28: 1900060218912 | G28: NR_EAS | H28: 2 | I28: 1.26 | J28: 16959.97 | K28: 3.08 | L28: 3.08 | M28: 0 | N28: 0 | O28: 0 | P28: 0
A29: NR_FOK | B29: 858 | C29: 1900060218959 | G29: NR_FOK | H29: 2 | I29: 1.451 | J29: 16959.97 | K29: 1.97 | L29: 1.97 | M29: 0 | N29: 0 | O29: 0 | P29: 0
A30: NR_HAS | B30: 859 | C30: 1900060218986 | G30: NR_HAS | H30: 2 | I30: 0 | J30: 22539.41 | K30: 2.92 | L30: 2.92 | M30: 0 | N30: 0 | O30: 0 | P30: 0
... A34: NR_QUE | B34: 863 | C34: 1900060219084 | G34: NR_QUE | H34: 1 | I34: 0 | J34: 3054.42 | K34: 1.33 | L34: 1.33 | M34: 0 | N34: 0 | O34: 0 | P34: 0
A35: NR_SIT | B35: 864 | C35: 1900060219819;1900060219855 | G35: NR_SIT | H35: 3 | I35: 0 | J35: 36594.39 | K35: 1.82 | L35: 1.82 | M35: 0 | N35: 0 | O35: 0 | P35: 0
A36: NR_THA | B36: 865 | C36: 1900060219720;1900060219794 | G36: NR_THA | H36: 2 | I36: 1.788 | J36: 16959.97 | K36: 2.43 | L36: 2.43 | M36: 0 | N36: 0 | O36: 0 | P36: 0
A37: NR_TUN | B37: 867 | C37: 1900060219206 | G37: NR_TUN | H37: 3 | I37: 7.341 | J37: 36594.39 | K37: 2.9 | L37: 2.9 | M37: 0 | N37: 0 | O37: 0 | P37: 0
A38: PFIZER | B38: 881 | C38: 1900060219544 | F38: 1900060858356 | G38: PFIZER | H38: 2 | I38: 0 | J38: 19440.83 | K38: 1.14 | L38: 1.14 | M38: 0 | N38: 0 | O38: 0 | P38: 0
A39: SENTIV | B39: 888 | C39: 1900090497281;1900090497290;1900090497306;1900090497315 | G39: SENTIV | H39: 4 | I39: 0.05 | J39: 183985.57 | K39: 1.39 | L39: 1.39 | M39: 0 | N39: 0 | O39: 0 | P39: 0
A40: THAMEM | B40: 838 | C40: 1900090872672;1900090872681 | D40: THAMEM | E40: 691 | F40: 1900090876979;1900090876988 | G40: THAMEM | H40: 4 | I40: 0 | J40: 73474.95 | K40: 1.6 | L40: 1.6 | M40: 0 | N40: 4909.47 | O40: 0.05 | P40: 0.05
A41: THAMES | B41: 884 | C41: 1900016424857 | D41: THAMES | E41: 732 | F41: 1900060576611 | G41: THAMES | H41: 2 | I41: 0.756 | J41: 20906.49 | K41: 3.14 | L41: 3.14 | M41: -0.482 | N41: 2943.17 | O41: 0.05 | P41: 0.05
A42: TWHK66 | B42: 839 | C42: 1900091206176 | D42: TWHK66 | E42: 692 | F42: 1900091206194 | G42: TWHK66 | H42: 2 | I42: 7.429 | J42: 16211.32 | K42: 2.34 | L42: 2.34 | M42: -8.002 | N42: 51.46 | O42: 0.05 | P42: 0.05
A43: ANMSTR | B43: 873 | C43: 1900091919588 | D43: ANMSTR | E43: 780 | F43: 1900091919597 | G43: ANMSTR | H43: 0 | I43: 2.153 | J43: 58.21 | K43: 1.02 | L43: 1.02 | M43: -2.153 | N43: 1633.73 | O43: 0.05 | P43: 0.05
A44: ASHBYS | B44: 809 | C44: 1900091216963 | D44: ASHBYS | E44: 741 | F44: 1900091216972 | G44: ASHBYS | H44: 0 | I44: 5.143 | J44: 16.42 | K44: 1.9 | L44: 1.9 | M44: 0 | N44: 1674.86 | O44: 0.05 | P44: 0.05
A45: AYLESF | B45: 868 | C45: 1900060216613 | D45: AYLESF | E45: 725 | F45: 1900060436880 | G45: AYLESF | H45: 4 | I45: 0.045 | J45: 67518.21 | K45: 0.8 | L45: 0.8 | M45: 0 | N45: 0 | O45: 0 | P45: 0
...

Sheet Annex 2a Import
A1: Note: The list of MPANs / MSIDs provided may be incomplete; the DNO reserves the right to apply the listed charges to any other MPANs / MSIDs associated with the site. Note: This table is automatically populated based on the content of the tab entitled 'Annex 2 EHV Charges'. The timebands are as shown in Annex 2.
A2: =Overview!B4& " - Effective from "&Overview!D4&" - "&Overview!E4&" EDCM import charges" -> South Eastern Power Networks - Effective from 1 April 2024 - Final EDCM import charges
A4: Import Unique Identifier | B4: LLFC | C4: Import MPANs/MSIDs | D4: Name | E4: ='Annex 2 EHV charges'!I9 -> Import Super Red unit charge (p/kWh) | F4: ='Annex 2 EHV charges'!J9 -> Import fixed charge (p/day) | G4: ='Annex 2 EHV charges'!K9 -> Import capacity charge (p/kVA/day) | H4: ='Annex 2 EHV charges'!L9 -> Import exceeded capacity charge (p/kVA/day)
A5: {=IFERROR(INDEX('Annex 2 EHV charges'!$A$10:$A$108, MATCH(0, IF(ISBLANK('Annex 2 EHV charges'!$A$10:$A$108),1, COUNTIF(A$4:$A4, 'Annex 2 EHV charges'!$A$10:$A$108)), 0)),"")} -> B&RLTD | B5: =IF($A5="","",VLOOKUP($A5,'Annex 2 EHV charges'!$A:$O,2,0)) -> 834 | C5: =IF($A5="","",VLOOKUP($A5,'Annex 2 EHV charges'!$A:$O,3,0)) -> 1900035000482;1900035425153 | D5: =IF($A5="","",VLOOKUP($A5,'Annex 2 EHV charges'!$A:$O,7,0)) -> B&RLTD | E5: =IFERROR(IF(VLOOKUP($A5,'Annex 2 EHV charges'!$A:$O,9,FALSE)=0,"",VLOOKUP($A5,'Annex 2 EHV charges'!$A:$O,9,FALSE)),"") -> 1.862 | F5: =IFERROR(IF(VLOOKUP($A5,'Annex 2 EHV charges'!$A:$O,10,FALSE)=0,"",VLOOKUP($A5,'Annex 2 EHV charges'!$A:$O,10,FALSE)),"") -> 2865.31 | G5: =IFERROR(IF(VLOOKUP($A5,'Annex 2 EHV charges'!$A:$O,11,FALSE)=0,"",VLOOKUP($A5,'Annex 2 EHV charges'!$A:$O,11,FALSE)),"") -> 2.97 | H5: =IFERROR(IF(VLOOKUP($A5,'Annex 2 EHV charges'!$A:$O,12,FALSE)=0,"",VLOOKUP($A5,'Annex 2 EHV charges'!$A:$O,12,FALSE)),"") -> 2.97
A6: {=IFERROR(INDEX('Annex 2 EHV charges'!$A$10:$A$108, MATCH(0, IF(ISBLANK('Annex 2 EHV charges'!$A$10:$A$108),1, COUNTIF(A$4:$A5, 'Annex 2 EHV charges'!$A$10:$A$108)), 0)),"")} -> BEDDIN | B6: =IF($A6="","",VLOOKUP($A6,'Annex 2 EHV charges'!$A:$O,2,0)) -> 889 | C6: =IF($A6="","",VLOOKUP($A6,'Annex 2 EHV charges'!$A:$O,3,0)) -> 1900070745640;1900070745650;1900070745669;1900070745678 | D6: =IF($A6="","",VLOOKUP($A6,'Annex 2 EHV charges'!$A:$O,7,0)) -> BEDDIN | E6: =IFERROR(IF(VLOOKUP($A6,'Annex 2 EHV charges'!$A:$O,9,FALSE)=0,"",VLOOKUP($A6,'Annex 2 EHV charges'!$A:$O,9,FALSE)),"") -> 0.005 | F6: =IFERROR(IF(VLOOKUP($A6,'Annex 2 EHV charges'!$A:$O,10,FALSE)=0,"",VLOOKUP($A6,'Annex 2 EHV charges'!$A:$O,10,FALSE)),"") -> 16076.25 | G6: =IFERROR(IF(VLOOKUP($A6,'Annex 2 EHV charges'!$A:$O,11,FALSE)=0,"",VLOOKUP($A6,'Annex 2 EHV charges'!$A:$O,11,FALSE)),"") -> 1.45 | H6: =IFERROR(IF(VLOOKUP($A6,'Annex 2 EHV charges'!$A:$O,12,FALSE)=0,"",VLOOKUP($A6,'Annex 2 EHV charges'!$A:$O,12,FALSE)),"") -> 1.45
A7: {=IFERROR(INDEX('Annex 2 EHV charges'!$A$10:$A$108, MATCH(0, IF(ISBLANK('Annex 2 EHV charges'!$A$10:$A$108),1, COUNTIF(A$4:$A6, 'Annex 2 EHV charges'!$A$10:$A$108)), 0)),"")} -> BP_OIL | B7: =IF($A7="","",VLOOKUP($A7,'Annex 2 EHV charges'!$A:$O,2,0)) -> 835 | C7: =IF($A7="","",VLOOKUP($A7,'Annex 2 EHV charges'!$A:$O,3,0)) -> 1900017426438;1900017426447 | D7: =IF($A7="","",VLOOKUP($A7,'Annex 2 EHV charges'!$A:$O,7,0)) -> BP_OIL | E7: =IFERROR(IF(VLOOKUP($A7,'Annex 2 EHV charges'!$A:$O,9,FALSE)=0,"",VLOOKUP($A7,'Annex 2 EHV charges'!$A:$O,9,FALSE)),"") -> 0.312 | F7: =IFERROR(IF(VLOOKUP($A7,'Annex 2 EHV charges'!$A:$O,10,FALSE)=0,"",VLOOKUP($A7,'Annex 2 EHV charges'!$A:$O,10,FALSE)),"") -> 2865.31 | G7: =IFERROR(IF(VLOOKUP($A7,'Annex 2 EHV charges'!$A:$O,11,FALSE)=0,"",VLOOKUP($A7,'Annex 2 EHV charges'!$A:$O,11,FALSE)),"") -> 1.43 | H7: =IFERROR(IF(VLOOKUP($A7,'Annex 2 EHV charges'!$A:$O,12,FALSE)=0,"",VLOOKUP($A7,'Annex 2 EHV charges'!$A:$O,12,FALSE)),"") -> 1.43
A8: {=IFERROR(INDEX('Annex 2 EHV charges'!$A$10:$A$108, MATCH(0, IF(ISBLANK('Annex 2 EHV charges'!$A$10:$A$108),1, COUNTIF(A$4:$A7, 'Annex 2 EHV charges'!$A$10:$A$108)), 0)),"")} -> CHESDC | B8: =IF($A8="","",VLOOKUP($A8,'Annex 2 EHV charges'!$A:$O,2,0)) -> 0 | C8: =IF($A8="","",VLOOKUP($A8,'Annex 2 EHV charges'!$A:$O,3,0)) -> ENET | D8: =IF($A8="","",VLOOKUP($A8,'Annex 2 EHV charges'!$A:$O,7,0)) -> CHESDC | E8: =IFERROR(IF(VLOOKUP($A8,'Annex 2 EHV charges'!$A:$O,9,FALSE)=0,"",VLOOKUP($A8,'Annex 2 EHV charges'!$A:$O,9,FALSE)),"") -> 0.004 | F8: =IFERROR(IF(VLOOKUP($A8,'Annex 2 EHV charges'!$A:$O,10,FALSE)=0,"",VLOOKUP($A8,'Annex 2 EHV charges'!$A:$O,10,FALSE)),"") -> 33041.98 | G8: =IFERROR(IF(VLOOKUP($A8,'Annex 2 EHV charges'!$A:$O,11,FALSE)=0,"",VLOOKUP($A8,'Annex 2 EHV charges'!$A:$O,11,FALSE)),"") -> 0.99 | H8: =IFERROR(IF(VLOOKUP($A8,'Annex 2 EHV charges'!$A:$O,12,FALSE)=0,"",VLOOKUP($A8,'Annex 2 EHV charges'!$A:$O,12,FALSE)),"") -> 0.99
A9: {=IFERROR(INDEX('Annex 2 EHV charges'!$A$10:$A$108, MATCH(0, IF(ISBLANK('Annex 2 EHV charges'!$A$10:$A$108),1, COUNTIF(A$4:$A8, 'Annex 2 EHV charges'!$A$10:$A$108)), 0)),"")} -> DIGREA | B9: =IF($A9="","",VLOOKUP($A9,'Annex 2 EHV charges'!$A:$O,2,0)) -> 833 | C9: =IF($A9="","",VLOOKUP($A9,'Annex 2 EHV charges'!$A:$O,3,0)) -> 1900091200323;1900091200332 | D9: =IF($A9="","",VLOOKUP($A9,'Annex 2 EHV charges'!$A:$O,7,0)) -> DIGREA | E9: =IFERROR(IF(VLOOKUP($A9,'Annex 2 EHV charges'!$A:$O,9,FALSE)=0,"",VLOOKUP($A9,'Annex 2 EHV charges'!$A:$O,9,FALSE)),"") | F9: =IFERROR(IF(VLOOKUP($A9,'Annex 2 EHV charges'!$A:$O,10,FALSE)=0,"",VLOOKUP($A9,'Annex 2 EHV charges'!$A:$O,10,FALSE)),"") -> 69548.53 | G9: =IFERROR(IF(VLOOKUP($A9,'Annex 2 EHV charges'!$A:$O,11,FALSE)=0,"",VLOOKUP($A9,'Annex 2 EHV charges'!$A:$O,11,FALSE)),"") -> 1.86 | H9: =IFERROR(IF(VLOOKUP($A9,'Annex 2 EHV charges'!$A:$O,12,FALSE)=0,"",VLOOKUP($A9,'Annex 2 EHV charges'!$A:$O,12,FALSE)),"") -> 1.86
A10: {=IFERROR(INDEX('Annex 2 EHV charges'!$A$10:$A$108, MATCH(0, IF(ISBLANK('Annex 2 EHV charges'!$A$10:$A$108),1, COUNTIF(A$4:$A9, 'Annex 2 EHV charges'!$A$10:$A$108)), 0)),"")} -> EUROTU | B10: =IF($A10="","",VLOOKUP($A10,'Annex 2 EHV charges'!$A:$O,2,0)) -> 874 | C10: =IF($A10="","",VLOOKUP($A10,'Annex 2 EHV charges'!$A:$O,3,0)) -> 1900060219605 | D10: =IF($A10="","",VLOOKUP($A10,'Annex 2 EHV charges'!$A:$O,7,0)) -> EUROTU | E10: =IFERROR(IF(VLOOKUP($A10,'Annex 2 EHV charges'!$A:$O,9,FALSE)=0,"",VLOOKUP($A10,'Annex 2 EHV charges'!$A:$O,9,FALSE)),"") | F10: =IFERROR(IF(VLOOKUP($A10,'Annex 2 EHV charges'!$A:$O,10,FALSE)=0,"",VLOOKUP($A10,'Annex 2 EHV charges'!$A:$O,10,FALSE)),"") -> 220981.93 | G10: =IFERROR(IF(VLOOKUP($A10,'Annex 2 EHV charges'!$A:$O,11,FALSE)=0,"",VLOOKUP($A10,'Annex 2 EHV charges'!$A:$O,11,FALSE)),"") -> 0.74 | H10: =IFERROR(IF(VLOOKUP($A10,'Annex 2 EHV charges'!$A:$O,12,FALSE)=0,"",VLOOKUP($A10,'Annex 2 EHV charges'!$A:$O,12,FALSE)),"") -> 0.74
A11: {=IFERROR(INDEX('Annex 2 EHV charges'!$A$10:$A$108, MATCH(0, IF(ISBLANK('Annex 2 EHV charges'!$A$10:$A$108),1, COUNTIF(A$4:$A10, 'Annex 2 EHV charges'!$A$10:$A$108)), 0)),"")} -> GAT_AF | B11: =IF($A11="","",VLOOKUP($A11,'Annex 2 EHV charges'!$A:$O,2,0)) -> 869 | C11: =IF($A11="","",VLOOKUP($A11,'Annex 2 EHV charges'!$A:$O,3,0)) -> 1900017427938;1900017427947;1900060576620 | D11: =IF($A11="","",VLOOKUP($A11,'Annex 2 EHV charges'!$A:$O,7,0)) -> GAT_AF | E11: =IFERROR(IF(VLOOKUP($A11,'Annex 2 EHV charges'!$A:$O,9,FALSE)=0,"",VLOOKUP($A11,'Annex 2 EHV charges'!$A:$O,9,FALSE)),"") -> 0.746 | F11: =IFERROR(IF(VLOOKUP($A11,'Annex 2 EHV charges'!$A:$O,10,FALSE)=0,"",VLOOKUP($A11,'Annex 2 EHV charges'!$A:$O,10,FALSE)),"") -> 39690.72 | G11: =IFERROR(IF(VLOOKUP($A11,'Annex 2 EHV charges'!$A:$O,11,FALSE)=0,"",VLOOKUP($A11,'Annex 2 EHV charges'!$A:$O,11,FALSE)),"") -> 1.78 | H11: =IFERROR(IF(VLOOKUP($A11,'Annex 2 EHV charges'!$A:$O,12,FALSE)=0,"",VLOOKUP($A11,'Annex 2 EHV charges'!$A:$O,12,FALSE)),"") -> 1.78
A12: {=IFERROR(INDEX('Annex 2 EHV charges'!$A$10:$A$108, MATCH(0, IF(ISBLANK('Annex 2 EHV charges'!$A$10:$A$108),1, COUNTIF(A$4:$A11, 'Annex 2 EHV charges'!$A$10:$A$108)), 0)),"")} -> GAT_BF | B12: =IF($A12="","",VLOOKUP($A12,'Annex 2 EHV charges'!$A:$O,2,0)) -> 870 | C12: =IF($A12="","",VLOOKUP($A12,'Annex 2 EHV charges'!$A:$O,3,0)) -> 1900060690231;1900060690240 | D12: =IF($A12="","",VLOOKUP($A12,'Annex 2 EHV charges'!$A:$O,7,0)) -> GAT_BF | E12: =IFERROR(IF(VLOOKUP($A12,'Annex 2 EHV charges'!$A:$O,9,FALSE)=0,"",VLOOKUP($A12,'Annex 2 EHV charges'!$A:$O,9,FALSE)),"") -> 0.776 | F12: =IFERROR(IF(VLOOKUP($A12,'Annex 2 EHV charges'!$A:$O,10,FALSE)=0,"",VLOOKUP($A12,'Annex 2 EHV charges'!$A:$O,10,FALSE)),"") -> 36594.39 | G12: =IFERROR(IF(VLOOKUP($A12,'Annex 2 EHV charges'!$A:$O,11,FALSE)=0,"",VLOOKUP($A12,'Annex 2 EHV charges'!$A:$O,11,FALSE)),"") -> 1.91 | H12: =IFERROR(IF(VLOOKUP($A12,'Annex 2 EHV charges'!$A:$O,12,FALSE)=0,"",VLOOKUP($A12,'Annex 2 EHV charges'!$A:$O,12,FALSE)),"") -> 1.91
A13: {=IFERROR(INDEX('Annex 2 EHV charges'!$A$10:$A$108, MATCH(0, IF(ISBLANK('Annex 2 EHV charges'!$A$10:$A$108),1, COUNTIF(A$4:$A12, 'Annex 2 EHV charges'!$A$10:$A$108)), 0)),"")} -> KNGSPN | B13: =IF($A13="","",VLOOKUP($A13,'Annex 2 EHV charges'!$A:$O,2,0)) -> 0 | C13: =IF($A13="","",VLOOKUP($A13,'Annex 2 EHV charges'!$A:$O,3,0)) -> MSID: 1027 | D13: =IF($A13="","",VLOOKUP($A13,'Annex 2 EHV charges'!$A:$O,7,0)) -> KNGSPN | E13: =IFERROR(IF(VLOOKUP($A13,'Annex 2 EHV charges'!$A:$O,9,FALSE)=0,"",VLOOKUP($A13,'Annex 2 EHV charges'!$A:$O,9,FALSE)),"") -> 0.13 | F13: =IFERROR(IF(VLOOKUP($A13,'Annex 2 EHV charges'!$A:$O,10,FALSE)=0,"",VLOOKUP($A13,'Annex 2 EHV charges'!$A:$O,10,FALSE)),"") -> 66928.99 | G13: =IFERROR(IF(VLOOKUP($A13,'Annex 2 EHV charges'!$A:$O,11,FALSE)=0,"",VLOOKUP($A13,'Annex 2 EHV charges'!$A:$O,11,FALSE)),"") -> 2.16 | H13: =IFERROR(IF(VLOOKUP($A13,'Annex 2 EHV charges'!$A:$O,12,FALSE)=0,"",VLOOKUP($A13,'Annex 2 EHV charges'!$A:$O,12,FALSE)),"") -> 2.16
A14: {=IFERROR(INDEX('Annex 2 EHV charges'!$A$10:$A$108, MATCH(0, IF(ISBLANK('Annex 2 EHV charges'!$A$10:$A$108),1, COUNTIF(A$4:$A13, 'Annex 2 EHV charges'!$A$10:$A$108)), 0)),"")} -> NP_LAB | B14: =IF($A14="","",VLOOKUP($A14,'Annex 2 EHV charges'!$A:$O,2,0)) -> 837 | C14: =IF($A14="","",VLOOKUP($A14,'Annex 2 EHV charges'!$A:$O,3,0)) -> 1900047386380 | D14: =IF($A14="","",VLOOKUP($A14,'Annex 2 EHV charges'!$A:$O,7,0)) -> NP_LAB | E14: =IFERROR(IF(VLOOKUP($A14,'Annex 2 EHV charges'!$A:$O,9,FALSE)=0,"",VLOOKUP($A14,'Annex 2 EHV charges'!$A:$O,9,FALSE)),"") -> 1.888 | F14: =IFERROR(IF(VLOOKUP($A14,'Annex 2 EHV charges'!$A:$O,10,FALSE)=0,"",VLOOKUP($A14,'Annex 2 EHV charges'!$A:$O,10,FALSE)),"") -> 3238.38 | G14: =IFERROR(IF(VLOOKUP($A14,'Annex 2 EHV charges'!$A:$O,11,FALSE)=0,"",VLOOKUP($A14,'Annex 2 EHV charges'!$A:$O,11,FALSE)),"") -> 3.07 | H14: =IFERROR(IF(VLOOKUP($A14,'Annex 2 EHV charges'!$A:$O,12,FALSE)=0,"",VLOOKUP($A14,'Annex 2 EHV charges'!$A:$O,12,FALSE)),"") -> 3.07
A15: {=IFERROR(INDEX('Annex 2 EHV charges'!$A$10:$A$108, MATCH(0, IF(ISBLANK('Annex 2 EHV charges'!$A$10:$A$108),1, COUNTIF(A$4:$A14, 'Annex 2 EHV charges'!$A$10:$A$108)), 0)),"")} -> NR_3BR | B15: =IF($A15="","",VLOOKUP($A15,'Annex 2 EHV charges'!$A:$O,2,0)) -> 866 | C15: =IF($A15="","",VLOOKUP($A15,'Annex 2 EHV charges'!$A:$O,3,0)) -> 1900060219145 | D15: =IF($A15="","",VLOOKUP($A15,'Annex 2 EHV charges'!$A:$O,7,0)) -> NR_3BR | E15: =IFERROR(IF(VLOOKUP($A15,'Annex 2 EHV charges'!$A:$O,9,FALSE)=0,"",VLOOKUP($A15,'Annex 2 EHV charges'!$A:$O,9,FALSE)),"") -> 0.815 | F15: =IFERROR(IF(VLOOKUP($A15,'Annex 2 EHV charges'!$A:$O,10,FALSE)=0,"",VLOOKUP($A15,'Annex 2 EHV charges'!$A:$O,10,FALSE)),"") -> 68534.37 | G15: =IFERROR(IF(VLOOKUP($A15,'Annex 2 EHV charges'!$A:$O,11,FALSE)=0,"",VLOOKUP($A15,'Annex 2 EHV charges'!$A:$O,11,FALSE)),"") -> 2.73 | H15: =IFERROR(IF(VLOOKUP($A15,'Annex 2 EHV charges'!$A:$O,12,FALSE)=0,"",VLOOKUP($A15,'Annex 2 EHV charges'!$A:$O,12,FALSE)),"") -> 2.73
A16: {=IFERROR(INDEX('Annex 2 EHV charges'!$A$10:$A$108, MATCH(0, IF(ISBLANK('Annex 2 EHV charges'!$A$10:$A$108),1, COUNTIF(A$4:$A15, 'Annex 2 EHV charges'!$A$10:$A$108)), 0)),"")} -> NR_AFD | B16: =IF($A16="","",VLOOKUP($A16,'Annex 2 EHV charges'!$A:$O,2,0)) -> 851 | C16: =IF($A16="","",VLOOKUP($A16,'Annex 2 EHV charges'!$A:$O,3,0)) -> 1900060219377 | D16: =IF($A16="","",VLOOKUP($A16,'Annex 2 EHV charges'!$A:$O,7,0)) -> NR_AFD | E16: =IFERROR(IF(VLOOKUP($A16,'Annex 2 EHV charges'!$A:$O,9,FALSE)=0,"",VLOOKUP($A16,'Annex 2 EHV charges'!$A:$O,9,FALSE)),"") -> 1.802 | F16: =IFERROR(IF(VLOOKUP($A16,'Annex 2 EHV charges'!$A:$O,10,FALSE)=0,"",VLOOKUP($A16,'Annex 2 EHV charges'!$A:$O,10,FALSE)),"") -> 36594.39 | G16: =IFERROR(IF(VLOOKUP($A16,'Annex 2 EHV charges'!$A:$O,11,FALSE)=0,"",VLOOKUP($A16,'Annex 2 EHV charges'!$A:$O,11,FALSE)),"") -> 2.42 | H16: =IFERROR(IF(VLOOKUP($A16,'Annex 2 EHV charges'!$A:$O,12,FALSE)=0,"",VLOOKUP($A16,'Annex 2 EHV charges'!$A:$O,12,FALSE)),"") -> 2.42
... A254: {=IFERROR(INDEX('Annex 2 EHV charges'!$A$10:$A$108, MATCH(0, IF(ISBLANK('Annex 2 EHV charges'!$A$10:$A$108),1, COUNTIF(A$4:$A253, 'Annex 2 EHV charges'!$A$10:$A$108)), 0)),"")} | B254: =IF($A254="","",VLOOKUP($A254,'Annex 2 EHV charges'!$A:$O,2,0)) | C254: =IF($A254="","",VLOOKUP($A254,'Annex 2 EHV charges'!$A:$O,3,0)) | D254: =IF($A254="","",VLOOKUP($A254,'Annex 2 EHV charges'!$A:$O,7,0)) | E254: =IFERROR(IF(VLOOKUP($A254,'Annex 2 EHV charges'!$A:$O,9,FALSE)=0,"",VLOOKUP($A254,'Annex 2 EHV charges'!$A:$O,9,FALSE)),"") | F254: =IFERROR(IF(VLOOKUP($A254,'Annex 2 EHV charges'!$A:$O,10,FALSE)=0,"",VLOOKUP($A254,'Annex 2 EHV charges'!$A:$O,10,FALSE)),"") | G254: =IFERROR(IF(VLOOKUP($A254,'Annex 2 EHV charges'!$A:$O,11,FALSE)=0,"",VLOOKUP($A254,'Annex 2 EHV charges'!$A:$O,11,FALSE)),"") | H254: =IFERROR(IF(VLOOKUP($A254,'Annex 2 EHV charges'!$A:$O,12,FALSE)=0,"",VLOOKUP($A254,'Annex 2 EHV charges'!$A:$O,12,FALSE)),"")

Sheet Annex 2b Export
A1: Note: The list of MPANs / MSIDs provided may be incomplete; the DNO reserves the right to apply the listed charges to any other MPANs / MSIDs associated with the site. Note: This table is automatically populated based on the content of the tab entitled 'Annex 2 EHV Charges'. The timebands are as shown in Annex 2.
A2: =Overview!B4& " - Effective from "&Overview!D4&" - "&Overview!E4&" EDCM export charges" -> South Eastern Power Networks - Effective from 1 April 2024 - Final EDCM export charges
A4: Export Unique Identifier | B4: LLFC | C4: Export MPANs/MSIDs | D4: Name | E4: ='Annex 2 EHV charges'!M9 -> Export Super Red unit charge (p/kWh) | F4: ='Annex 2 EHV charges'!N9 -> Export fixed charge (p/day) | G4: ='Annex 2 EHV charges'!O9 -> Export capacity charge (p/kVA/day) | H4: ='Annex 2 EHV charges'!P9 -> Export exceeded capacity charge (p/kVA/day)
A5: {=IFERROR(INDEX('Annex 2 EHV charges'!$D$10:$D$108, MATCH(0, IF(ISBLANK('Annex 2 EHV charges'!$D$10:$D$108),1, COUNTIF(A$4:$A4, 'Annex 2 EHV charges'!$D$10:$D$108)), 0)),"")} -> THAMEM | B5: =IF($A5="","",VLOOKUP($A5,'Annex 2 EHV charges'!$D:$O,2,0)) -> 691 | C5: =IF($A5="","",VLOOKUP($A5,'Annex 2 EHV charges'!$D:$O,3,0)) -> 1900090876979;1900090876988 | D5: =IF($A5="","",VLOOKUP($A5,'Annex 2 EHV charges'!$D:$O,4,0)) -> THAMEM | E5: =IFERROR(IF(VLOOKUP($A5,'Annex 2 EHV charges'!$D:$O,10,FALSE)=0,"",VLOOKUP($A5,'Annex 2 EHV charges'!$D:$O,10,FALSE)),"") | F5: =IFERROR(IF(VLOOKUP($A5,'Annex 2 EHV charges'!$D:$O,11,FALSE)=0,"",VLOOKUP($A5,'Annex 2 EHV charges'!$D:$O,11,FALSE)),"") -> 4909.47 | G5: =IFERROR(IF(VLOOKUP($A5,'Annex 2 EHV charges'!$D:$O,12,FALSE)=0,"",VLOOKUP($A5,'Annex 2 EHV charges'!$D:$O,12,FALSE)),"") -> 0.05 | H5: =IFERROR(IF(VLOOKUP($A5,'Annex 2 EHV charges'!$D:$P,13,FALSE)=0,"",VLOOKUP($A5,'Annex 2 EHV charges'!$D:$P,13,FALSE)),"") -> 0.05
A6: {=IFERROR(INDEX('Annex 2 EHV charges'!$D$10:$D$108, MATCH(0, IF(ISBLANK('Annex 2 EHV charges'!$D$10:$D$108),1, COUNTIF(A$4:$A5, 'Annex 2 EHV charges'!$D$10:$D$108)), 0)),"")} -> THAMES | B6: =IF($A6="","",VLOOKUP($A6,'Annex 2 EHV charges'!$D:$O,2,0)) -> 732 | C6: =IF($A6="","",VLOOKUP($A6,'Annex 2 EHV charges'!$D:$O,3,0)) -> 1900060576611 | D6: =IF($A6="","",VLOOKUP($A6,'Annex 2 EHV charges'!$D:$O,4,0)) -> THAMES | E6: =IFERROR(IF(VLOOKUP($A6,'Annex 2 EHV charges'!$D:$O,10,FALSE)=0,"",VLOOKUP($A6,'Annex 2 EHV charges'!$D:$O,10,FALSE)),"") -> -0.482 | F6: =IFERROR(IF(VLOOKUP($A6,'Annex 2 EHV charges'!$D:$O,11,FALSE)=0,"",VLOOKUP($A6,'Annex 2 EHV charges'!$D:$O,11,FALSE)),"") -> 2943.17 | G6: =IFERROR(IF(VLOOKUP($A6,'Annex 2 EHV charges'!$D:$O,12,FALSE)=0,"",VLOOKUP($A6,'Annex 2 EHV charges'!$D:$O,12,FALSE)),"") -> 0.05 | H6: =IFERROR(IF(VLOOKUP($A6,'Annex 2 EHV charges'!$D:$P,13,FALSE)=0,"",VLOOKUP($A6,'Annex 2 EHV charges'!$D:$P,13,FALSE)),"") -> 0.05
A7: {=IFERROR(INDEX('Annex 2 EHV charges'!$D$10:$D$108, MATCH(0, IF(ISBLANK('Annex 2 EHV charges'!$D$10:$D$108),1, COUNTIF(A$4:$A6, 'Annex 2 EHV charges'!$D$10:$D$108)), 0)),"")} -> TWHK66 | B7: =IF($A7="","",VLOOKUP($A7,'Annex 2 EHV charges'!$D:$O,2,0)) -> 692 | C7: =IF($A7="","",VLOOKUP($A7,'Annex 2 EHV charges'!$D:$O,3,0)) -> 1900091206194 | D7: =IF($A7="","",VLOOKUP($A7,'Annex 2 EHV charges'!$D:$O,4,0)) -> TWHK66 | E7: =IFERROR(IF(VLOOKUP($A7,'Annex 2 EHV charges'!$D:$O,10,FALSE)=0,"",VLOOKUP($A7,'Annex 2 EHV charges'!$D:$O,10,FALSE)),"") -> -8.002 | F7: =IFERROR(IF(VLOOKUP($A7,'Annex 2 EHV charges'!$D:$O,11,FALSE)=0,"",VLOOKUP($A7,'Annex 2 EHV charges'!$D:$O,11,FALSE)),"") -> 51.46 | G7: =IFERROR(IF(VLOOKUP($A7,'Annex 2 EHV charges'!$D:$O,12,FALSE)=0,"",VLOOKUP($A7,'Annex 2 EHV charges'!$D:$O,12,FALSE)),"") -> 0.05 | H7: =IFERROR(IF(VLOOKUP($A7,'Annex 2 EHV charges'!$D:$P,13,FALSE)=0,"",VLOOKUP($A7,'Annex 2 EHV charges'!$D:$P,13,FALSE)),"") -> 0.05
A8: {=IFERROR(INDEX('Annex 2 EHV charges'!$D$10:$D$108, MATCH(0, IF(ISBLANK('Annex 2 EHV charges'!$D$10:$D$108),1, COUNTIF(A$4:$A7, 'Annex 2 EHV charges'!$D$10:$D$108)), 0)),"")} -> ANMSTR | B8: =IF($A8="","",VLOOKUP($A8,'Annex 2 EHV charges'!$D:$O,2,0)) -> 780 | C8: =IF($A8="","",VLOOKUP($A8,'Annex 2 EHV charges'!$D:$O,3,0)) -> 1900091919597 | D8: =IF($A8="","",VLOOKUP($A8,'Annex 2 EHV charges'!$D:$O,4,0)) -> ANMSTR | E8: =IFERROR(IF(VLOOKUP($A8,'Annex 2 EHV charges'!$D:$O,10,FALSE)=0,"",VLOOKUP($A8,'Annex 2 EHV charges'!$D:$O,10,FALSE)),"") -> -2.153 | F8: =IFERROR(IF(VLOOKUP($A8,'Annex 2 EHV charges'!$D:$O,11,FALSE)=0,"",VLOOKUP($A8,'Annex 2 EHV charges'!$D:$O,11,FALSE)),"") -> 1633.73 | G8: =IFERROR(IF(VLOOKUP($A8,'Annex 2 EHV charges'!$D:$O,12,FALSE)=0,"",VLOOKUP($A8,'Annex 2 EHV charges'!$D:$O,12,FALSE)),"") -> 0.05 | H8: =IFERROR(IF(VLOOKUP($A8,'Annex 2 EHV charges'!$D:$P,13,FALSE)=0,"",VLOOKUP($A8,'Annex 2 EHV charges'!$D:$P,13,FALSE)),"") -> 0.05
A9: {=IFERROR(INDEX('Annex 2 EHV charges'!$D$10:$D$108, MATCH(0, IF(ISBLANK('Annex 2 EHV charges'!$D$10:$D$108),1, COUNTIF(A$4:$A8, 'Annex 2 EHV charges'!$D$10:$D$108)), 0)),"")} -> ASHBYS | B9: =IF($A9="","",VLOOKUP($A9,'Annex 2 EHV charges'!$D:$O,2,0)) -> 741 | C9: =IF($A9="","",VLOOKUP($A9,'Annex 2 EHV charges'!$D:$O,3,0)) -> 1900091216972 | D9: =IF($A9="","",VLOOKUP($A9,'Annex 2 EHV charges'!$D:$O,4,0)) -> ASHBYS | E9: =IFERROR(IF(VLOOKUP($A9,'Annex 2 EHV charges'!$D:$O,10,FALSE)=0,"",VLOOKUP($A9,'Annex 2 EHV charges'!$D:$O,10,FALSE)),"") | F9: =IFERROR(IF(VLOOKUP($A9,'Annex 2 EHV charges'!$D:$O,11,FALSE)=0,"",VLOOKUP($A9,'Annex 2 EHV charges'!$D:$O,11,FALSE)),"") -> 1674.86 | G9: =IFERROR(IF(VLOOKUP($A9,'Annex 2 EHV charges'!$D:$O,12,FALSE)=0,"",VLOOKUP($A9,'Annex 2 EHV charges'!$D:$O,12,FALSE)),"") -> 0.05 | H9: =IFERROR(IF(VLOOKUP($A9,'Annex 2 EHV charges'!$D:$P,13,FALSE)=0,"",VLOOKUP($A9,'Annex 2 EHV charges'!$D:$P,13,FALSE)),"") -> 0.05
A10: {=IFERROR(INDEX('Annex 2 EHV charges'!$D$10:$D$108, MATCH(0, IF(ISBLANK('Annex 2 EHV charges'!$D$10:$D$108),1, COUNTIF(A$4:$A9, 'Annex 2 EHV charges'!$D$10:$D$108)), 0)),"")} -> AYLESF | B10: =IF($A10="","",VLOOKUP($A10,'Annex 2 EHV charges'!$D:$O,2,0)) -> 725 | C10: =IF($A10="","",VLOOKUP($A10,'Annex 2 EHV charges'!$D:$O,3,0)) -> 1900060436880 | D10: =IF($A10="","",VLOOKUP($A10,'Annex 2 EHV charges'!$D:$O,4,0)) -> AYLESF | E10: =IFERROR(IF(VLOOKUP($A10,'Annex 2 EHV charges'!$D:$O,10,FALSE)=0,"",VLOOKUP($A10,'Annex 2 EHV charges'!$D:$O,10,FALSE)),"") | F10: =IFERROR(IF(VLOOKUP($A10,'Annex 2 EHV charges'!$D:$O,11,FALSE)=0,"",VLOOKUP($A10,'Annex 2 EHV charges'!$D:$O,11,FALSE)),"") | G10: =IFERROR(IF(VLOOKUP($A10,'Annex 2 EHV charges'!$D:$O,12,FALSE)=0,"",VLOOKUP($A10,'Annex 2 EHV charges'!$D:$O,12,FALSE)),"") | H10: =IFERROR(IF(VLOOKUP($A10,'Annex 2 EHV charges'!$D:$P,13,FALSE)=0,"",VLOOKUP($A10,'Annex 2 EHV charges'!$D:$P,13,FALSE)),"")
A11: {=IFERROR(INDEX('Annex 2 EHV charges'!$D$10:$D$108, MATCH(0, IF(ISBLANK('Annex 2 EHV charges'!$D$10:$D$108),1, COUNTIF(A$4:$A10, 'Annex 2 EHV charges'!$D$10:$D$108)), 0)),"")} -> BEDERF | B11: =IF($A11="","",VLOOKUP($A11,'Annex 2 EHV charges'!$D:$O,2,0)) -> 693 | C11: =IF($A11="","",VLOOKUP($A11,'Annex 2 EHV charges'!$D:$O,3,0)) -> 1900091482597 | D11: =IF($A11="","",VLOOKUP($A11,'Annex 2 EHV charges'!$D:$O,4,0)) -> BEDERF | E11: =IFERROR(IF(VLOOKUP($A11,'Annex 2 EHV charges'!$D:$O,10,FALSE)=0,"",VLOOKUP($A11,'Annex 2 EHV charges'!$D:$O,10,FALSE)),"") -> -0.317 | F11: =IFERROR(IF(VLOOKUP($A11,'Annex 2 EHV charges'!$D:$O,11,FALSE)=0,"",VLOOKUP($A11,'Annex 2 EHV charges'!$D:$O,11,FALSE)),"") -> 4105.64 | G11: =IFERROR(IF(VLOOKUP($A11,'Annex 2 EHV charges'!$D:$O,12,FALSE)=0,"",VLOOKUP($A11,'Annex 2 EHV charges'!$D:$O,12,FALSE)),"") -> 0.05 | H11: =IFERROR(IF(VLOOKUP($A11,'Annex 2 EHV charges'!$D:$P,13,FALSE)=0,"",VLOOKUP($A11,'Annex 2 EHV charges'!$D:$P,13,FALSE)),"") -> 0.05
A12: {=IFERROR(INDEX('Annex 2 EHV charges'!$D$10:$D$108, MATCH(0, IF(ISBLANK('Annex 2 EHV charges'!$D$10:$D$108),1, COUNTIF(A$4:$A11, 'Annex 2 EHV charges'!$D$10:$D$108)), 0)),"")} -> BESAYL | B12: =IF($A12="","",VLOOKUP($A12,'Annex 2 EHV charges'!$D:$O,2,0)) -> 694 | C12: =IF($A12="","",VLOOKUP($A12,'Annex 2 EHV charges'!$D:$O,3,0)) -> 1900091632784 | D12: =IF($A12="","",VLOOKUP($A12,'Annex 2 EHV charges'!$D:$O,4,0)) -> BESAYL | E12: =IFERROR(IF(VLOOKUP($A12,'Annex 2 EHV charges'!$D:$O,10,FALSE)=0,"",VLOOKUP($A12,'Annex 2 EHV charges'!$D:$O,10,FALSE)),"") -> -0.087 | F12: =IFERROR(IF(VLOOKUP($A12,'Annex 2 EHV charges'!$D:$O,11,FALSE)=0,"",VLOOKUP($A12,'Annex 2 EHV charges'!$D:$O,11,FALSE)),"") -> 589.22 | G12: =IFERROR(IF(VLOOKUP($A12,'Annex 2 EHV charges'!$D:$O,12,FALSE)=0,"",VLOOKUP($A12,'Annex 2 EHV charges'!$D:$O,12,FALSE)),"") -> 0.05 | H12: =IFERROR(IF(VLOOKUP($A12,'Annex 2 EHV charges'!$D:$P,13,FALSE)=0,"",VLOOKUP($A12,'Annex 2 EHV charges'!$D:$P,13,FALSE)),"") -> 0.05
A13: {=IFERROR(INDEX('Annex 2 EHV charges'!$D$10:$D$108, MATCH(0, IF(ISBLANK('Annex 2 EHV charges'!$D$10:$D$108),1, COUNTIF(A$4:$A12, 'Annex 2 EHV charges'!$D$10:$D$108)), 0)),"")} -> BNTLEY | B13: =IF($A13="","",VLOOKUP($A13,'Annex 2 EHV charges'!$D:$O,2,0)) -> 713 | C13: =IF($A13="","",VLOOKUP($A13,'Annex 2 EHV charges'!$D:$O,3,0)) -> 1900091343787 | D13: =IF($A13="","",VLOOKUP($A13,'Annex 2 EHV charges'!$D:$O,4,0)) -> BNTLEY | E13: =IFERROR(IF(VLOOKUP($A13,'Annex 2 EHV charges'!$D:$O,10,FALSE)=0,"",VLOOKUP($A13,'Annex 2 EHV charges'!$D:$O,10,FALSE)),"") | F13: =IFERROR(IF(VLOOKUP($A13,'Annex 2 EHV charges'!$D:$O,11,FALSE)=0,"",VLOOKUP($A13,'Annex 2 EHV charges'!$D:$O,11,FALSE)),"") -> 1477.43 | G13: =IFERROR(IF(VLOOKUP($A13,'Annex 2 EHV charges'!$D:$O,12,FALSE)=0,"",VLOOKUP($A13,'Annex 2 EHV charges'!$D:$O,12,FALSE)),"") -> 0.05 | H13: =IFERROR(IF(VLOOKUP($A13,'Annex 2 EHV charges'!$D:$P,13,FALSE)=0,"",VLOOKUP($A13,'Annex 2 EHV charges'!$D:$P,13,FALSE)),"") -> 0.05
A14: {=IFERROR(INDEX('Annex 2 EHV charges'!$D$10:$D$108, MATCH(0, IF(ISBLANK('Annex 2 EHV charges'!$D$10:$D$108),1, COUNTIF(A$4:$A13, 'Annex 2 EHV charges'!$D$10:$D$108)), 0)),"")} -> BNTLY2 | B14: =IF($A14="","",VLOOKUP($A14,'Annex 2 EHV charges'!$D:$O,2,0)) -> 712 | C14: =IF($A14="","",VLOOKUP($A14,'Annex 2 EHV charges'!$D:$O,3,0)) -> 1900091463655 | D14: =IF($A14="","",VLOOKUP($A14,'Annex 2 EHV charges'!$D:$O,4,0)) -> BNTLY2 | E14: =IFERROR(IF(VLOOKUP($A14,'Annex 2 EHV charges'!$D:$O,10,FALSE)=0,"",VLOOKUP($A14,'Annex 2 EHV charges'!$D:$O,10,FALSE)),"") | F14: =IFERROR(IF(VLOOKUP($A14,'Annex 2 EHV charges'!$D:$O,11,FALSE)=0,"",VLOOKUP($A14,'Annex 2 EHV charges'!$D:$O,11,FALSE)),"") -> 945.82 | G14: =IFERROR(IF(VLOOKUP($A14,'Annex 2 EHV charges'!$D:$O,12,FALSE)=0,"",VLOOKUP($A14,'Annex 2 EHV charges'!$D:$O,12,FALSE)),"") -> 0.05 | H14: =IFERROR(IF(VLOOKUP($A14,'Annex 2 EHV charges'!$D:$P,13,FALSE)=0,"",VLOOKUP($A14,'Annex 2 EHV charges'!$D:$P,13,FALSE)),"") -> 0.05
A15: {=IFERROR(INDEX('Annex 2 EHV charges'!$D$10:$D$108, MATCH(0, IF(ISBLANK('Annex 2 EHV charges'!$D$10:$D$108),1, COUNTIF(A$4:$A14, 'Annex 2 EHV charges'!$D$10:$D$108)), 0)),"")} -> BOBBNG | B15: =IF($A15="","",VLOOKUP($A15,'Annex 2 EHV charges'!$D:$O,2,0)) -> 705 | C15: =IF($A15="","",VLOOKUP($A15,'Annex 2 EHV charges'!$D:$O,3,0)) -> 1900091395517 | D15: =IF($A15="","",VLOOKUP($A15,'Annex 2 EHV charges'!$D:$O,4,0)) -> BOBBNG | E15: =IFERROR(IF(VLOOKUP($A15,'Annex 2 EHV charges'!$D:$O,10,FALSE)=0,"",VLOOKUP($A15,'Annex 2 EHV charges'!$D:$O,10,FALSE)),"") | F15: =IFERROR(IF(VLOOKUP($A15,'Annex 2 EHV charges'!$D:$O,11,FALSE)=0,"",VLOOKUP($A15,'Annex 2 EHV charges'!$D:$O,11,FALSE)),"") -> 1603.2 | G15: =IFERROR(IF(VLOOKUP($A15,'Annex 2 EHV charges'!$D:$O,12,FALSE)=0,"",VLOOKUP($A15,'Annex 2 EHV charges'!$D:$O,12,FALSE)),"") -> 0.05 | H15: =IFERROR(IF(VLOOKUP($A15,'Annex 2 EHV charges'!$D:$P,13,FALSE)=0,"",VLOOKUP($A15,'Annex 2 EHV charges'!$D:$P,13,FALSE)),"") -> 0.05
A16: {=IFERROR(INDEX('Annex 2 EHV charges'!$D$10:$D$108, MATCH(0, IF(ISBLANK('Annex 2 EHV charges'!$D$10:$D$108),1, COUNTIF(A$4:$A15, 'Annex 2 EHV charges'!$D$10:$D$108)), 0)),"")} -> BRAMBS | B16: =IF($A16="","",VLOOKUP($A16,'Annex 2 EHV charges'!$D:$O,2,0)) -> 695 | C16: =IF($A16="","",VLOOKUP($A16,'Annex 2 EHV charges'!$D:$O,3,0)) -> 1900091566820 | D16: =IF($A16="","",VLOOKUP($A16,'Annex 2 EHV charges'!$D:$O,4,0)) -> BRAMBS | E16: =IFERROR(IF(VLOOKUP($A16,'Annex 2 EHV charges'!$D:$O,10,FALSE)=0,"",VLOOKUP($A16,'Annex 2 EHV charges'!$D:$O,10,FALSE)),"") -> -0.6 | F16: =IFERROR(IF(VLOOKUP($A16,'Annex 2 EHV charges'!$D:$O,11,FALSE)=0,"",VLOOKUP($A16,'Annex 2 EHV charges'!$D:$O,11,FALSE)),"") -> 589.22 | G16: =IFERROR(IF(VLOOKUP($A16,'Annex 2 EHV charges'!$D:$O,12,FALSE)=0,"",VLOOKUP($A16,'Annex 2 EHV charges'!$D:$O,12,FALSE)),"") -> 0.05 | H16: =IFERROR(IF(VLOOKUP($A16,'Annex 2 EHV charges'!$D:$P,13,FALSE)=0,"",VLOOKUP($A16,'Annex 2 EHV charges'!$D:$P,13,FALSE)),"") -> 0.05
... A254: {=IFERROR(INDEX('Annex 2 EHV charges'!$D$10:$D$108, MATCH(0, IF(ISBLANK('Annex 2 EHV charges'!$D$10:$D$108),1, COUNTIF(A$4:$A253, 'Annex 2 EHV charges'!$D$10:$D$108)), 0)),"")} | B254: =IF($A254="","",VLOOKUP($A254,'Annex 2 EHV charges'!$D:$O,2,0)) | C254: =IF($A254="","",VLOOKUP($A254,'Annex 2 EHV charges'!$D:$O,3,0)) | D254: =IF($A254="","",VLOOKUP($A254,'Annex 2 EHV charges'!$D:$O,4,0)) | E254: =IFERROR(IF(VLOOKUP($A254,'Annex 2 EHV charges'!$D:$O,10,FALSE)=0,"",VLOOKUP($A254,'Annex 2 EHV charges'!$D:$O,10,FALSE)),"") | F254: =IFERROR(IF(VLOOKUP($A254,'Annex 2 EHV charges'!$D:$O,11,FALSE)=0,"",VLOOKUP($A254,'Annex 2 EHV charges'!$D:$O,11,FALSE)),"") | G254: =IFERROR(IF(VLOOKUP($A254,'Annex 2 EHV charges'!$D:$O,12,FALSE)=0,"",VLOOKUP($A254,'Annex 2 EHV charges'!$D:$O,12,FALSE)),"") | H254: =IFERROR(IF(VLOOKUP($A254,'Annex 2 EHV charges'!$D:$P,13,FALSE)=0,"",VLOOKUP($A254,'Annex 2 EHV charges'!$D:$P,13,FALSE)),"")

Sheet Annex 3 Preserved charges
A1: Back to Overview
A2: =Overview!B4& " - Effective from "&Overview!D4&" - "&Overview!E4&" LV and HV tariffs" -> South Eastern Power Networks - Effective from 1 April 2024 - Final LV and HV tariffs
A3: Supercustomer preserved charges/additional LLFCs
B4: Closed LLFCs | C4: PCs | D4: Red/black unit charge p/kWh | E4: Amber/yellow unit charge p/kWh | F4: Green unit charge p/kWh | G4: Fixed charge p/MPAN/day
A6: Notes: | B6: South Eastern Power Networks has no Preserved NHH Tariffs/Additional LLFC classes
A11: Site Specific preserved charges/additional LLFCs
B12: Closed LLFCs | C12: PCs | D12: Red/black unit charge p/kWh | E12: Amber/yellow unit charge p/kWh | F12: Green unit charge p/kWh | G12: Fixed charge p/MPAN/day | H12: Capacity charge p/kVA/day | I12: Exceeded capacity charge p/kVA/day | J12: Reactive power charge p/kVArh
A14: Notes: | B14: South Eastern Power Networks has no Preserved HH Tariffs/Additional LLFC classes

Sheet Annex 4 LDNO charges
A1: Back to Overview | B1: Copy from CDCM table 3701 "Tariffs!A42:I84" and paste values into A14 | F1: Copy from EDCM table 6005 "LDNORev!B549:G683" and paste values into D57
A2: =Overview!B4& " - Effective from "&Overview!D4&" - "&Overview!E4&" LDNO tariffs" -> South Eastern Power Networks - Effective from 1 April 2024 - Final LDNO tariffs
A4: Time Bands for LV and HV Designated Properties | F4: Time Bands for Unmetered Properties
A5: Time periods | B5: Red Time Band | C5: Amber Time Band | D5: Green Time Band | H5: Black Time Band | I5: Yellow Time Band | J5: Green Time Band
A6: Monday to Friday (Including Bank Holidays) All Year | B6: 16:00 - 19:00 | C6: 07:00 - 16:00 19:00 - 23:00 | D6: 00:00 - 07:00 23:00 - 24:00 | F6: Monday to Friday (Including Bank Holidays) November to February Inclusive | H6: 16:00 - 19:00 | I6: 07:00 - 16:00 19:00 - 23:00 | J6: 00:00 - 07:00 23:00 - 24:00
A7: Saturday and Sunday All Year | D7: 00:00 - 24:00 | F7: Monday to Friday (Including Bank Holidays) March to October Inclusive | I7: 07:00 - 23:00 | J7: 00:00 - 07:00 23:00 - 24:00
A8: Notes | B8: All the above times are in UK Clock time | F8: Saturday and Sunday All Year | J8: 00:00 - 24:00
F9: Notes | H9: All the above times are in UK Clock time
A11: Tariff name | B11: Unique billing identifier | C11: PCs | D11: Red/black unit charge p/kWh | E11: Amber/yellow unit charge p/kWh | F11: Green unit charge p/kWh | G11: Fixed charge p/MPAN/day | H11: Capacity charge p/kVA/day | I11: Exceeded capacity charge p/kVA/day | J11: Reactive power charge p/kVArh
A12: LDNO LV: Domestic Aggregated or CT with Residual | B12: A00 | C12: 0, 1, 2 | D12: 11.554 | E12: 0.433 | F12: 0.148 | G12: 13.56
A13: LDNO LV: Domestic Aggregated (related MPAN) | B13: B00 | C13: 2 | D13: 11.554 | E13: 0.433 | F13: 0.148
A14: LDNO LV: Non-Domestic Aggregated or CT No Residual | B14: C00 | C14: 0, 3, 4, 5-8 | D14: 7.862 | E14: 0.295 | F14: 0.101 | G14: 4.31
A15: LDNO LV: Non-Domestic Aggregated or CT Band 1 | B15: C01 | C15: 0, 3, 4, 5-8 | D15: 7.862 | E15: 0.295 | F15: 0.101 | G15: 8.06
A16: LDNO LV: Non-Domestic Aggregated or CT Band 2 | B16: C02 | C16: 0, 3, 4, 5-8 | D16: 7.862 | E16: 0.295 | F16: 0.101 | G16: 24.84
A17: LDNO LV: Non-Domestic Aggregated or CT Band 3 | B17: C03 | C17: 0, 3, 4, 5-8 | D17: 7.862 | E17: 0.295 | F17: 0.101 | G17: 51.97
A18: LDNO LV: Non-Domestic Aggregated or CT Band 4 | B18: C04 | C18: 0, 3, 4, 5-8 | D18: 7.862 | E18: 0.295 | F18: 0.101 | G18: 152.15
A19: LDNO LV: Non-Domestic Aggregated (related MPAN) | B19: D00 | C19: 4 | D19: 7.862 | E19: 0.295 | F19: 0.101
A20: LDNO LV: LV Site Specific No Residual | B20: E00 | C20: 0 | D20: 6.519 | E20: 0.237 | F20: 0.079 | G20: 12.79 | H20: 2.87 | I20: 5.11 | J20: 0.212
A21: LDNO LV: LV Site Specific Band 1 | B21: E01 | C21: 0 | D21: 6.519 | E21: 0.237 | F21: 0.079 | G21: 290.94 | H21: 2.87 | I21: 5.11 | J21: 0.212
A22: LDNO LV: LV Site Specific Band 2 | B22: E02 | C22: 0 | D22: 6.519 | E22: 0.237 | F22: 0.079 | G22: 481.47 | H22: 2.87 | I22: 5.11 | J22: 0.212
A23: LDNO LV: LV Site Specific Band 3 | B23: E03 | C23: 0 | D23: 6.519 | E23: 0.237 | F23: 0.079 | G23: 778.14 | H23: 2.87 | I23: 5.11 | J23: 0.212
A24: LDNO LV: LV Site Specific Band 4 | B24: E04 | C24: 0 | D24: 6.519 | E24: 0.237 | F24: 0.079 | G24: 1716.15 | H24: 2.87 | I24: 5.11 | J24: 0.212
A25: LDNO LV: Unmetered Supplies | B25: U00 | C25: 0, 1 or 8 | D25: 30.458 | E25: 2.138 | F25: 1.929
A26: LDNO LV: LV Generation Aggregated | B26: F00 | C26: 0 | D26: -10.397 | E26: -0.39 | F26: -0.133 | G26: 0
A27: LDNO LV: LV Generation Site Specific | B27: G00 | C27: 0 | D27: -10.397 | E27: -0.39 | F27: -0.133 | G27: 0 | J27: 0.311
A28: LDNO HV: Domestic Aggregated or CT with Residual | B28: A10 | C28: 0, 1, 2 | D28: 8.911 | E28: 0.334 | F28: 0.114 | G28: 10.68
A29: LDNO HV: Domestic Aggregated (Related MPAN) | B29: B10 | C29: 2 | D29: 8.911 | E29: 0.334 | F29: 0.114
A30: LDNO HV: Non-Domestic Aggregated or CT No Residual | B30: C10 | C30: 0, 3, 4, 5-8 | D30: 6.063 | E30: 0.227 | F30: 0.078 | G30: 3.51
A31: LDNO HV: Non-Domestic Aggregated or CT Band 1 | B31: C11 | C31: 0, 3, 4, 5-8 | D31: 6.063 | E31: 0.227 | F31: 0.078 | G31: 6.4
A32: LDNO HV: Non-Domestic Aggregated or CT Band 2 | B32: C12 | C32: 0, 3, 4, 5-8 | D32: 6.063 | E32: 0.227 | F32: 0.078 | G32: 19.34
A33: LDNO HV: Non-Domestic Aggregated or CT Band 3 | B33: C13 | C33: 0, 3, 4, 5-8 | D33: 6.063 | E33: 0.227 | F33: 0.078 | G33: 40.27
A34: LDNO HV: Non-Domestic Aggregated or CT Band 4 | B34: C14 | C34: 0, 3, 4, 5-8 | D34: 6.063 | E34: 0.227 | F34: 0.078 | G34: 117.53
A35: LDNO HV: Non-Domestic Aggregated (related MPAN) | B35: D10 | C35: 4 | D35: 6.063 | E35: 0.227 | F35: 0.078
A36: LDNO HV: LV Site Specific No Residual | B36: E10 | C36: 0 | D36: 5.027 | E36: 0.183 | F36: 0.061 | G36: 10.05 | H36: 2.21 | I36: 3.94 | J36: 0.163
A37: LDNO HV: LV Site Specific Band 1 | B37: E11 | C37: 0 | D37: 5.027 | E37: 0.183 | F37: 0.061 | G37: 224.58 | H37: 2.21 | I37: 3.94 | J37: 0.163
A38: LDNO HV: LV Site Specific Band 2 | B38: E12 | C38: 0 | D38: 5.027 | E38: 0.183 | F38: 0.061 | G38: 371.52 | H38: 2.21 | I38: 3.94 | J38: 0.163
A39: LDNO HV: LV Site Specific Band 3 | B39: E13 | C39: 0 | D39: 5.027 | E39: 0.183 | F39: 0.061 | G39: 600.33 | H39: 2.21 | I39: 3.94 | J39: 0.163
A40: LDNO HV: LV Site Specific Band 4 | B40: E14 | C40: 0 | D40: 5.027 | E40: 0.183 | F40: 0.061 | G40: 1323.77 | H40: 2.21 | I40: 3.94 | J40: 0.163
A41: LDNO HV: LV Sub Site Specific No Residual | B41: J10 | C41: 0 | D41: 4.973 | E41: 0.169 | F41: 0.054 | G41: 12.71 | H41: 4.95 | I41: 6.29 | J41: 0.157
A42: LDNO HV: LV Sub Site Specific Band 1 | B42: J11 | C42: 0 | D42: 4.973 | E42: 0.169 | F42: 0.054 | G42: 342.29 | H42: 4.95 | I42: 6.29 | J42: 0.157
...

Sheet Annex 5 LLFs
A1: Back to Overview
A2: These line loss factors are illustrative based on the latest calculated values and are published in good faith. However, the line loss factors that are approved by the BSC Panel for the applicable year and consequently published on the Elexon website will take precedence and will be used in Settlement if they differ from these values.
A3: =Overview!B4& " - Illustrative LLFs for year beginning "&Overview!D4 -> South Eastern Power Networks - Illustrative LLFs for year beginning 1 April 2024
A4: Time periods | C4: Period 1 | D4: Period 2 | E4: Period 3 | F4: Period 4 | G4: Period 5
C5: Winter Peak | D5: Summer Peak | E5: Winter Shoulder | F5: Night | G5: Other
A6: Monday to Friday November to February | C6: 16:00 - 20:00 | E6: 07:00 - 16:00
A7: Monday to Friday June to August | D7: 07:00 - 20:00
A8: Monday to Friday March | E8: 07:00 - 20:00
A9: All Year | F9: 00:00 - 07:00 | G9: All Other Times
A10: Notes | C10: All the above times are in UK Clock time
A12: Generic demand and generation LLFs
A13: Metered voltage, respective periods and associated LLFCs
A14: Metered voltage | B14: Period 1 | C14: Period 2 | D14: Period 3 | E14: Period 4 | F14: Period 5 | G14: Associated LLFC
A15: Low-voltage network | B15: 1.106 | C15: 1.078 | D15: 1.093 | E15: 1.07 | F15: 1.083 | G15: 1, 2, 70, 71, 72, 73, 74, 100, 199, 200, 201, 202, 203, 204, 300, 350, 351, 352, 353, 354, 355, 356, 357, 358, 359, 360, 361, 362, 363, 364, 365, 366, 932, 980, 981
A16: Low-voltage substation | B16: 1.047 | C16: 1.039 | D16: 1.043 | E16: 1.039 | F16: 1.041 | G16: 80, 81, 82, 83, 84, 984, 985
A17: High-voltage network | B17: 1.036 | C17: 1.028 | D17: 1.032 | E17: 1.025 | F17: 1.029 | G17: 90, 91, 92, 93, 94, 988, 989
A18: High-voltage substation | B18: 1.03 | C18: 1.024 | D18: 1.027 | E18: 1.022 | F18: 1.025 | G18: 771, 791, 792
A19: 33kV generic | B19: 1.017 | C19: 1.013 | D19: 1.015 | E19: 1.012 | F19: 1.014 | G19: 796, 797
A20: 132kV generic | B20: 1.006 | C20: 1.005 | D20: 1.006 | E20: 1.004 | F20: 1.005 | G20: 798, 799
A22: EHV site specific LLFs
A23: Demand
A24: Site | B24: Period 1 | C24: Period 2 | D24: Period 3 | E24: Period 4 | F24: Period 5 | G24: Associated LLFC
A25: NEWHVN - Import | B25: 1.035 | C25: 1.05 | D25: 1.049 | E25: 1.046 | F25: 1.048 | G25: 800
A26: BRKHST - Import | B26: 1.047 | C26: 1.016 | D26: 1.048 | E26: 1.03 | F26: 1.032 | G26: 802
A27: KNWLTN - Import | B27: 1.017 | C27: 1.013 | D27: 1.015 | E27: 1.012 | F27: 1.014 | G27: 803
A28: DSCPRK - Import | B28: 1.023 | C28: 1.017 | D28: 1.022 | E28: 1.011 | F28: 1.015 | G28: 804
A29: OLDRSF - Import | B29: 1.017 | C29: 1.013 | D29: 1.015 | E29: 1.012 | F29: 1.014 | G29: 805
A30: WSTWDX - Import | B30: 1.017 | C30: 1.013 | D30: 1.015 | E30: 1.012 | F30: 1.014 | G30: 806
A31: SYCAMR - Import | B31: 1.017 | C31: 1.013 | D31: 1.015 | E31: 1.012 | F31: 1.014 | G31: 807
A32: LENHAM - Import | B32: 1.017 | C32: 1.013 | D32: 1.015 | E32: 1.012 | F32: 1.014 | G32: 808
A33: ASHBYS - Import | B33: 1.017 | C33: 1.013 | D33: 1.015 | E33: 1.012 | F33: 1.014 | G33: 809
A34: BTBRKS - Import | B34: 1.017 | C34: 1.013 | D34: 1.015 | E34: 1.012 | F34: 1.014 | G34: 810
A35: FRWOOD - Import | B35: 1.017 | C35: 1.013 | D35: 1.015 | E35: 1.012 | F35: 1.014 | G35: 811
A36: HADLOW - Import | B36: 1.017 | C36: 1.013 | D36: 1.015 | E36: 1.012 | F36: 1.014 | G36: 812
... A116: POTMBS - Import | B116: 1.006 | C116: 1.005 | D116: 1.006 | E116: 1.004 | F116: 1.005 | G116: 925
A118: EHV site specific LLFs
A119: Generation
A120: Site | B120: Period 1 | C120: Period 2 | D120: Period 3 | E120: Period 4 | F120: Period 5 | G120: Associated LLFC
A121: THAMEM - Export | B121: 1.03 | C121: 1.024 | D121: 1.027 | E121: 1.022 | F121: 1.025 | G121: 691
A122: TWHK66 - Export | B122: 1.03 | C122: 1.024 | D122: 1.027 | E122: 1.022 | F122: 1.025 | G122: 692
...

Sheet Annex 6 New or Amended EHV
A1: Back to Overview | G1: Note: The DNO reserves the right to apply the listed charges to any other MPANs/MSIDs associated with the site. This includes reallocating charges to a traded MPAN at the same site where another MPAN has been disconnected or de-energised. If sites appear in both Annex 2 and Annex 6, the charges in Annex 6 take precedence. Where an existing Designated EHV Property is modified and energised in the charging year, we may revise the EDCM charges for the modified Designated EHV Property.
A2: Annex 6 - Charges for New or Amended Designated EHV Properties
A4: =Overview!B4& " - Effective from "&Overview!D4&" - "&Overview!E4&" new designated EHV charges" -> South Eastern Power Networks - Effective from 1 April 2024 - Final new designated EHV charges
A5: Effective from date | B5: Import Unique Identifier | C5: LLFC | D5: Import MPANs/MSIDs | E5: Export Unique Identifier | F5: LLFC | G5: Export MPANs/MSIDs | H5: Name | I5: Residual Charging Band | J5: ='Annex 2 EHV charges'!I9 -> Import Super Red unit charge (p/kWh) | K5: ='Annex 2 EHV charges'!J9 -> Import fixed charge (p/day) | L5: ='Annex 2 EHV charges'!K9 -> Import capacity charge (p/kVA/day) | M5: ='Annex 2 EHV charges'!L9 -> Import exceeded capacity charge (p/kVA/day) | N5: ='Annex 2 EHV charges'!M9 -> Export Super Red unit charge (p/kWh) | O5: ='Annex 2 EHV charges'!N9 -> Export fixed charge (p/day) | P5: ='Annex 2 EHV charges'!O9 -> Export capacity charge (p/kVA/day) | Q5: ='Annex 2 EHV charges'!P9 -> Export exceeded capacity charge (p/kVA/day)
A6: 45383 | B6: BRELLE | C6: 843 | D6: 1900091523116 | E6: BRELLE | F6: 696 | G6: 1900091523125 | H6: BRELLE | J6: 0 | K6: 57.61 | L6: 1.34 | M6: 1.34 | N6: 0 | O6: 1229.03 | P6: 0.05 | Q6: 0.05
A7: 45383 | B7: BROABS | D7: MSID: 7478 | E7: BROABS | G7: MSID: 7479 | H7: BROABS | J7: 0 | K7: 589.13 | L7: 1.08 | M7: 1.08 | N7: -0.074 | O7: 589.13 | P7: 0.05 | Q7: 0.05
A8: 01/04/2024 | B8: POTMBS | C8: 925 | D8: 1900092272791 | E8: POTMBS | F8: 785 | G8: 1900092272807 | H8: POTMBS | J8: 0 | K8: 1028.78 | L8: 0.95 | M8: 0.95 | N8: 0 | O8: 1028.78 | P8: 0.05 | Q8: 0.05
A9: 01/04/2024 | B9: BTBRKS | C9: 810 | D9: 1900091199350 | E9: BTBRKS | F9: 742 | G9: 1900091199379 | H9: BTBRKS | J9: 0.499 | K9: 83.11 | L9: 1.51 | M9: 1.51 | N9: 0 | O9: 1846.86 | P9: 0.05 | Q9: 0.05
A10: 01/04/2024 | B10: GATWEV | C10: 924 | D10: 1900092421070 | H10: GATWEV | I10: 1 | J10: 0.746 | K10: 3358.19 | L10: 1.81 | M10: 1.81
A11: 01/04/2024 | B11: GATWBS | C11: 907 | D11: 1900092421061 | E11: GATWBS | F11: 768 | G11: 1900092421113 | H11: GATWBS | I11: 1 | J11: 0.746 | K11: 3339.31 | L11: 1.08 | M11: 1.08 | N11: -0.793 | O11: 660.95 | P11: 0.05 | Q11: 0.05
A12: 01/04/2024 | B12: THAER1 | C12: 850 | D12: 1900090417081 | E12: THAER1 | F12: 733 | G12: 1900090417160 | H12: THAER1 | I12: 2 | J12: 0 | K12: 15767.52 | L12: 1.72 | M12: 1.72 | N12: -1.229 | O12: 1526.56 | P12: 0.05 | Q12: 0.05
A13: 01/04/2024 | B13: THAER2 | C13: 850 | D13: 1900090417106 | E13: THAER2 | F13: 733 | G13: 1900090417189 | H13: THAER2 | I13: 2 | J13: 0 | K13: 15452.22 | L13: 1.72 | M13: 1.72 | N13: -1.229 | O13: 1211.26 | P13: 0.05 | Q13: 0.05
A14: 01/04/2024 | B14: THAER3 | C14: 850 | D14: 1900090417133 | E14: THAER3 | F14: 733 | G14: 1900090417212 | H14: THAER3 | I14: 2 | J14: 0 | K14: 16319.29 | L14: 1.72 | M14: 1.72 | N14: -1.229 | O14: 2078.33 | P14: 0.05 | Q14: 0.05
A15: 01/04/2024 | B15: THAER4 | C15: 850 | D15: 1900090417151 | E15: THAER4 | F15: 733 | G15: 1900090417230 | H15: THAER4 | I15: 1 | J15: 0 | K15: 3132.12 | L15: 1.92 | M15: 1.92 | N15: -1.229 | O15: 659.48 | P15: 0.05 | Q15: 0.05
A16: 01/04/2024 | B16: THAER2 | C16: 850 | D16: 1900090417106 | E16: THAER2 | F16: 733 | G16: 1900090417189 | H16: THAER2 | I16: 2 | J16: 0 | K16: 15767.52 | L16: 1.72 | M16: 1.72 | N16: -1.229 | O16: 1526.56 | P16: 0.05 | Q16: 0.05
A17: 01/04/2024 | B17: THAER4 | C17: 850 | D17: 1900090417151 | E17: THAER4 | F17: 733 | G17: 1900090417230 | H17: THAER4 | I17: 1 | J17: 0 | K17: 2816.82 | L17: 2.33 | M17: 2.33 | N17: -1.229 | O17: 344.18 | P17: 0.05 | Q17: 0.05
A18: 01/04/2024 | B18: GATWBS | C18: 907 | D18: 1900092421061 | E18: GATWBS | F18: 768 | G18: 1900092421113 | H18: GATWBS | J18: 0.746 | K18: 462.67 | L18: 1.08 | M18: 1.08 | N18: -0.793 | O18: 660.95 | P18: 0.05 | Q18: 0.05
A19: 01/04/2024 | B19: LONGDC | D19: ENET | H19: LONGDC | I19: 2 | K19: 15575.58 | L19: 1.35 | M19: 1.35
A20: 01/04/2024 | B20: DSCPRK | C20: 804 | D20: 1900091637072;1900091057568;1900060219544 | E20: DSCPRK | F20: 704 | G20: 1900091637081;1900091057559 | H20: DSCPRK | I20: 3 | J20: 0 | K20: 40266.8 | L20: 0.96 | M20: 0.96 | N20: 0 | O20: 6634.06 | P20: 0.05 | Q20: 0.05
A22: =Overview!B4& " - Effective from "&Overview!D4&" - "&Overview!E4&" new designated EHV line loss factors" -> South Eastern Power Networks - Effective from 1 April 2024 - Final new designated EHV line loss factors
A23: Effective from date | B23: Import Unique Identifier | C23: LLFC | D23: Import MPANs/MSIDs | E23: Export Unique Identifier | F23: LLFC | G23: Export MPANs/MSIDs | H23: Name | I23: Residual Charging Band | J23: Import LLF period 1 | K23: Import LLF period 2 | L23: Import LLF period 3 | M23: Import LLF period 4 | N23: Import LLF period 5 | O23: Export LLF period 1 | P23: Export LLF period 2 | Q23: Export LLF period 3 | R23: Export LLF period 4 | S23: Export LLF period 5
