Workbook
Name OLE_LINK1: 'Annex 3 Preserved charges'!#REF!

Sheet Overview
A2: Company and Licence name, charging year, effective from, status
B3: Company and Licence name | C3: Year | D3: Effective From | E3: Status
A4: Company and Licence name, charging year, effective from, status | B4: South Eastern Power Networks | C4: 2021/22 | D4: 1 April 2021 | E4: Final
A6: List of data tables in this workbook
A7: Worksheet | B7: Information
A8: Annex 1 LV, HV and Unmetered Supplies charges | B8: Annex 1 contains the charges to LV and HV Designated Properties and Unmetered Supplies.
A9: Annex 2 EHV charges | B9: ="Annex 2 contains the charges to Designated EHV Properties and charges applied to LDNOs with Designated EHV Properties/end-users embedded in networks within the " &B4 &" Licence area." -> Annex 2 contains the charges to Designated EHV Properties and charges applied to LDNOs with Designated EHV Properties/end-users embedded in networks within the South Eastern Power Networks Licence area.
A10: Annex 3 Preserved charges | B10: Annex 3 contains details of any preserved and additional charges that are valid at this time.
A11: Annex 4 LDNO charges | B11: ="Annex 4 contains charges that are levied on the owner of an embedded network within the "&B4&" Licence area. "&"Electricity suppliers and consumers who have properties connected to an embedded network should contact the embedded network owner to determine their distribution charges."&" The charges listed in this table are not payable by domestic consumers, business consumers or electricity suppliers." -> Annex 4 contains charges that are levied on the owner of an embedded network within the South Eastern Power Networks Licence area. Electricity suppliers and consumers who have properties connected to an embedded network should contact the embedded network owner to determine their distribution charges. The charges listed in this table are not payable by domestic consumers, business consumers or electricity suppliers.
A12: Annex 5 LLFs | B12: Annex 5 has been intentionally left blank as this charging statement is published a complete year before the LLFs have been audited. The line loss factors that are approved by the BSC Panel for the applicable year and consequently published on the Elexon website will take precedence and be used in Settlement. This annex will be re-published with these values once they are available.
A13: Annex 6 Charges for New or Amended Designated EHV Properties | B13: ="Annex 6 contains the charges for new or amended Designated EHV Properties and charges applied to LDNOs with new or amended Designated EHV Properties/end-users embedded in networks within the " &B4 &" Licence area." -> Annex 6 contains the charges for new or amended Designated EHV Properties and charges applied to LDNOs with new or amended Designated EHV Properties/end-users embedded in networks within the South Eastern Power Networks Licence area.
A14: Annex 7 Fixed adders for Supplier of Last Resort and Eligible Bad Debt pass-through costs | B14: Annex 7 contains the fixed adders to recover Supplier of Last Resort and Eligible Bad Debt pass-through costs. The Excess Supplier of Last Resort fixed adder relates to an increase to previously published charges only.
A15: Nodal prices | B15: Contains the underlying [nodal/network group] costs used to calculate the current EDCM charges.
A16: Charge calculator | B16: Charge calculator is a tool to help you estimate your distribution charges using current consumption data and forecast consumption data.
A18: Notes to users of this spreadsheet
A20: Please use this spreadsheet with reference to the LC14 use of system charging statement.
A22: Notes to DNOs populating this spreadsheet
A24: DNOs must endeavour to maintain consistency in the structure of this spreadsheet. Any changes to the structure must be noted in the 'Notes to users of this spreadsheet'
A25: The drop down list on the charge calculator can be expanded by unprotecting the charge calculator sheet and selecting 'data', 'data validation...' and then expanding the 'source' data range. The sheet can then be protected.

Sheet Annex 1 LV, HV and UMS charges
A1: Back to Overview | B1: 'DNOs paste value cells A15:J47 from CDCM 3701 into cells A14:J46
A2: =Overview!B4& " - Effective from "&Overview!D4&" - "&Overview!E4&" LV and HV charges" -> South Eastern Power Networks - Effective from 1 April 2021 - Final LV and HV charges
A4: Time Bands for LV and HV Designated Properties | G4: Time Bands for Unmetered Properties
A5: Time periods | B5: Red Time Band | C5: Amber Time Band | E5: Green Time Band | I5: Black Time Band | J5: Yellow Time Band | K5: Green Time Band
A6: Monday to Friday (Including Bank Holidays) All Year | B6: 16:00 - 19:00 | C6: 07:00 - 16:00 19:00 - 23:00 | E6: 00:00 - 07:00 23:00 - 24:00 | G6: Monday to Friday (Including Bank Holidays) November to February Inclusive | I6: 16:00 - 19:00 | J6: 07:00 - 16:00 19:00 - 23:00 | K6: 00:00 - 07:00 23:00 - 24:00
A7: Saturday and Sunday All Year | E7: 00:00 - 24:00 | G7: Monday to Friday (Including Bank Holidays) March to October Inclusive | J7: 07:00 - 23:00 | K7: 00:00 - 07:00 23:00 - 24:00
A8: Notes | B8: All times are in UK Clock time | G8: Saturday and Sunday All Year | K8: 00:00 - 24:00
G9: Notes | I9: All times are in UK Clock time
A11: Tariff name | B11: Open LLFCs | C11: PCs | D11: Red/black unit charge p/kWh | E11: Amber/yellow unit charge p/kWh | F11: Green unit charge p/kWh | G11: Fixed charge p/MPAN/day | H11: Capacity charge p/kVA/day | I11: Exceeded capacity charge p/kVA/day | J11: Reactive power charge p/kVArh | K11: Closed LLFCs
A12: Domestic Aggregated | B12: 1, 100, 300 | C12: 1, 2 or 0 | D12: 16.865 | E12: 1.208 | F12: 0.665 | G12: 3.99 | K12: 101, 250, 301
A13: Domestic Aggregated (related MPAN) | B13: 2, 251 | C13: 2 | D13: 16.865 | E13: 1.208 | F13: 0.665 | K13: 283, 296
A14: Non-Domestic Aggregated | B14: 120, 200, 201, 202, 203, 204, 320, 480 | C14: 3-8 or 0 | D14: 13.204 | E14: 1.062 | F14: 0.641 | G14: 4.14 | K14: 124, 270, 274, 324, 484
A15: Non-Domestic Aggregated (related MPAN) | B15: 287 | C15: 4 | D15: 13.204 | E15: 1.062 | F15: 0.641 | K15: 297
A16: LV Site Specific | B16: 71, 72, 73, 74, 550 | C16: 0 | D16: 9.09 | E16: 0.881 | F16: 0.61 | G16: 11.31 | H16: 3.68 | I16: 7.12 | J16: 0.276
A17: LV Sub Site Specific | B17: 81, 82, 83, 84, 756 | C17: 0 | D17: 5.848 | E17: 0.735 | F17: 0.585 | G17: 8.39 | H17: 5.7 | I17: 7.43 | J17: 0.161
A18: HV Site Specific | B18: 91, 92, 93, 94, 650 | C18: 0 | D18: 5.471 | E18: 0.713 | F18: 0.58 | G18: 111.11 | H18: 4.27 | I18: 6.63 | J18: 0.151
A19: LV Site Specific Storage Import | B19: 19, 70 | C19: 0 | D19: 8.531 | E19: 0.321 | F19: 0.05 | G19: 11.31 | H19: 3.68 | I19: 7.12 | J19: 0.276
A20: LV Sub Site Specific Storage Import | B20: 79, 80 | C20: 0 | D20: 5.289 | E20: 0.176 | F20: 0.025 | G20: 8.39 | H20: 5.7 | I20: 7.43 | J20: 0.161
A21: HV Site Specific Storage Import | B21: 89, 90 | C21: 0 | D21: 4.911 | E21: 0.153 | F21: 0.021 | G21: 111.11 | H21: 4.27 | I21: 6.63 | J21: 0.151
A22: Unmetered Supplies | B22: 350, 351, 352, 353, 354, 355, 356, 357, 358, 359, 360, 361, 362, 363, 364, 365, 366 | C22: 1, 8 or 0 | D22: 40.302 | E22: 1.789 | F22: 1.317
A23: LV Generation Aggregated | B23: 932 | C23: 8 or 0 | D23: -9.262 | E23: -0.368 | F23: -0.06 | G23: 0 | K23: 922, 933
A24: LV Sub Generation Aggregated | C24: 0 | D24: -8.273 | E24: -0.318 | F24: -0.051 | G24: 0
A25: LV Generation Site Specific | B25: 980, 982 | C25: 0 | D25: -9.262 | E25: -0.368 | F25: -0.06 | G25: 0 | J25: 0.267
A26: LV Generation Site Specific no RP charge | B26: 981, 983 | C26: 0 | D26: -9.262 | E26: -0.368 | F26: -0.06 | G26: 0
A27: LV Sub Generation Site Specific | B27: 984, 986 | C27: 0 | D27: -8.273 | E27: -0.318 | F27: -0.051 | G27: 0 | J27: 0.243
A28: LV Sub Generation Site Specific no RP charge | B28: 985, 987 | C28: 0 | D28: -8.273 | E28: -0.318 | F28: -0.051 | G28: 0
A29: HV Generation Site Specific | B29: 988, 990 | C29: 0 | D29: -5.769 | E29: -0.189 | F29: -0.027 | G29: 9.39 | J29: 0.196
A30: HV Generation Site Specific no RP charge | B30: 989, 991 | C30: 0 | D30: -5.769 | E30: -0.189 | F30: -0.027 | G30: 9.39

Sheet Annex 2 EHV charges
A1: Back to Overview | C1: Copy EDCM table 5001 range starting B101 and paste into G11. Extend or reduce print area as required. | F1: Note: The list of MPANs / MSIDs provided may be incomplete; the DNO reserves the right to apply the listed charges to any other MPANs / MSIDs associated with the site.
A2: =Overview!B4& " - Effective from "&Overview!D4&" - "&Overview!E4&" EDCM charges" -> South Eastern Power Networks - Effective from 1 April 2021 - Final EDCM charges
A4: Time Periods for Designated EHV Properties
A5: Time periods | D5: Super Red Time Band
A6: Monday to Friday (Including Bank Holidays) November to February Inclusive | D6: 16:00 - 19:00
A7: Notes | D7: All times are in UK Clock time
A9: Import Unique Identifier | B9: LLFC | C9: Import MPANs/MSIDs | D9: Export Unique Identifier | E9: LLFC | F9: Export MPANs/MSIDs | G9: Name | H9: Import Super Red unit charge (p/kWh) | I9: Import fixed charge (p/day) | J9: Import capacity charge (p/kVA/day) | K9: Import exceeded capacity charge (p/kVA/day) | L9: Export Super Red unit charge (p/kWh) | M9: Export fixed charge (p/day) | N9: Export capacity charge (p/kVA/day) | O9: Export exceeded capacity charge (p/kVA/day)
A10: B&RLTD | B10: 834 | C10: 1900035000482 1900035425153 | G10: B&RLTD | H10: 2.862 | I10: 218.82 | J10: 5.37 | K10: 5.37
A11: BEDDIN | B11: 889 | C11: 1900070745640 1900070745650 1900070745669 1900070745678 | G11: BEDDIN | H11: 0 | I11: 109.41 | J11: 1.26 | K11: 1.26
A12: BP_OIL | B12: 835 | C12: 1900017426438 1900017426447 | G12: BP_OIL | H12: 1.109 | I12: 218.82 | J12: 1.84 | K12: 1.84
A13: CHESDC | B13: ENET | C13: 1999000002228 1999000002237 | G13: CHESDC | H13: 0 | I13: 627.76 | J13: 1.55 | K13: 1.55
A14: DIGREA | B14: 833 | C14: 1900091200323 1900091200332 | G14: DIGREA | H14: 0 | I14: 1536.48 | J14: 3.48 | K14: 3.48
A15: EUROTU | B15: 874 | C15: 1900060219605 | G15: EUROTU | H15: 0 | I15: 90359.38 | J15: 0.65 | K15: 0.65
A16: GAT_AF | B16: 869 | C16: 1900017427938 1900017427947 1900060576620 | G16: GAT_AF | H16: 2.138 | I16: 2443.9 | J16: 7.42 | K16: 7.42
A17: GAT_BF | B17: 870 | C17: 1900060690231 1900060690240 | G17: GAT_BF | H17: 0.723 | I17: 627.76 | J17: 4.84 | K17: 4.84
A18: KNGSPN | C18: MSID: 1027 | G18: KNGSPN | H18: 0 | I18: 0 | J18: 2.7 | K18: 2.7
A19: NP_LAB | B19: 837 | C19: 1900047386380 | G19: NP_LAB | H19: 2.398 | I19: 437.64 | J19: 4.49 | K19: 4.49
A20: NR_3BR | B20: 866 | C20: 1900060219145 | G20: NR_3BR | H20: 0.863 | I20: 941.64 | J20: 4.66 | K20: 4.66
A21: NR_AFD | B21: 851 | C21: 1900060219377 | G21: NR_AFD | H21: 0.176 | I21: 627.76 | J21: 2.4 | K21: 2.4
A22: NR_ASH | B22: 879 | C22: 1900070068129 | G22: NR_ASH | H22: 0.224 | I22: 627.76 | J22: 4.41 | K22: 4.41
A23: NR_BRI | B23: 852 | C23: 1900060218675 | G23: NR_BRI | H23: 0 | I23: 941.64 | J23: 2.44 | K23: 2.44
A24: NR_BYF | B24: 853 | C24: 1900060218727 | G24: NR_BYF | H24: 0.263 | I24: 941.64 | J24: 2.17 | K24: 2.17
A25: NR_CAN | B25: 854 | C25: 1900060218790 | G25: NR_CAN | H25: 0.017 | I25: 627.76 | J25: 3.01 | K25: 3.01
A26: NR_CRO | B26: 855 | C26: 1900060218815 | G26: NR_CRO | H26: 0 | I26: 627.76 | J26: 2.88 | K26: 2.88
A27: NR_DOR | B27: 856 | C27: 1900060219303 | G27: NR_DOR | H27: 2.343 | I27: 627.76 | J27: 3.19 | K27: 3.19
A28: NR_EAS | B28: 857 | C28: 1900060218912 | G28: NR_EAS | H28: 3.464 | I28: 627.76 | J28: 3.86 | K28: 3.86
A29: NR_FOK | B29: 858 | C29: 1900060218959 | G29: NR_FOK | H29: 0.102 | I29: 627.76 | J29: 3.01 | K29: 3.01
A30: NR_HAS | B30: 859 | C30: 1900060218986 | G30: NR_HAS | H30: 0.267 | I30: 3900.36 | J30: 3.64 | K30: 3.64
... A34: NR_QUE | B34: 863 | C34: 1900060219084 | G34: NR_QUE | H34: 0 | I34: 329.74 | J34: 3.27 | K34: 3.27
A35: NR_SIT | B35: 864 | C35: 1900060219819 1900060219855 | G35: NR_SIT | H35: 0.002 | I35: 627.76 | J35: 1.64 | K35: 1.64
A36: NR_THA | B36: 865 | C36: 1900060219720 1900060219794 | G36: NR_THA | H36: 0.732 | I36: 627.76 | J36: 4.1 | K36: 4.1
A37: NR_TUN | B37: 867 | C37: 1900060219206 | G37: NR_TUN | H37: 1.17 | I37: 627.76 | J37: 2.9 | K37: 2.9
A38: PFIZER | B38: 881 | C38: 1900060219544 | G38: PFIZER | H38: 0.142 | I38: 2082.9 | J38: 1.06 | K38: 1.06
A39: SENTIV | B39: 888 | C39: 1900090497281 1900090497290 1900090497306 1900090497315 | G39: SENTIV | H39: 0.005 | I39: 68659.26 | J39: 1.42 | K39: 1.42
A40: THAMEM | B40: 838 | C40: 1900090872672 1900090872681 | D40: THAMEM | E40: 691 | F40: 1900090876979 1900090876988 | G40: THAMEM | H40: 0 | I40: 3839.52 | J40: 2.26 | K40: 2.26 | L40: 0 | M40: 2879.64 | N40: 0.05 | O40: 0.05
A41: THAMES | B41: 884 | C41: 1900016424857 | D41: THAMES | E41: 732 | F41: 1900060576611 | G41: THAMES | H41: 0 | I41: 2942.58 | J41: 4.59 | K41: 4.59 | L41: 0 | M41: 1726.31 | N41: 0.05 | O41: 0.05
A42: TWHK66 | B42: 839 | C42: 1900091206176 | D42: TWHK66 | E42: 692 | F42: 1900091206194 | G42: TWHK66 | H42: 3.008 | I42: 188.64 | J42: 1.88 | K42: 1.88 | L42: -2.957 | M42: 30.18 | N42: 0.05 | O42: 0.05
A43: ASHBYS | B43: 809 | C43: 1900091216963 | D43: ASHBYS | E43: 741 | F43: 1900091216972 | G43: ASHBYS | H43: 0.051 | I43: 9.63 | J43: 4.22 | K43: 4.22 | L43: 0 | M43: 982.39 | N43: 0.05 | O43: 0.05
A44: ASHGEN | B44: 801 | C44: 1900090978866 | D44: ASHGEN | E44: 734 | F44: 1900090978875 | G44: ASHGEN | H44: 0 | I44: 91.9 | J44: 1.25 | K44: 1.25 | L44: 0 | M44: 2756.96 | N44: 0.05 | O44: 0.05
A45: AYLESF | B45: 868 | C45: 1900060216613 | D45: AYLESF | E45: 725 | F45: 1900060436880 | G45: AYLESF | H45: 0 | I45: 313.88 | J45: 0.87 | K45: 0.87 | L45: 0 | M45: 0 | N45: 0 | O45: 0
...

Sheet Annex 2a Import
A1: Note: The list of MPANs / MSIDs provided may be incomplete; the DNO reserves the right to apply the listed charges to any other MPANs / MSIDs associated with the site. Note: This table is automatically populated based on the content of the tab entitled 'Annex 2 EHV Charges'. The timebands are as shown in Annex 2.
A2: =Overview!B4& " - Effective from "&Overview!D4&" - "&Overview!E4&" EDCM import charges" -> South Eastern Power Networks - Effective from 1 April 2021 - Final EDCM import charges
A4: Import Unique Identifier | B4: LLFC | C4: Import MPANs/MSIDs | D4: Name | E4: ='Annex 2 EHV charges'!H9 -> Import Super Red unit charge (p/kWh) | F4: ='Annex 2 EHV charges'!I9 -> Import fixed charge (p/day) | G4: ='Annex 2 EHV charges'!J9 -> Import capacity charge (p/kVA/day) | H4: ='Annex 2 EHV charges'!K9 -> Import exceeded capacity charge (p/kVA/day)
A5: {=IFERROR(INDEX('Annex 2 EHV charges'!$A$10:$A$259, MATCH(0, IF(ISBLANK('Annex 2 EHV charges'!$A$10:$A$259),1, COUNTIF(A$4:$A4, 'Annex 2 EHV charges'!$A$10:$A$259)), 0)),"")} -> B&RLTD | B5: =IF($A5="","",VLOOKUP($A5,'Annex 2 EHV charges'!$A:$O,2,0)) -> 834 | C5: =IF($A5="","",VLOOKUP($A5,'Annex 2 EHV charges'!$A:$O,3,0)) -> 1900035000482 1900035425153 | D5: =IF($A5="","",VLOOKUP($A5,'Annex 2 EHV charges'!$A:$O,7,0)) -> B&RLTD | E5: =IFERROR(IF(VLOOKUP($A5,'Annex 2 EHV charges'!$A:$O,8,FALSE)=0,"",VLOOKUP($A5,'Annex 2 EHV charges'!$A:$O,8,FALSE)),"") -> 2.862 | F5: =IFERROR(IF(VLOOKUP($A5,'Annex 2 EHV charges'!$A:$O,9,FALSE)=0,"",VLOOKUP($A5,'Annex 2 EHV charges'!$A:$O,9,FALSE)),"") -> 218.82 | G5: =IFERROR(IF(VLOOKUP($A5,'Annex 2 EHV charges'!$A:$O,10,FALSE)=0,"",VLOOKUP($A5,'Annex 2 EHV charges'!$A:$O,10,FALSE)),"") -> 5.37 | H5: =IFERROR(IF(VLOOKUP($A5,'Annex 2 EHV charges'!$A:$O,11,FALSE)=0,"",VLOOKUP($A5,'Annex 2 EHV charges'!$A:$O,11,FALSE)),"") -> 5.37
A6: {=IFERROR(INDEX('Annex 2 EHV charges'!$A$10:$A$259, MATCH(0, IF(ISBLANK('Annex 2 EHV charges'!$A$10:$A$259),1, COUNTIF(A$4:$A5, 'Annex 2 EHV charges'!$A$10:$A$259)), 0)),"")} -> BEDDIN | B6: =IF($A6="","",VLOOKUP($A6,'Annex 2 EHV charges'!$A:$O,2,0)) -> 889 | C6: =IF($A6="","",VLOOKUP($A6,'Annex 2 EHV charges'!$A:$O,3,0)) -> 1900070745640 1900070745650 1900070745669 1900070745678 | D6: =IF($A6="","",VLOOKUP($A6,'Annex 2 EHV charges'!$A:$O,7,0)) -> BEDDIN | E6: =IFERROR(IF(VLOOKUP($A6,'Annex 2 EHV charges'!$A:$O,8,FALSE)=0,"",VLOOKUP($A6,'Annex 2 EHV charges'!$A:$O,8,FALSE)),"") | F6: =IFERROR(IF(VLOOKUP($A6,'Annex 2 EHV charges'!$A:$O,9,FALSE)=0,"",VLOOKUP($A6,'Annex 2 EHV charges'!$A:$O,9,FALSE)),"") -> 109.41 | G6: =IFERROR(IF(VLOOKUP($A6,'Annex 2 EHV charges'!$A:$O,10,FALSE)=0,"",VLOOKUP($A6,'Annex 2 EHV charges'!$A:$O,10,FALSE)),"") -> 1.26 | H6: =IFERROR(IF(VLOOKUP($A6,'Annex 2 EHV charges'!$A:$O,11,FALSE)=0,"",VLOOKUP($A6,'Annex 2 EHV charges'!$A:$O,11,FALSE)),"") -> 1.26
A7: {=IFERROR(INDEX('Annex 2 EHV charges'!$A$10:$A$259, MATCH(0, IF(ISBLANK('Annex 2 EHV charges'!$A$10:$A$259),1, COUNTIF(A$4:$A6, 'Annex 2 EHV charges'!$A$10:$A$259)), 0)),"")} -> BP_OIL | B7: =IF($A7="","",VLOOKUP($A7,'Annex 2 EHV charges'!$A:$O,2,0)) -> 835 | C7: =IF($A7="","",VLOOKUP($A7,'Annex 2 EHV charges'!$A:$O,3,0)) -> 1900017426438 1900017426447 | D7: =IF($A7="","",VLOOKUP($A7,'Annex 2 EHV charges'!$A:$O,7,0)) -> BP_OIL | E7: =IFERROR(IF(VLOOKUP($A7,'Annex 2 EHV charges'!$A:$O,8,FALSE)=0,"",VLOOKUP($A7,'Annex 2 EHV charges'!$A:$O,8,FALSE)),"") -> 1.109 | F7: =IFERROR(IF(VLOOKUP($A7,'Annex 2 EHV charges'!$A:$O,9,FALSE)=0,"",VLOOKUP($A7,'Annex 2 EHV charges'!$A:$O,9,FALSE)),"") -> 218.82 | G7: =IFERROR(IF(VLOOKUP($A7,'Annex 2 EHV charges'!$A:$O,10,FALSE)=0,"",VLOOKUP($A7,'Annex 2 EHV charges'!$A:$O,10,FALSE)),"") -> 1.84 | H7: =IFERROR(IF(VLOOKUP($A7,'Annex 2 EHV charges'!$A:$O,11,FALSE)=0,"",VLOOKUP($A7,'Annex 2 EHV charges'!$A:$O,11,FALSE)),"") -> 1.84
A8: {=IFERROR(INDEX('Annex 2 EHV charges'!$A$10:$A$259, MATCH(0, IF(ISBLANK('Annex 2 EHV charges'!$A$10:$A$259),1, COUNTIF(A$4:$A7, 'Annex 2 EHV charges'!$A$10:$A$259)), 0)),"")} -> CHESDC | B8: =IF($A8="","",VLOOKUP($A8,'Annex 2 EHV charges'!$A:$O,2,0)) -> ENET | C8: =IF($A8="","",VLOOKUP($A8,'Annex 2 EHV charges'!$A:$O,3,0)) -> 1999000002228 1999000002237 | D8: =IF($A8="","",VLOOKUP($A8,'Annex 2 EHV charges'!$A:$O,7,0)) -> CHESDC | E8: =IFERROR(IF(VLOOKUP($A8,'Annex 2 EHV charges'!$A:$O,8,FALSE)=0,"",VLOOKUP($A8,'Annex 2 EHV charges'!$A:$O,8,FALSE)),"") | F8: =IFERROR(IF(VLOOKUP($A8,'Annex 2 EHV charges'!$A:$O,9,FALSE)=0,"",VLOOKUP($A8,'Annex 2 EHV charges'!$A:$O,9,FALSE)),"") -> 627.76 | G8: =IFERROR(IF(VLOOKUP($A8,'Annex 2 EHV charges'!$A:$O,10,FALSE)=0,"",VLOOKUP($A8,'Annex 2 EHV charges'!$A:$O,10,FALSE)),"") -> 1.55 | H8: =IFERROR(IF(VLOOKUP($A8,'Annex 2 EHV charges'!$A:$O,11,FALSE)=0,"",VLOOKUP($A8,'Annex 2 EHV charges'!$A:$O,11,FALSE)),"") -> 1.55
A9: {=IFERROR(INDEX('Annex 2 EHV charges'!$A$10:$A$259, MATCH(0, IF(ISBLANK('Annex 2 EHV charges'!$A$10:$A$259),1, COUNTIF(A$4:$A8, 'Annex 2 EHV charges'!$A$10:$A$259)), 0)),"")} -> DIGREA | B9: =IF($A9="","",VLOOKUP($A9,'Annex 2 EHV charges'!$A:$O,2,0)) -> 833 | C9: =IF($A9="","",VLOOKUP($A9,'Annex 2 EHV charges'!$A:$O,3,0)) -> 1900091200323 1900091200332 | D9: =IF($A9="","",VLOOKUP($A9,'Annex 2 EHV charges'!$A:$O,7,0)) -> DIGREA | E9: =IFERROR(IF(VLOOKUP($A9,'Annex 2 EHV charges'!$A:$O,8,FALSE)=0,"",VLOOKUP($A9,'Annex 2 EHV charges'!$A:$O,8,FALSE)),"") | F9: =IFERROR(IF(VLOOKUP($A9,'Annex 2 EHV charges'!$A:$O,9,FALSE)=0,"",VLOOKUP($A9,'Annex 2 EHV charges'!$A:$O,9,FALSE)),"") -> 1536.48 | G9: =IFERROR(IF(VLOOKUP($A9,'Annex 2 EHV charges'!$A:$O,10,FALSE)=0,"",VLOOKUP($A9,'Annex 2 EHV charges'!$A:$O,10,FALSE)),"") -> 3.48 | H9: =IFERROR(IF(VLOOKUP($A9,'Annex 2 EHV charges'!$A:$O,11,FALSE)=0,"",VLOOKUP($A9,'Annex 2 EHV charges'!$A:$O,11,FALSE)),"") -> 3.48
A10: {=IFERROR(INDEX('Annex 2 EHV charges'!$A$10:$A$259, MATCH(0, IF(ISBLANK('Annex 2 EHV charges'!$A$10:$A$259),1, COUNTIF(A$4:$A9, 'Annex 2 EHV charges'!$A$10:$A$259)), 0)),"")} -> EUROTU | B10: =IF($A10="","",VLOOKUP($A10,'Annex 2 EHV charges'!$A:$O,2,0)) -> 874 | C10: =IF($A10="","",VLOOKUP($A10,'Annex 2 EHV charges'!$A:$O,3,0)) -> 1900060219605 | D10: =IF($A10="","",VLOOKUP($A10,'Annex 2 EHV charges'!$A:$O,7,0)) -> EUROTU | E10: =IFERROR(IF(VLOOKUP($A10,'Annex 2 EHV charges'!$A:$O,8,FALSE)=0,"",VLOOKUP($A10,'Annex 2 EHV charges'!$A:$O,8,FALSE)),"") | F10: =IFERROR(IF(VLOOKUP($A10,'Annex 2 EHV charges'!$A:$O,9,FALSE)=0,"",VLOOKUP($A10,'Annex 2 EHV charges'!$A:$O,9,FALSE)),"") -> 90359.38 | G10: =IFERROR(IF(VLOOKUP($A10,'Annex 2 EHV charges'!$A:$O,10,FALSE)=0,"",VLOOKUP($A10,'Annex 2 EHV charges'!$A:$O,10,FALSE)),"") -> 0.65 | H10: =IFERROR(IF(VLOOKUP($A10,'Annex 2 EHV charges'!$A:$O,11,FALSE)=0,"",VLOOKUP($A10,'Annex 2 EHV charges'!$A:$O,11,FALSE)),"") -> 0.65
A11: {=IFERROR(INDEX('Annex 2 EHV charges'!$A$10:$A$259, MATCH(0, IF(ISBLANK('Annex 2 EHV charges'!$A$10:$A$259),1, COUNTIF(A$4:$A10, 'Annex 2 EHV charges'!$A$10:$A$259)), 0)),"")} -> GAT_AF | B11: =IF($A11="","",VLOOKUP($A11,'Annex 2 EHV charges'!$A:$O,2,0)) -> 869 | C11: =IF($A11="","",VLOOKUP($A11,'Annex 2 EHV charges'!$A:$O,3,0)) -> 1900017427938 1900017427947 1900060576620 | D11: =IF($A11="","",VLOOKUP($A11,'Annex 2 EHV charges'!$A:$O,7,0)) -> GAT_AF | E11: =IFERROR(IF(VLOOKUP($A11,'Annex 2 EHV charges'!$A:$O,8,FALSE)=0,"",VLOOKUP($A11,'Annex 2 EHV charges'!$A:$O,8,FALSE)),"") -> 2.138 | F11: =IFERROR(IF(VLOOKUP($A11,'Annex 2 EHV charges'!$A:$O,9,FALSE)=0,"",VLOOKUP($A11,'Annex 2 EHV charges'!$A:$O,9,FALSE)),"") -> 2443.9 | G11: =IFERROR(IF(VLOOKUP($A11,'Annex 2 EHV charges'!$A:$O,10,FALSE)=0,"",VLOOKUP($A11,'Annex 2 EHV charges'!$A:$O,10,FALSE)),"") -> 7.42 | H11: =IFERROR(IF(VLOOKUP($A11,'Annex 2 EHV charges'!$A:$O,11,FALSE)=0,"",VLOOKUP($A11,'Annex 2 EHV charges'!$A:$O,11,FALSE)),"") -> 7.42
A12: {=IFERROR(INDEX('Annex 2 EHV charges'!$A$10:$A$259, MATCH(0, IF(ISBLANK('Annex 2 EHV charges'!$A$10:$A$259),1, COUNTIF(A$4:$A11, 'Annex 2 EHV charges'!$A$10:$A$259)), 0)),"")} -> GAT_BF | B12: =IF($A12="","",VLOOKUP($A12,'Annex 2 EHV charges'!$A:$O,2,0)) -> 870 | C12: =IF($A12="","",VLOOKUP($A12,'Annex 2 EHV charges'!$A:$O,3,0)) -> 1900060690231 1900060690240 | D12: =IF($A12="","",VLOOKUP($A12,'Annex 2 EHV charges'!$A:$O,7,0)) -> GAT_BF | E12: =IFERROR(IF(VLOOKUP($A12,'Annex 2 EHV charges'!$A:$O,8,FALSE)=0,"",VLOOKUP($A12,'Annex 2 EHV charges'!$A:$O,8,FALSE)),"") -> 0.723 | F12: =IFERROR(IF(VLOOKUP($A12,'Annex 2 EHV charges'!$A:$O,9,FALSE)=0,"",VLOOKUP($A12,'Annex 2 EHV charges'!$A:$O,9,FALSE)),"") -> 627.76 | G12: =IFERROR(IF(VLOOKUP($A12,'Annex 2 EHV charges'!$A:$O,10,FALSE)=0,"",VLOOKUP($A12,'Annex 2 EHV charges'!$A:$O,10,FALSE)),"") -> 4.84 | H12: =IFERROR(IF(VLOOKUP($A12,'Annex 2 EHV charges'!$A:$O,11,FALSE)=0,"",VLOOKUP($A12,'Annex 2 EHV charges'!$A:$O,11,FALSE)),"") -> 4.84
A13: {=IFERROR(INDEX('Annex 2 EHV charges'!$A$10:$A$259, MATCH(0, IF(ISBLANK('Annex 2 EHV charges'!$A$10:$A$259),1, COUNTIF(A$4:$A12, 'Annex 2 EHV charges'!$A$10:$A$259)), 0)),"")} -> KNGSPN | B13: =IF($A13="","",VLOOKUP($A13,'Annex 2 EHV charges'!$A:$O,2,0)) -> 0 | C13: =IF($A13="","",VLOOKUP($A13,'Annex 2 EHV charges'!$A:$O,3,0)) -> MSID: 1027 | D13: =IF($A13="","",VLOOKUP($A13,'Annex 2 EHV charges'!$A:$O,7,0)) -> KNGSPN | E13: =IFERROR(IF(VLOOKUP($A13,'Annex 2 EHV charges'!$A:$O,8,FALSE)=0,"",VLOOKUP($A13,'Annex 2 EHV charges'!$A:$O,8,FALSE)),"") | F13: =IFERROR(IF(VLOOKUP($A13,'Annex 2 EHV charges'!$A:$O,9,FALSE)=0,"",VLOOKUP($A13,'Annex 2 EHV charges'!$A:$O,9,FALSE)),"") | G13: =IFERROR(IF(VLOOKUP($A13,'Annex 2 EHV charges'!$A:$O,10,FALSE)=0,"",VLOOKUP($A13,'Annex 2 EHV charges'!$A:$O,10,FALSE)),"") -> 2.7 | H13: =IFERROR(IF(VLOOKUP($A13,'Annex 2 EHV charges'!$A:$O,11,FALSE)=0,"",VLOOKUP($A13,'Annex 2 EHV charges'!$A:$O,11,FALSE)),"") -> 2.7
A14: {=IFERROR(INDEX('Annex 2 EHV charges'!$A$10:$A$259, MATCH(0, IF(ISBLANK('Annex 2 EHV charges'!$A$10:$A$259),1, COUNTIF(A$4:$A13, 'Annex 2 EHV charges'!$A$10:$A$259)), 0)),"")} -> NP_LAB | B14: =IF($A14="","",VLOOKUP($A14,'Annex 2 EHV charges'!$A:$O,2,0)) -> 837 | C14: =IF($A14="","",VLOOKUP($A14,'Annex 2 EHV charges'!$A:$O,3,0)) -> 1900047386380 | D14: =IF($A14="","",VLOOKUP($A14,'Annex 2 EHV charges'!$A:$O,7,0)) -> NP_LAB | E14: =IFERROR(IF(VLOOKUP($A14,'Annex 2 EHV charges'!$A:$O,8,FALSE)=0,"",VLOOKUP($A14,'Annex 2 EHV charges'!$A:$O,8,FALSE)),"") -> 2.398 | F14: =IFERROR(IF(VLOOKUP($A14,'Annex 2 EHV charges'!$A:$O,9,FALSE)=0,"",VLOOKUP($A14,'Annex 2 EHV charges'!$A:$O,9,FALSE)),"") -> 437.64 | G14: =IFERROR(IF(VLOOKUP($A14,'Annex 2 EHV charges'!$A:$O,10,FALSE)=0,"",VLOOKUP($A14,'Annex 2 EHV charges'!$A:$O,10,FALSE)),"") -> 4.49 | H14: =IFERROR(IF(VLOOKUP($A14,'Annex 2 EHV charges'!$A:$O,11,FALSE)=0,"",VLOOKUP($A14,'Annex 2 EHV charges'!$A:$O,11,FALSE)),"") -> 4.49
A15: {=IFERROR(INDEX('Annex 2 EHV charges'!$A$10:$A$259, MATCH(0, IF(ISBLANK('Annex 2 EHV charges'!$A$10:$A$259),1, COUNTIF(A$4:$A14, 'Annex 2 EHV charges'!$A$10:$A$259)), 0)),"")} -> NR_3BR | B15: =IF($A15="","",VLOOKUP($A15,'Annex 2 EHV charges'!$A:$O,2,0)) -> 866 | C15: =IF($A15="","",VLOOKUP($A15,'Annex 2 EHV charges'!$A:$O,3,0)) -> 1900060219145 | D15: =IF($A15="","",VLOOKUP($A15,'Annex 2 EHV charges'!$A:$O,7,0)) -> NR_3BR | E15: =IFERROR(IF(VLOOKUP($A15,'Annex 2 EHV charges'!$A:$O,8,FALSE)=0,"",VLOOKUP($A15,'Annex 2 EHV charges'!$A:$O,8,FALSE)),"") -> 0.863 | F15: =IFERROR(IF(VLOOKUP($A15,'Annex 2 EHV charges'!$A:$O,9,FALSE)=0,"",VLOOKUP($A15,'Annex 2 EHV charges'!$A:$O,9,FALSE)),"") -> 941.64 | G15: =IFERROR(IF(VLOOKUP($A15,'Annex 2 EHV charges'!$A:$O,10,FALSE)=0,"",VLOOKUP($A15,'Annex 2 EHV charges'!$A:$O,10,FALSE)),"") -> 4.66 | H15: =IFERROR(IF(VLOOKUP($A15,'Annex 2 EHV charges'!$A:$O,11,FALSE)=0,"",VLOOKUP($A15,'Annex 2 EHV charges'!$A:$O,11,FALSE)),"") -> 4.66
A16: {=IFERROR(INDEX('Annex 2 EHV charges'!$A$10:$A$259, MATCH(0, IF(ISBLANK('Annex 2 EHV charges'!$A$10:$A$259),1, COUNTIF(A$4:$A15, 'Annex 2 EHV charges'!$A$10:$A$259)), 0)),"")} -> NR_AFD | B16: =IF($A16="","",VLOOKUP($A16,'Annex 2 EHV charges'!$A:$O,2,0)) -> 851 | C16: =IF($A16="","",VLOOKUP($A16,'Annex 2 EHV charges'!$A:$O,3,0)) -> 1900060219377 | D16: =IF($A16="","",VLOOKUP($A16,'Annex 2 EHV charges'!$A:$O,7,0)) -> NR_AFD | E16: =IFERROR(IF(VLOOKUP($A16,'Annex 2 EHV charges'!$A:$O,8,FALSE)=0,"",VLOOKUP($A16,'Annex 2 EHV charges'!$A:$O,8,FALSE)),"") -> 0.176 | F16: =IFERROR(IF(VLOOKUP($A16,'Annex 2 EHV charges'!$A:$O,9,FALSE)=0,"",VLOOKUP($A16,'Annex 2 EHV charges'!$A:$O,9,FALSE)),"") -> 627.76 | G16: =IFERROR(IF(VLOOKUP($A16,'Annex 2 EHV charges'!$A:$O,10,FALSE)=0,"",VLOOKUP($A16,'Annex 2 EHV charges'!$A:$O,10,FALSE)),"") -> 2.4 | H16: =IFERROR(IF(VLOOKUP($A16,'Annex 2 EHV charges'!$A:$O,11,FALSE)=0,"",VLOOKUP($A16,'Annex 2 EHV charges'!$A:$O,11,FALSE)),"") -> 2.4
... A254: {=IFERROR(INDEX('Annex 2 EHV charges'!$A$10:$A$259, MATCH(0, IF(ISBLANK('Annex 2 EHV charges'!$A$10:$A$259),1, COUNTIF(A$4:$A253, 'Annex 2 EHV charges'!$A$10:$A$259)), 0)),"")} | B254: =IF($A254="","",VLOOKUP($A254,'Annex 2 EHV charges'!$A:$O,2,0)) | C254: =IF($A254="","",VLOOKUP($A254,'Annex 2 EHV charges'!$A:$O,3,0)) | D254: =IF($A254="","",VLOOKUP($A254,'Annex 2 EHV charges'!$A:$O,7,0)) | E254: =IFERROR(IF(VLOOKUP($A254,'Annex 2 EHV charges'!$A:$O,8,FALSE)=0,"",VLOOKUP($A254,'Annex 2 EHV charges'!$A:$O,8,FALSE)),"") | F254: =IFERROR(IF(VLOOKUP($A254,'Annex 2 EHV charges'!$A:$O,9,FALSE)=0,"",VLOOKUP($A254,'Annex 2 EHV charges'!$A:$O,9,FALSE)),"") | G254: =IFERROR(IF(VLOOKUP($A254,'Annex 2 EHV charges'!$A:$O,10,FALSE)=0,"",VLOOKUP($A254,'Annex 2 EHV charges'!$A:$O,10,FALSE)),"") | H254: =IFERROR(IF(VLOOKUP($A254,'Annex 2 EHV charges'!$A:$O,11,FALSE)=0,"",VLOOKUP($A254,'Annex 2 EHV charges'!$A:$O,11,FALSE)),"")

Sheet Annex 2b Export
A1: Note: The list of MPANs / MSIDs provided may be incomplete; the DNO reserves the right to apply the listed charges to any other MPANs / MSIDs associated with the site. Note: This table is automatically populated based on the content of the tab entitled 'Annex 2 EHV Charges'. The timebands are as shown in Annex 2.
A2: =Overview!B4& " - Effective from "&Overview!D4&" - "&Overview!E4&" EDCM export charges" -> South Eastern Power Networks - Effective from 1 April 2021 - Final EDCM export charges
A4: Export Unique Identifier | B4: LLFC | C4: Export MPANs/MSIDs | D4: Name | E4: ='Annex 2 EHV charges'!L9 -> Export Super Red unit charge (p/kWh) | F4: ='Annex 2 EHV charges'!M9 -> Export fixed charge (p/day) | G4: ='Annex 2 EHV charges'!N9 -> Export capacity charge (p/kVA/day) | H4: ='Annex 2 EHV charges'!O9 -> Export exceeded capacity charge (p/kVA/day)
A5: {=IFERROR(INDEX('Annex 2 EHV charges'!$D$10:$D$259, MATCH(0, IF(ISBLANK('Annex 2 EHV charges'!$D$10:$D$259),1, COUNTIF(A$4:$A4, 'Annex 2 EHV charges'!$D$10:$D$259)), 0)),"")} -> THAMEM | B5: =IF($A5="","",VLOOKUP($A5,'Annex 2 EHV charges'!$D:$O,2,0)) -> 691 | C5: =IF($A5="","",VLOOKUP($A5,'Annex 2 EHV charges'!$D:$O,3,0)) -> 1900090876979 1900090876988 | D5: =IF($A5="","",VLOOKUP($A5,'Annex 2 EHV charges'!$D:$O,4,0)) -> THAMEM | E5: =IFERROR(IF(VLOOKUP($A5,'Annex 2 EHV charges'!$D:$O,9,FALSE)=0,"",VLOOKUP($A5,'Annex 2 EHV charges'!$D:$O,9,FALSE)),"") | F5: =IFERROR(IF(VLOOKUP($A5,'Annex 2 EHV charges'!$D:$O,10,FALSE)=0,"",VLOOKUP($A5,'Annex 2 EHV charges'!$D:$O,10,FALSE)),"") -> 2879.64 | G5: =IFERROR(IF(VLOOKUP($A5,'Annex 2 EHV charges'!$D:$O,11,FALSE)=0,"",VLOOKUP($A5,'Annex 2 EHV charges'!$D:$O,11,FALSE)),"") -> 0.05 | H5: =IFERROR(IF(VLOOKUP($A5,'Annex 2 EHV charges'!$D:$O,12,FALSE)=0,"",VLOOKUP($A5,'Annex 2 EHV charges'!$D:$O,12,FALSE)),"") -> 0.05
A6: {=IFERROR(INDEX('Annex 2 EHV charges'!$D$10:$D$259, MATCH(0, IF(ISBLANK('Annex 2 EHV charges'!$D$10:$D$259),1, COUNTIF(A$4:$A5, 'Annex 2 EHV charges'!$D$10:$D$259)), 0)),"")} -> THAMES | B6: =IF($A6="","",VLOOKUP($A6,'Annex 2 EHV charges'!$D:$O,2,0)) -> 732 | C6: =IF($A6="","",VLOOKUP($A6,'Annex 2 EHV charges'!$D:$O,3,0)) -> 1900060576611 | D6: =IF($A6="","",VLOOKUP($A6,'Annex 2 EHV charges'!$D:$O,4,0)) -> THAMES | E6: =IFERROR(IF(VLOOKUP($A6,'Annex 2 EHV charges'!$D:$O,9,FALSE)=0,"",VLOOKUP($A6,'Annex 2 EHV charges'!$D:$O,9,FALSE)),"") | F6: =IFERROR(IF(VLOOKUP($A6,'Annex 2 EHV charges'!$D:$O,10,FALSE)=0,"",VLOOKUP($A6,'Annex 2 EHV charges'!$D:$O,10,FALSE)),"") -> 1726.31 | G6: =IFERROR(IF(VLOOKUP($A6,'Annex 2 EHV charges'!$D:$O,11,FALSE)=0,"",VLOOKUP($A6,'Annex 2 EHV charges'!$D:$O,11,FALSE)),"") -> 0.05 | H6: =IFERROR(IF(VLOOKUP($A6,'Annex 2 EHV charges'!$D:$O,12,FALSE)=0,"",VLOOKUP($A6,'Annex 2 EHV charges'!$D:$O,12,FALSE)),"") -> 0.05
A7: {=IFERROR(INDEX('Annex 2 EHV charges'!$D$10:$D$259, MATCH(0, IF(ISBLANK('Annex 2 EHV charges'!$D$10:$D$259),1, COUNTIF(A$4:$A6, 'Annex 2 EHV charges'!$D$10:$D$259)), 0)),"")} -> TWHK66 | B7: =IF($A7="","",VLOOKUP($A7,'Annex 2 EHV charges'!$D:$O,2,0)) -> 692 | C7: =IF($A7="","",VLOOKUP($A7,'Annex 2 EHV charges'!$D:$O,3,0)) -> 1900091206194 | D7: =IF($A7="","",VLOOKUP($A7,'Annex 2 EHV charges'!$D:$O,4,0)) -> TWHK66 | E7: =IFERROR(IF(VLOOKUP($A7,'Annex 2 EHV charges'!$D:$O,9,FALSE)=0,"",VLOOKUP($A7,'Annex 2 EHV charges'!$D:$O,9,FALSE)),"") -> -2.957 | F7: =IFERROR(IF(VLOOKUP($A7,'Annex 2 EHV charges'!$D:$O,10,FALSE)=0,"",VLOOKUP($A7,'Annex 2 EHV charges'!$D:$O,10,FALSE)),"") -> 30.18 | G7: =IFERROR(IF(VLOOKUP($A7,'Annex 2 EHV charges'!$D:$O,11,FALSE)=0,"",VLOOKUP($A7,'Annex 2 EHV charges'!$D:$O,11,FALSE)),"") -> 0.05 | H7: =IFERROR(IF(VLOOKUP($A7,'Annex 2 EHV charges'!$D:$O,12,FALSE)=0,"",VLOOKUP($A7,'Annex 2 EHV charges'!$D:$O,12,FALSE)),"") -> 0.05
A8: {=IFERROR(INDEX('Annex 2 EHV charges'!$D$10:$D$259, MATCH(0, IF(ISBLANK('Annex 2 EHV charges'!$D$10:$D$259),1, COUNTIF(A$4:$A7, 'Annex 2 EHV charges'!$D$10:$D$259)), 0)),"")} -> ASHBYS | B8: =IF($A8="","",VLOOKUP($A8,'Annex 2 EHV charges'!$D:$O,2,0)) -> 741 | C8: =IF($A8="","",VLOOKUP($A8,'Annex 2 EHV charges'!$D:$O,3,0)) -> 1900091216972 | D8: =IF($A8="","",VLOOKUP($A8,'Annex 2 EHV charges'!$D:$O,4,0)) -> ASHBYS | E8: =IFERROR(IF(VLOOKUP($A8,'Annex 2 EHV charges'!$D:$O,9,FALSE)=0,"",VLOOKUP($A8,'Annex 2 EHV charges'!$D:$O,9,FALSE)),"") | F8: =IFERROR(IF(VLOOKUP($A8,'Annex 2 EHV charges'!$D:$O,10,FALSE)=0,"",VLOOKUP($A8,'Annex 2 EHV charges'!$D:$O,10,FALSE)),"") -> 982.39 | G8: =IFERROR(IF(VLOOKUP($A8,'Annex 2 EHV charges'!$D:$O,11,FALSE)=0,"",VLOOKUP($A8,'Annex 2 EHV charges'!$D:$O,11,FALSE)),"") -> 0.05 | H8: =IFERROR(IF(VLOOKUP($A8,'Annex 2 EHV charges'!$D:$O,12,FALSE)=0,"",VLOOKUP($A8,'Annex 2 EHV charges'!$D:$O,12,FALSE)),"") -> 0.05
A9: {=IFERROR(INDEX('Annex 2 EHV charges'!$D$10:$D$259, MATCH(0, IF(ISBLANK('Annex 2 EHV charges'!$D$10:$D$259),1, COUNTIF(A$4:$A8, 'Annex 2 EHV charges'!$D$10:$D$259)), 0)),"")} -> ASHGEN | B9: =IF($A9="","",VLOOKUP($A9,'Annex 2 EHV charges'!$D:$O,2,0)) -> 734 | C9: =IF($A9="","",VLOOKUP($A9,'Annex 2 EHV charges'!$D:$O,3,0)) -> 1900090978875 | D9: =IF($A9="","",VLOOKUP($A9,'Annex 2 EHV charges'!$D:$O,4,0)) -> ASHGEN | E9: =IFERROR(IF(VLOOKUP($A9,'Annex 2 EHV charges'!$D:$O,9,FALSE)=0,"",VLOOKUP($A9,'Annex 2 EHV charges'!$D:$O,9,FALSE)),"") | F9: =IFERROR(IF(VLOOKUP($A9,'Annex 2 EHV charges'!$D:$O,10,FALSE)=0,"",VLOOKUP($A9,'Annex 2 EHV charges'!$D:$O,10,FALSE)),"") -> 2756.96 | G9: =IFERROR(IF(VLOOKUP($A9,'Annex 2 EHV charges'!$D:$O,11,FALSE)=0,"",VLOOKUP($A9,'Annex 2 EHV charges'!$D:$O,11,FALSE)),"") -> 0.05 | H9: =IFERROR(IF(VLOOKUP($A9,'Annex 2 EHV charges'!$D:$O,12,FALSE)=0,"",VLOOKUP($A9,'Annex 2 EHV charges'!$D:$O,12,FALSE)),"") -> 0.05
A10: {=IFERROR(INDEX('Annex 2 EHV charges'!$D$10:$D$259, MATCH(0, IF(ISBLANK('Annex 2 EHV charges'!$D$10:$D$259),1, COUNTIF(A$4:$A9, 'Annex 2 EHV charges'!$D$10:$D$259)), 0)),"")} -> AYLESF | B10: =IF($A10="","",VLOOKUP($A10,'Annex 2 EHV charges'!$D:$O,2,0)) -> 725 | C10: =IF($A10="","",VLOOKUP($A10,'Annex 2 EHV charges'!$D:$O,3,0)) -> 1900060436880 | D10: =IF($A10="","",VLOOKUP($A10,'Annex 2 EHV charges'!$D:$O,4,0)) -> AYLESF | E10: =IFERROR(IF(VLOOKUP($A10,'Annex 2 EHV charges'!$D:$O,9,FALSE)=0,"",VLOOKUP($A10,'Annex 2 EHV charges'!$D:$O,9,FALSE)),"") | F10: =IFERROR(IF(VLOOKUP($A10,'Annex 2 EHV charges'!$D:$O,10,FALSE)=0,"",VLOOKUP($A10,'Annex 2 EHV charges'!$D:$O,10,FALSE)),"") | G10: =IFERROR(IF(VLOOKUP($A10,'Annex 2 EHV charges'!$D:$O,11,FALSE)=0,"",VLOOKUP($A10,'Annex 2 EHV charges'!$D:$O,11,FALSE)),"") | H10: =IFERROR(IF(VLOOKUP($A10,'Annex 2 EHV charges'!$D:$O,12,FALSE)=0,"",VLOOKUP($A10,'Annex 2 EHV charges'!$D:$O,12,FALSE)),"")
A11: {=IFERROR(INDEX('Annex 2 EHV charges'!$D$10:$D$259, MATCH(0, IF(ISBLANK('Annex 2 EHV charges'!$D$10:$D$259),1, COUNTIF(A$4:$A10, 'Annex 2 EHV charges'!$D$10:$D$259)), 0)),"")} -> BEDERF | B11: =IF($A11="","",VLOOKUP($A11,'Annex 2 EHV charges'!$D:$O,2,0)) -> 693 | C11: =IF($A11="","",VLOOKUP($A11,'Annex 2 EHV charges'!$D:$O,3,0)) -> 1900091482597 | D11: =IF($A11="","",VLOOKUP($A11,'Annex 2 EHV charges'!$D:$O,4,0)) -> BEDERF | E11: =IFERROR(IF(VLOOKUP($A11,'Annex 2 EHV charges'!$D:$O,9,FALSE)=0,"",VLOOKUP($A11,'Annex 2 EHV charges'!$D:$O,9,FALSE)),"") -> -0.175 | F11: =IFERROR(IF(VLOOKUP($A11,'Annex 2 EHV charges'!$D:$O,10,FALSE)=0,"",VLOOKUP($A11,'Annex 2 EHV charges'!$D:$O,10,FALSE)),"") -> 2408.15 | G11: =IFERROR(IF(VLOOKUP($A11,'Annex 2 EHV charges'!$D:$O,11,FALSE)=0,"",VLOOKUP($A11,'Annex 2 EHV charges'!$D:$O,11,FALSE)),"") -> 0.05 | H11: =IFERROR(IF(VLOOKUP($A11,'Annex 2 EHV charges'!$D:$O,12,FALSE)=0,"",VLOOKUP($A11,'Annex 2 EHV charges'!$D:$O,12,FALSE)),"") -> 0.05
A12: {=IFERROR(INDEX('Annex 2 EHV charges'!$D$10:$D$259, MATCH(0, IF(ISBLANK('Annex 2 EHV charges'!$D$10:$D$259),1, COUNTIF(A$4:$A11, 'Annex 2 EHV charges'!$D$10:$D$259)), 0)),"")} -> BESAYL | B12: =IF($A12="","",VLOOKUP($A12,'Annex 2 EHV charges'!$D:$O,2,0)) -> 694 | C12: =IF($A12="","",VLOOKUP($A12,'Annex 2 EHV charges'!$D:$O,3,0)) -> 1900091632784 | D12: =IF($A12="","",VLOOKUP($A12,'Annex 2 EHV charges'!$D:$O,4,0)) -> BESAYL | E12: =IFERROR(IF(VLOOKUP($A12,'Annex 2 EHV charges'!$D:$O,9,FALSE)=0,"",VLOOKUP($A12,'Annex 2 EHV charges'!$D:$O,9,FALSE)),"") -> -0.209 | F12: =IFERROR(IF(VLOOKUP($A12,'Annex 2 EHV charges'!$D:$O,10,FALSE)=0,"",VLOOKUP($A12,'Annex 2 EHV charges'!$D:$O,10,FALSE)),"") -> 345.61 | G12: =IFERROR(IF(VLOOKUP($A12,'Annex 2 EHV charges'!$D:$O,11,FALSE)=0,"",VLOOKUP($A12,'Annex 2 EHV charges'!$D:$O,11,FALSE)),"") -> 0.05 | H12: =IFERROR(IF(VLOOKUP($A12,'Annex 2 EHV charges'!$D:$O,12,FALSE)=0,"",VLOOKUP($A12,'Annex 2 EHV charges'!$D:$O,12,FALSE)),"") -> 0.05
A13: {=IFERROR(INDEX('Annex 2 EHV charges'!$D$10:$D$259, MATCH(0, IF(ISBLANK('Annex 2 EHV charges'!$D$10:$D$259),1, COUNTIF(A$4:$A12, 'Annex 2 EHV charges'!$D$10:$D$259)), 0)),"")} -> BNTLEY | B13: =IF($A13="","",VLOOKUP($A13,'Annex 2 EHV charges'!$D:$O,2,0)) -> 713 | C13: =IF($A13="","",VLOOKUP($A13,'Annex 2 EHV charges'!$D:$O,3,0)) -> 1900091343787 | D13: =IF($A13="","",VLOOKUP($A13,'Annex 2 EHV charges'!$D:$O,4,0)) -> BNTLEY | E13: =IFERROR(IF(VLOOKUP($A13,'Annex 2 EHV charges'!$D:$O,9,FALSE)=0,"",VLOOKUP($A13,'Annex 2 EHV charges'!$D:$O,9,FALSE)),"") | F13: =IFERROR(IF(VLOOKUP($A13,'Annex 2 EHV charges'!$D:$O,10,FALSE)=0,"",VLOOKUP($A13,'Annex 2 EHV charges'!$D:$O,10,FALSE)),"") -> 866.59 | G13: =IFERROR(IF(VLOOKUP($A13,'Annex 2 EHV charges'!$D:$O,11,FALSE)=0,"",VLOOKUP($A13,'Annex 2 EHV charges'!$D:$O,11,FALSE)),"") -> 0.05 | H13: =IFERROR(IF(VLOOKUP($A13,'Annex 2 EHV charges'!$D:$O,12,FALSE)=0,"",VLOOKUP($A13,'Annex 2 EHV charges'!$D:$O,12,FALSE)),"") -> 0.05
A14: {=IFERROR(INDEX('Annex 2 EHV charges'!$D$10:$D$259, MATCH(0, IF(ISBLANK('Annex 2 EHV charges'!$D$10:$D$259),1, COUNTIF(A$4:$A13, 'Annex 2 EHV charges'!$D$10:$D$259)), 0)),"")} -> BNTLY2 | B14: =IF($A14="","",VLOOKUP($A14,'Annex 2 EHV charges'!$D:$O,2,0)) -> 712 | C14: =IF($A14="","",VLOOKUP($A14,'Annex 2 EHV charges'!$D:$O,3,0)) -> 1900091463655 | D14: =IF($A14="","",VLOOKUP($A14,'Annex 2 EHV charges'!$D:$O,4,0)) -> BNTLY2 | E14: =IFERROR(IF(VLOOKUP($A14,'Annex 2 EHV charges'!$D:$O,9,FALSE)=0,"",VLOOKUP($A14,'Annex 2 EHV charges'!$D:$O,9,FALSE)),"") | F14: =IFERROR(IF(VLOOKUP($A14,'Annex 2 EHV charges'!$D:$O,10,FALSE)=0,"",VLOOKUP($A14,'Annex 2 EHV charges'!$D:$O,10,FALSE)),"") -> 554.77 | G14: =IFERROR(IF(VLOOKUP($A14,'Annex 2 EHV charges'!$D:$O,11,FALSE)=0,"",VLOOKUP($A14,'Annex 2 EHV charges'!$D:$O,11,FALSE)),"") -> 0.05 | H14: =IFERROR(IF(VLOOKUP($A14,'Annex 2 EHV charges'!$D:$O,12,FALSE)=0,"",VLOOKUP($A14,'Annex 2 EHV charges'!$D:$O,12,FALSE)),"") -> 0.05
A15: {=IFERROR(INDEX('Annex 2 EHV charges'!$D$10:$D$259, MATCH(0, IF(ISBLANK('Annex 2 EHV charges'!$D$10:$D$259),1, COUNTIF(A$4:$A14, 'Annex 2 EHV charges'!$D$10:$D$259)), 0)),"")} -> BOBBNG | B15: =IF($A15="","",VLOOKUP($A15,'Annex 2 EHV charges'!$D:$O,2,0)) -> 705 | C15: =IF($A15="","",VLOOKUP($A15,'Annex 2 EHV charges'!$D:$O,3,0)) -> 1900091395517 | D15: =IF($A15="","",VLOOKUP($A15,'Annex 2 EHV charges'!$D:$O,4,0)) -> BOBBNG | E15: =IFERROR(IF(VLOOKUP($A15,'Annex 2 EHV charges'!$D:$O,9,FALSE)=0,"",VLOOKUP($A15,'Annex 2 EHV charges'!$D:$O,9,FALSE)),"") | F15: =IFERROR(IF(VLOOKUP($A15,'Annex 2 EHV charges'!$D:$O,10,FALSE)=0,"",VLOOKUP($A15,'Annex 2 EHV charges'!$D:$O,10,FALSE)),"") -> 940.36 | G15: =IFERROR(IF(VLOOKUP($A15,'Annex 2 EHV charges'!$D:$O,11,FALSE)=0,"",VLOOKUP($A15,'Annex 2 EHV charges'!$D:$O,11,FALSE)),"") -> 0.05 | H15: =IFERROR(IF(VLOOKUP($A15,'Annex 2 EHV charges'!$D:$O,12,FALSE)=0,"",VLOOKUP($A15,'Annex 2 EHV charges'!$D:$O,12,FALSE)),"") -> 0.05
A16: {=IFERROR(INDEX('Annex 2 EHV charges'!$D$10:$D$259, MATCH(0, IF(ISBLANK('Annex 2 EHV charges'!$D$10:$D$259),1, COUNTIF(A$4:$A15, 'Annex 2 EHV charges'!$D$10:$D$259)), 0)),"")} -> BRAMBS | B16: =IF($A16="","",VLOOKUP($A16,'Annex 2 EHV charges'!$D:$O,2,0)) -> 695 | C16: =IF($A16="","",VLOOKUP($A16,'Annex 2 EHV charges'!$D:$O,3,0)) -> 1900091566820 | D16: =IF($A16="","",VLOOKUP($A16,'Annex 2 EHV charges'!$D:$O,4,0)) -> BRAMBS | E16: =IFERROR(IF(VLOOKUP($A16,'Annex 2 EHV charges'!$D:$O,9,FALSE)=0,"",VLOOKUP($A16,'Annex 2 EHV charges'!$D:$O,9,FALSE)),"") -> -0.085 | F16: =IFERROR(IF(VLOOKUP($A16,'Annex 2 EHV charges'!$D:$O,10,FALSE)=0,"",VLOOKUP($A16,'Annex 2 EHV charges'!$D:$O,10,FALSE)),"") -> 345.61 | G16: =IFERROR(IF(VLOOKUP($A16,'Annex 2 EHV charges'!$D:$O,11,FALSE)=0,"",VLOOKUP($A16,'Annex 2 EHV charges'!$D:$O,11,FALSE)),"") -> 0.05 | H16: =IFERROR(IF(VLOOKUP($A16,'Annex 2 EHV charges'!$D:$O,12,FALSE)=0,"",VLOOKUP($A16,'Annex 2 EHV charges'!$D:$O,12,FALSE)),"") -> 0.05
... A254: {=IFERROR(INDEX('Annex 2 EHV charges'!$D$10:$D$259, MATCH(0, IF(ISBLANK('Annex 2 EHV charges'!$D$10:$D$259),1, COUNTIF(A$4:$A253, 'Annex 2 EHV charges'!$D$10:$D$259)), 0)),"")} | B254: =IF($A254="","",VLOOKUP($A254,'Annex 2 EHV charges'!$D:$O,2,0)) | C254: =IF($A254="","",VLOOKUP($A254,'Annex 2 EHV charges'!$D:$O,3,0)) | D254: =IF($A254="","",VLOOKUP($A254,'Annex 2 EHV charges'!$D:$O,4,0)) | E254: =IFERROR(IF(VLOOKUP($A254,'Annex 2 EHV charges'!$D:$O,9,FALSE)=0,"",VLOOKUP($A254,'Annex 2 EHV charges'!$D:$O,9,FALSE)),"") | F254: =IFERROR(IF(VLOOKUP($A254,'Annex 2 EHV charges'!$D:$O,10,FALSE)=0,"",VLOOKUP($A254,'Annex 2 EHV charges'!$D:$O,10,FALSE)),"") | G254: =IFERROR(IF(VLOOKUP($A254,'Annex 2 EHV charges'!$D:$O,11,FALSE)=0,"",VLOOKUP($A254,'Annex 2 EHV charges'!$D:$O,11,FALSE)),"") | H254: =IFERROR(IF(VLOOKUP($A254,'Annex 2 EHV charges'!$D:$O,12,FALSE)=0,"",VLOOKUP($A254,'Annex 2 EHV charges'!$D:$O,12,FALSE)),"")

Sheet Annex 3 Preserved charges
A1: Back to Overview
A2: =Overview!B4& " - Effective from "&Overview!D4&" - "&Overview!E4&" LV and HV tariffs" -> South Eastern Power Networks - Effective from 1 April 2021 - Final LV and HV tariffs
A3: Supercustomer preserved charges/additional LLFCs
B4: Closed LLFCs | C4: PCs | D4: Red/black unit charge p/kWh | E4: Amber/yellow unit charge p/kWh | F4: Green unit charge p/kWh | G4: Fixed charge p/MPAN/day
A6: Notes: | B6: South Eastern Power Networks has no Preserved NHH Tariffs/Additional LLFC classes
A11: Site Specific preserved charges/additional LLFCs
B12: Closed LLFCs | C12: PCs | D12: Red/black unit charge p/kWh | E12: Amber/yellow unit charge p/kWh | F12: Green unit charge p/kWh | G12: Fixed charge p/MPAN/day | H12: Capacity charge p/kVA/day | I12: Exceeded capacity charge p/kVA/day | J12: Reactive power charge p/kVArh
C13: 0
A14: Notes: | B14: South Eastern Power Networks has no Preserved HH Tariffs/Additional LLFC classes

Sheet Annex 4 LDNO charges
A1: Back to Overview | B1: Copy from CDCM table 3701 "Tariffs!A42:I84" and paste values into A14 | F1: Copy from EDCM table 6005 "LDNORev!B549:G683" and paste values into D57
A2: =Overview!B4& " - Effective from "&Overview!D4&" - "&Overview!E4&" LDNO tariffs" -> South Eastern Power Networks - Effective from 1 April 2021 - Final LDNO tariffs
A4: Time Bands for LV and HV Designated Properties | F4: Time Bands for Unmetered Properties
A5: Time periods | B5: Red Time Band | C5: Amber Time Band | D5: Green Time Band | H5: Black Time Band | I5: Yellow Time Band | J5: Green Time Band
A6: Monday to Friday (Including Bank Holidays) All Year | B6: 16:00 - 19:00 | C6: 07:00 - 16:00 19:00 - 23:00 | D6: 00:00 - 07:00 23:00 - 24:00 | F6: Monday to Friday (Including Bank Holidays) November to February Inclusive | H6: 16:00 - 19:00 | I6: 07:00 - 16:00 19:00 - 23:00 | J6: 00:00 - 07:00 23:00 - 24:00
A7: Saturday and Sunday All Year | D7: 00:00 - 24:00 | F7: Monday to Friday (Including Bank Holidays) March to October Inclusive | I7: 07:00 - 23:00 | J7: 00:00 - 07:00 23:00 - 24:00
A8: Notes | B8: All times are in UK Clock time | F8: Saturday and Sunday All Year | J8: 00:00 - 24:00
F9: Notes | H9: All times are in UK Clock time
A11: Tariff name | B11: Unique billing identifier | C11: PCs | D11: Red/black unit charge p/kWh | E11: Amber/yellow unit charge p/kWh | F11: Green unit charge p/kWh | G11: Fixed charge p/MPAN/day | H11: Capacity charge p/kVA/day | I11: Exceeded capacity charge p/kVA/day | J11: Reactive power charge p/kVArh
A12: LDNO LV: Domestic Aggregated | B12: A00 | C12: 1, 2 or 0 | D12: 11.484 | E12: 0.822 | F12: 0.453 | G12: 2.78
A13: LDNO LV: Domestic Aggregated (related MPAN) | B13: B00 | C13: 2 | D13: 11.484 | E13: 0.822 | F13: 0.453
A14: LDNO LV: Non-Domestic Aggregated | B14: C00, C01, C02, C03, C04 | C14: 3-8 or 0 | D14: 8.991 | E14: 0.723 | F14: 0.437 | G14: 2.88
A15: LDNO LV: Non-Domestic Aggregated (related MPAN) | B15: D00 | C15: 4 | D15: 8.991 | E15: 0.723 | F15: 0.437
A16: LDNO LV: LV Site Specific | B16: E01, E02, E03, E04 | C16: 0 | D16: 6.19 | E16: 0.6 | F16: 0.415 | G16: 7.76 | H16: 2.5 | I16: 4.85 | J16: 0.188
A17: LDNO LV: LV Site Specific Storage Import | B17: E00 | C17: 0 | D17: 5.809 | E17: 0.219 | F17: 0.034 | G17: 7.76 | H17: 2.5 | I17: 4.85 | J17: 0.188
A18: LDNO LV: Unmetered Supplies | B18: U00 | C18: 1, 8 or 0 | D18: 27.443 | E18: 1.218 | F18: 0.896
A19: LDNO LV: LV Generation Aggregated | B19: F00 | C19: 8 or 0 | D19: -9.262 | E19: -0.368 | F19: -0.06 | G19: 0
A20: LDNO LV: LV Generation Site Specific | B20: G00 | C20: 0 | D20: -9.262 | E20: -0.368 | F20: -0.06 | G20: 0 | J20: 0.267
A21: LDNO HV: Domestic Aggregated | B21: A10 | C21: 1, 2 or 0 | D21: 8.715 | E21: 0.624 | F21: 0.344 | G21: 2.16
A22: LDNO HV: Domestic Aggregated (related MPAN) | B22: B10 | C22: 2 | D22: 8.715 | E22: 0.624 | F22: 0.344
A23: LDNO HV: Non-Domestic Aggregated | B23: C10, C11, C12, C13, C14 | C23: 3-8 or 0 | D23: 6.823 | E23: 0.549 | F23: 0.331 | G23: 2.23
A24: LDNO HV: Non-Domestic Aggregated (related MPAN) | B24: D10 | C24: 4 | D24: 6.823 | E24: 0.549 | F24: 0.331
A25: LDNO HV: LV Site Specific | B25: E11, E12, E13, E14 | C25: 0 | D25: 4.697 | E25: 0.455 | F25: 0.315 | G25: 5.94 | H25: 1.9 | I25: 3.68 | J25: 0.143
A26: LDNO HV: LV Sub Site Specific | B26: J11, J12, J13, J14 | C26: 0 | D26: 4.531 | E26: 0.57 | F26: 0.453 | G26: 6.54 | H26: 4.41 | I26: 5.76 | J26: 0.125
A27: LDNO HV: HV Site Specific | B27: K11, K12, K13, K14 | C27: 0 | D27: 4.732 | E27: 0.616 | F27: 0.502 | G27: 96.14 | H27: 3.69 | I27: 5.73 | J27: 0.131
A28: LDNO HV: LV Site Specific Storage Import | B28: E10 | C28: 0 | D28: 4.408 | E28: 0.166 | F28: 0.026 | G28: 5.94 | H28: 1.9 | I28: 3.68 | J28: 0.143
A29: LDNO HV: LV Sub Site Specific Storage Import | B29: J10 | C29: 0 | D29: 4.098 | E29: 0.136 | F29: 0.02 | G29: 6.54 | H29: 4.41 | I29: 5.76 | J29: 0.125
A30: LDNO HV: HV Site Specific Storage Import | B30: K10 | C30: 0 | D30: 4.248 | E30: 0.132 | F30: 0.018 | G30: 96.14 | H30: 3.69 | I30: 5.73 | J30: 0.131
A31: LDNO HV: Unmetered Supplies | B31: U10 | C31: 1, 8 or 0 | D31: 20.826 | E31: 0.924 | F31: 0.68
A32: LDNO HV: LV Generation Aggregated | B32: F10 | C32: 8 or 0 | D32: -9.262 | E32: -0.368 | F32: -0.06 | G32: 0
A33: LDNO HV: LV Sub Generation Aggregated | B33: H10 | C33: 0 | D33: -8.273 | E33: -0.318 | F33: -0.051 | G33: 0
A34: LDNO HV: LV Generation Site Specific | B34: G10 | C34: 0 | D34: -9.262 | E34: -0.368 | F34: -0.06 | G34: 0 | J34: 0.267
A35: LDNO HV: LV Sub Generation Site Specific | B35: L10 | C35: 0 | D35: -8.273 | E35: -0.318 | F35: -0.051 | G35: 0 | J35: 0.243
A36: LDNO HV: HV Generation Site Specific | B36: M10 | C36: 0 | D36: -5.769 | E36: -0.189 | F36: -0.027 | G36: 0 | J36: 0.196
A37: LDNO HVplus: Domestic Aggregated | B37: A20 | C37: 1, 2 or 0 | D37: 6.392 | E37: 0.458 | F37: 0.252 | G37: 1.63
A38: LDNO HVplus: Domestic Aggregated (related MPAN) | B38: B20 | C38: 2 | D38: 6.392 | E38: 0.458 | F38: 0.252
A39: LDNO HVplus: Non-Domestic Aggregated | B39: C20, C21, C22, C23, C24 | C39: 3-8 or 0 | D39: 5.004 | E39: 0.403 | F39: 0.243 | G39: 1.69
A40: LDNO HVplus: Non-Domestic Aggregated (related MPAN) | B40: D20 | C40: 4 | D40: 5.004 | E40: 0.403 | F40: 0.243
A41: LDNO HVplus: LV Site Specific | B41: E21, E22, E23, E24 | C41: 0 | D41: 3.445 | E41: 0.334 | F41: 0.231 | G41: 4.41 | H41: 1.39 | I41: 2.7 | J41: 0.105
A42: LDNO HVplus: LV Sub Site Specific | B42: J21, J22, J23, J24 | C42: 0 | D42: 3.288 | E42: 0.413 | F42: 0.329 | G42: 4.8 | H42: 3.2 | I42: 4.18 | J42: 0.091
...

Sheet Annex 5 LLFs
A1: Back to Overview
A2: These line loss factors are illustrative based on the latest calculated values and are published in good faith. However, the line loss factors that are approved by the BSC Panel for the applicable year and consequently published on the Elexon website will take precedence and will be used in Settlement if they differ from these values.
A3: =Overview!B4& " - Illustrative LLFs for year beginning "&Overview!D4 -> South Eastern Power Networks - Illustrative LLFs for year beginning 1 April 2021
A4: Time periods | C4: Period 1 | D4: Period 2 | E4: Period 3 | F4: Period 4 | G4: Period 5
C5: Winter Peak | D5: Summer Peak | E5: Winter Shoulder | F5: Night | G5: Other
A6: Monday to Friday November to February | C6: 16:00 - 19:59 | E6: 07:00 - 15:59
A7: Monday to Friday June to August | D7: 07:00 - 19:59
A8: Monday to Friday March | E8: 07:00 - 19:59
A9: All Year | F9: 00:00 - 06:59 | G9: All Other Times
A10: Notes | C10: All times are in UK Clock time
A12: Generic demand and generation LLFs
A13: Metered voltage, respective periods and associated LLFCs
A14: Metered voltage | B14: Period 1 | C14: Period 2 | D14: Period 3 | E14: Period 4 | F14: Period 5 | G14: Associated LLFC
A15: Low-voltage network | B15: 1.098 | C15: 1.074 | D15: 1.087 | E15: 1.067 | F15: 1.078 | G15: 1, 2, 19, 69, 71, 72, 73, 74, 100, 120, 199, 200, 201, 202, 203, 204, 251, 287, 300, 320, 350, 351, 352, 353, 354, 355, 356, 357, 358, 359, 360, 361, 362, 363, 364, 365, 366, 480, 550, 921, 932, 935, 980, 981, 982, 983
A16: Low-voltage substation | B16: 1.073 | C16: 1.057 | D16: 1.066 | E16: 1.052 | F16: 1.059 | G16: 79, 81, 82, 83, 84, 756, 781, 782, 984, 985, 986, 987
A17: High-voltage network | B17: 1.057 | C17: 1.042 | D17: 1.051 | E17: 1.036 | F17: 1.044 | G17: 89, 91, 92, 93, 94, 650, 926, 937, 988, 989, 990, 991
A18: High-voltage substation | B18: 1.059 | C18: 1.043 | D18: 1.052 | E18: 1.037 | F18: 1.045 | G18: 771, 791, 792
A19: 33kV generic | B19: 1.019 | C19: 1.015 | D19: 1.017 | E19: 1.014 | F19: 1.016 | G19: 796, 797
A20: 132kV generic | B20: 1.006 | C20: 1.005 | D20: 1.006 | E20: 1.004 | F20: 1.005 | G20: 798, 799
A22: EHV site specific LLFs
A23: Demand
A24: Site | B24: Period 1 | C24: Period 2 | D24: Period 3 | E24: Period 4 | F24: Period 5 | G24: Associated LLFC
A25: NEWHVN - Import | B25: 1.035 | C25: 1.05 | D25: 1.049 | E25: 1.046 | F25: 1.048 | G25: 800
A26: ASHGEN - Import | B26: 0.991 | C26: 0.996 | D26: 0.996 | E26: 0.996 | F26: 0.997 | G26: 801
A27: BRKHST - Import | B27: 1.042 | C27: 1.034 | D27: 1.048 | E27: 1.023 | F27: 1.037 | G27: 802
A28: KNWLTN - Import | B28: 1.019 | C28: 1.015 | D28: 1.017 | E28: 1.014 | F28: 1.016 | G28: 803
A29: DSCPRK - Import | B29: 1.007 | C29: 1.012 | D29: 1.007 | E29: 1.01 | F29: 1.01 | G29: 804
A30: OLDRSF - Import | B30: 1.019 | C30: 1.015 | D30: 1.017 | E30: 1.014 | F30: 1.016 | G30: 805
A31: WSTWDX - Import | B31: 1.019 | C31: 1.015 | D31: 1.017 | E31: 1.014 | F31: 1.016 | G31: 806
A32: SYCAMR - Import | B32: 1.019 | C32: 1.015 | D32: 1.017 | E32: 1.014 | F32: 1.016 | G32: 807
A33: LENHAM - Import | B33: 1.019 | C33: 1.015 | D33: 1.017 | E33: 1.014 | F33: 1.016 | G33: 808
A34: ASHBYS - Import | B34: 1.035 | C34: 1.022 | D34: 1.031 | E34: 1.026 | F34: 1.029 | G34: 809
A35: BTBRKS - Import | B35: 1.009 | C35: 1.007 | D35: 1.008 | E35: 1.008 | F35: 1.008 | G35: 810
A36: FRWOOD - Import | B36: 1.019 | C36: 1.015 | D36: 1.017 | E36: 1.014 | F36: 1.016 | G36: 811
... A115: SELLSF - Import | B115: 1.006 | C115: 1.006 | D115: 1.006 | E115: 1.006 | F115: 1.006 | G115: 900
A117: EHV site specific LLFs
A118: Generation
A119: Site | B119: Period 1 | C119: Period 2 | D119: Period 3 | E119: Period 4 | F119: Period 5 | G119: Associated LLFC
A120: THAMEM - Export | B120: 1.059 | C120: 1.043 | D120: 1.052 | E120: 1.037 | F120: 1.045 | G120: 691
A121: TWHK66 - Export | B121: 1.059 | C121: 1.043 | D121: 1.052 | E121: 1.037 | F121: 1.045 | G121: 692
...

Sheet Annex 6 New or Amended EHV
A1: Back to Overview | H1: Note: The list of MPANs/MSIDs provided may be incomplete; the DNO reserves the right to apply the listed charges to any other MPANs/MSIDs associated with the site. If sites appear in both Annex 2 and Annex 6, the charges in Annex 6 take precedence. Where an existing Designated EHV Property is modified and energised in the charging year, we may revise the EDCM charges for the modified Designated EHV Property.
A2: Annex 6 - Charges for New or Amended Designated EHV Properties
A4: =Overview!B4& " - Effective from "&Overview!D4&" - "&Overview!E4&" new designated EHV charges" -> South Eastern Power Networks - Effective from 1 April 2021 - Final new designated EHV charges
A5: Effective from date | B5: Import Unique Identifier | C5: LLFC | D5: Import MPANs/MSIDs | E5: Export Unique Identifier | F5: LLFC | G5: Export MPANs/MSIDs | H5: Name | I5: ='Annex 2 EHV charges'!H9 -> Import Super Red unit charge (p/kWh) | J5: ='Annex 2 EHV charges'!I9 -> Import fixed charge (p/day) | K5: ='Annex 2 EHV charges'!J9 -> Import capacity charge (p/kVA/day) | L5: ='Annex 2 EHV charges'!K9 -> Import exceeded capacity charge (p/kVA/day) | M5: ='Annex 2 EHV charges'!L9 -> Export Super Red unit charge (p/kWh) | N5: ='Annex 2 EHV charges'!M9 -> Export fixed charge (p/day) | O5: ='Annex 2 EHV charges'!N9 -> Export capacity charge (p/kVA/day) | P5: ='Annex 2 EHV charges'!O9 -> Export exceeded capacity charge (p/kVA/day)
A6: 44287 | B6: ANMSTR | C6: 873 | D6: 1900091919588 | E6: ANMSTR | F6: 780 | G6: 1900091919597 | H6: ANMSTR | I6: 0.732 | J6: 35.87 | K6: 1.78 | L6: 1.78 | M6: -1.238 | N6: 956.47 | O6: 0.05 | P6: 0.05
A7: 44287 | B7: GLASSN | C7: 844 | D7: 1900091523301 | E7: GLASSN | F7: 697 | G7: 1900091523310 | H7: GLASSN | I7: 0 | J7: 384.06 | K7: 0.67 | L7: 0.67 | M7: 0 | N7: 384.06 | O7: 0.05 | P7: 0.05
A8: 44287 | B8: KNTSFM | D8: MSID: 7425 | E8: KNTSFM | G8: MSID: 7436 | H8: KNTSFM | I8: 2.872 | J8: 738.2 | K8: 1.05 | L8: 1.05 | M8: -2.884 | N8: 777.28 | O8: 0.05 | P8: 0.05
A9: 44378 | B9: KNTSFM | D9: MSID: 7425 | E9: KNTSFM | G9: MSID: 7436 | H9: KNTSFM | I9: 2.872 | J9: 737.74 | K9: 0.69 | L9: 0.69 | M9: -2.884 | N9: 776.79 | O9: 0.05 | P9: 0.05
A10: 44409 | B10: BESAYL | C10: 841 | D10: 1900091632775 | E10: BESAYL | F10: 694 | G10: 1900091632784 | H10: BESAYL | I10: 0.168 | J10: 345.23 | K10: 0.57 | L10: 0.57 | M10: -0.209 | N10: 345.23 | O10: 0.05 | P10: 0.05
A11: 44409 | B11: BRAMBS | C11: 842 | D11: 1900091566810 | E11: BRAMBS | F11: 695 | G11: 1900091566820 | H11: BRAMBS | I11: 0.075 | J11: 345.23 | K11: 0.83 | L11: 0.83 | M11: -0.085 | N11: 345.23 | O11: 0.05 | P11: 0.05
A17: =Overview!B4& " - Effective from "&Overview!D4&" - "&Overview!E4&" new designated EHV line loss factors" -> South Eastern Power Networks - Effective from 1 April 2021 - Final new designated EHV line loss factors
A18: Effective from date | B18: Import Unique Identifier | C18: LLFC | D18: Import MPANs/MSIDs | E18: Export Unique Identifier | F18: LLFC | G18: Export MPANs/MSIDs | H18: Name | I18: Import LLF period 1 | J18: Import LLF period 2 | K18: Import LLF period 3 | L18: Import LLF period 4 | M18: Import LLF period 5 | N18: Export LLF period 1 | O18: Export LLF period 2 | P18: Export LLF period 3 | Q18: Export LLF period 4 | R18: Export LLF period 5
A19: 44287 | B19: ANMSTR | C19: 873 | D19: 1900091919588 | E19: ANMSTR | F19: 780 | G19: 1900091919597 | H19: ANMSTR | I19: 1.019 | J19: 1.015 | K19: 1.017 | L19: 1.014 | M19: 1.016 | N19: 1.019 | O19: 1.015 | P19: 1.017 | Q19: 1.014 | R19: 1.016
A20: 44287 | B20: KNTSFM | C20: 907 | D20: 1900092045475 | E20: KNTSFM | F20: 768 | G20: 1900092045484 | H20: KNTSFM | I20: 1.019 | J20: 1.015 | K20: 1.017 | L20: 1.014 | M20: 1.016 | N20: 1.019 | O20: 1.015 | P20: 1.017 | Q20: 1.014 | R20: 1.016

Sheet Annex 7 Pass-Through Costs
A1: Back to Overview
A2: =Overview!B4& " - Effective from "&Overview!D4&" - "&Overview!E4&" Supplier of Last Resort and Eligible Bad Debt Pass-Through Costs" -> South Eastern Power Networks - Effective from 1 April 2021 - Final Supplier of Last Resort and Eligible Bad Debt Pass-Through Costs
A4: Tariff name | B4: Open LLFCs / LDNO unique billing identifier | C4: PCs | D4: Supplier of Last Resort Fixed charge adder* p/MPAN/day | E4: Excess Supplier of Last Resort Fixed charge adder** p/MPAN/day | F4: Eligible Bad Debt Fixed charge adder*** p/MPAN/day
A5: Domestic Aggregated | B5: =IFERROR(INDEX('Annex 1 LV, HV and UMS charges'!$B$12:$B$30,MATCH($A5,'Annex 1 LV, HV and UMS charges'!$A$12:$A$295,0)),INDEX('Annex 4 LDNO charges'!$B$12:$B$116,MATCH($A5,'Annex 4 LDNO charges'!$A$12:$A$116,0))) -> 1, 100, 300 | C5: =IFERROR(INDEX('Annex 1 LV, HV and UMS charges'!$C$12:$C$30,MATCH($A5,'Annex 1 LV, HV and UMS charges'!$A$12:$A$295,0)),INDEX('Annex 4 LDNO charges'!$C$12:$C$116,MATCH($A5,'Annex 4 LDNO charges'!$A$12:$A$116,0))) -> 1, 2 or 0 | D5: 0.0079313589 | F5: 0.18871621
A6: Non-Domestic Aggregated | B6: =IFERROR(INDEX('Annex 1 LV, HV and UMS charges'!$B$12:$B$30,MATCH($A6,'Annex 1 LV, HV and UMS charges'!$A$12:$A$295,0)),INDEX('Annex 4 LDNO charges'!$B$12:$B$116,MATCH($A6,'Annex 4 LDNO charges'!$A$12:$A$116,0))) -> 120, 200, 201, 202, 203, 204, 320, 480 | C6: =IFERROR(INDEX('Annex 1 LV, HV and UMS charges'!$C$12:$C$30,MATCH($A6,'Annex 1 LV, HV and UMS charges'!$A$12:$A$295,0)),INDEX('Annex 4 LDNO charges'!$C$12:$C$116,MATCH($A6,'Annex 4 LDNO charges'!$A$12:$A$116,0))) -> 3-8 or 0 | F6: 0.18871621
A7: LV Site Specific | B7: =IFERROR(INDEX('Annex 1 LV, HV and UMS charges'!$B$12:$B$30,MATCH($A7,'Annex 1 LV, HV and UMS charges'!$A$12:$A$295,0)),INDEX('Annex 4 LDNO charges'!$B$12:$B$116,MATCH($A7,'Annex 4 LDNO charges'!$A$12:$A$116,0))) -> 71, 72, 73, 74, 550 | C7: =IFERROR(INDEX('Annex 1 LV, HV and UMS charges'!$C$12:$C$30,MATCH($A7,'Annex 1 LV, HV and UMS charges'!$A$12:$A$295,0)),INDEX('Annex 4 LDNO charges'!$C$12:$C$116,MATCH($A7,'Annex 4 LDNO charges'!$A$12:$A$116,0))) -> 0 | F7: 0.18871621
A8: LV Sub Site Specific | B8: =IFERROR(INDEX('Annex 1 LV, HV and UMS charges'!$B$12:$B$30,MATCH($A8,'Annex 1 LV, HV and UMS charges'!$A$12:$A$295,0)),INDEX('Annex 4 LDNO charges'!$B$12:$B$116,MATCH($A8,'Annex 4 LDNO charges'!$A$12:$A$116,0))) -> 81, 82, 83, 84, 756 | C8: =IFERROR(INDEX('Annex 1 LV, HV and UMS charges'!$C$12:$C$30,MATCH($A8,'Annex 1 LV, HV and UMS charges'!$A$12:$A$295,0)),INDEX('Annex 4 LDNO charges'!$C$12:$C$116,MATCH($A8,'Annex 4 LDNO charges'!$A$12:$A$116,0))) -> 0 | F8: 0.18871621
A9: HV Site Specific | B9: =IFERROR(INDEX('Annex 1 LV, HV and UMS charges'!$B$12:$B$30,MATCH($A9,'Annex 1 LV, HV and UMS charges'!$A$12:$A$295,0)),INDEX('Annex 4 LDNO charges'!$B$12:$B$116,MATCH($A9,'Annex 4 LDNO charges'!$A$12:$A$116,0))) -> 91, 92, 93, 94, 650 | C9: =IFERROR(INDEX('Annex 1 LV, HV and UMS charges'!$C$12:$C$30,MATCH($A9,'Annex 1 LV, HV and UMS charges'!$A$12:$A$295,0)),INDEX('Annex 4 LDNO charges'!$C$12:$C$116,MATCH($A9,'Annex 4 LDNO charges'!$A$12:$A$116,0))) -> 0 | F9: 0.18871621
A10: LV Site Specific Storage Import | B10: =IFERROR(INDEX('Annex 1 LV, HV and UMS charges'!$B$12:$B$30,MATCH($A10,'Annex 1 LV, HV and UMS charges'!$A$12:$A$295,0)),INDEX('Annex 4 LDNO charges'!$B$12:$B$116,MATCH($A10,'Annex 4 LDNO charges'!$A$12:$A$116,0))) -> 19, 70 | C10: =IFERROR(INDEX('Annex 1 LV, HV and UMS charges'!$C$12:$C$30,MATCH($A10,'Annex 1 LV, HV and UMS charges'!$A$12:$A$295,0)),INDEX('Annex 4 LDNO charges'!$C$12:$C$116,MATCH($A10,'Annex 4 LDNO charges'!$A$12:$A$116,0))) -> 0 | F10: 0.18871621
A11: LV Sub Site Specific Storage Import | B11: =IFERROR(INDEX('Annex 1 LV, HV and UMS charges'!$B$12:$B$30,MATCH($A11,'Annex 1 LV, HV and UMS charges'!$A$12:$A$295,0)),INDEX('Annex 4 LDNO charges'!$B$12:$B$116,MATCH($A11,'Annex 4 LDNO charges'!$A$12:$A$116,0))) -> 79, 80 | C11: =IFERROR(INDEX('Annex 1 LV, HV and UMS charges'!$C$12:$C$30,MATCH($A11,'Annex 1 LV, HV and UMS charges'!$A$12:$A$295,0)),INDEX('Annex 4 LDNO charges'!$C$12:$C$116,MATCH($A11,'Annex 4 LDNO charges'!$A$12:$A$116,0))) -> 0 | F11: 0.18871621
A12: HV Site Specific Storage Import | B12: =IFERROR(INDEX('Annex 1 LV, HV and UMS charges'!$B$12:$B$30,MATCH($A12,'Annex 1 LV, HV and UMS charges'!$A$12:$A$295,0)),INDEX('Annex 4 LDNO charges'!$B$12:$B$116,MATCH($A12,'Annex 4 LDNO charges'!$A$12:$A$116,0))) -> 89, 90 | C12: =IFERROR(INDEX('Annex 1 LV, HV and UMS charges'!$C$12:$C$30,MATCH($A12,'Annex 1 LV, HV and UMS charges'!$A$12:$A$295,0)),INDEX('Annex 4 LDNO charges'!$C$12:$C$116,MATCH($A12,'Annex 4 LDNO charges'!$A$12:$A$116,0))) -> 0 | F12: 0.18871621
